File: examples/Birch/TGA_DSC data T18/13WaT18 10 K min air 14.2.07.TG.txt
#FILE:                        13WaT18 10 K min air 14.2.07.dsu
#FORMAT:                      NETZSCH4
#IDENTITY:                    13 WaT18 10 K min air
#DECIMAL:                     POINT
#SEPARATOR:                   SEMICOLON
#MTYPE:                       TG
#INSTRUMENT:                  NETZSCH STA 449C
#PROJECT:                     vtt
#DATE/TIME:                   14.2.2007 8:09:24
#CORR. FILE:                  correction 10Kmin air 800 C.bsu
#LABORATORY:                  EO
#OPERATOR:                    TL
#REMARK:
#SAMPLE:                      13 WaT18
#SAMPLE MASS /mg:             11.943
#MATERIAL:                    Empty crucibles
#REFERENCE:                   al2o3
#REFERENCE MASS /mg:          40.312
#TYPE OF CRUCIBLE:            DSC/TG pan Al2O3
#SAMPLE CRUCIBLE MASS /mg:    0.000
#REFERENCE CRUCIBLE MASS /mg: 0.000
#PROTECTIVE GAS:              N2
#PURGE GAS 1:                 air
#FLOW RATE 1 /(ml/min):       40
#PURGE GAS 2:
#FLOW RATE 2:
#DSC RANGE /æm:               5000
#TG RANGE /æm:                5000
#CORR. CODE:                  020
#EXO:                         +1
#RANGE:                       20.0/10.00(K/min)/800.0
#SEGMENT:                     S1/1

##Temp./øC;Mass/%
 21.25233;   100.00000
 22.25233;    99.94681
 23.25233;    99.93902
 24.25233;    99.93397
 25.25233;    99.92579
 26.25233;    99.92124
 27.25233;    99.91583
 28.25233;    99.91290
 29.25233;    99.90271
 30.25233;    99.89295
 31.25233;    99.88599
 32.25233;    99.87659
 33.25233;    99.87018
 34.25233;    99.86095
 35.25233;    99.84747
 36.25233;    99.83227
 37.25233;    99.82424
 38.25233;    99.81187
 39.25233;    99.79425
 40.25233;    99.77295
 41.25233;    99.75718
 42.25233;    99.74018
 43.25233;    99.72268
 44.25233;    99.70547
 45.25233;    99.68879
 46.25233;    99.66902
 47.25233;    99.65160
 48.25233;    99.63295
 49.25233;    99.60700
 50.25233;    99.57694
 51.25233;    99.55106
 52.25233;    99.52849
 53.25233;    99.49172
 54.25233;    99.46077
 55.25233;    99.43331
 56.25233;    99.40317
 57.25233;    99.36799
 58.25233;    99.33683
 59.25233;    99.29660
 60.25233;    99.25650
 61.25233;    99.21589
 62.25233;    99.18135
 63.25233;    99.14461
 64.25233;    99.09924
 65.25233;    99.05590
 66.25233;    99.01123
 67.25233;    98.96417
 68.25233;    98.91513
 69.25233;    98.87171
 70.25233;    98.82464
 71.25233;    98.78155
 72.25233;    98.73123
 73.25233;    98.67769
 74.25233;    98.62696
 75.25233;    98.57601
 76.25233;    98.52563
 77.25233;    98.47469
 78.25233;    98.42865
 79.25233;    98.37397
 80.25233;    98.32397
 81.25233;    98.27396
 82.25233;    98.21949
 83.25233;    98.17134
 84.25233;    98.12862
 85.25233;    98.08174
 86.25233;    98.03320
 87.25233;    97.98662
 88.25233;    97.94440
 89.25233;    97.89866
 90.25233;    97.86010
 91.25233;    97.82249
 92.25233;    97.78026
 93.25233;    97.74453
 94.25233;    97.70975
 95.25233;    97.67514
 96.25233;    97.64014
 97.25233;    97.61486
 98.25233;    97.58270
 99.25233;    97.55283
100.25233;    97.52806
101.25233;    97.50384
102.25233;    97.47985
103.25233;    97.46436
104.25233;    97.43992
105.25233;    97.41739
106.25233;    97.39984
107.25233;    97.38875
108.25233;    97.37052
109.25233;    97.36297
110.25233;    97.35006
111.25233;    97.33196
112.25233;    97.31802
113.25233;    97.31069
114.25233;    97.30441
115.25233;    97.29752
116.25233;    97.28661
117.25233;    97.27647
118.25233;    97.26439
119.25233;    97.25571
120.25233;    97.25034
121.25233;    97.24594
122.25233;    97.24022
123.25233;    97.23382
124.25233;    97.22916
125.25233;    97.22338
126.25233;    97.22013
127.25233;    97.21778
128.25233;    97.20988
129.25233;    97.20507
130.25233;    97.20252
131.25233;    97.19623
132.25233;    97.19258
133.25233;    97.18838
134.25233;    97.18488
135.25233;    97.18257
136.25233;    97.17998
137.25233;    97.17835
138.25233;    97.17479
139.25233;    97.17068
140.25233;    97.16759
141.25233;    97.16527
142.25233;    97.16378
143.25233;    97.16049
144.25233;    97.15728
145.25233;    97.15639
146.25233;    97.15707
147.25233;    97.15406
148.25233;    97.14996
149.25233;    97.14041
150.25233;    97.13388
151.25233;    97.13451
152.25233;    97.13329
153.25233;    97.13105
154.25233;    97.12893
155.25233;    97.12718
156.25233;    97.12376
157.25233;    97.11965
158.25233;    97.12055
159.25233;    97.11664
160.25233;    97.11301
161.25233;    97.10885
162.25233;    97.10520
163.25233;    97.10472
164.25233;    97.10542
165.25233;    97.10129
166.25233;    97.09716
167.25233;    97.09422
168.25233;    97.09018
169.25233;    97.08751
170.25233;    97.08568
171.25233;    97.08333
172.25233;    97.07837
173.25233;    97.07442
174.25233;    97.07269
175.25233;    97.06526
176.25233;    97.06199
177.25233;    97.05892
178.25233;    97.05614
179.25233;    97.05267
180.25233;    97.04987
181.25233;    97.04312
182.25233;    97.04081
183.25233;    97.03544
184.25233;    97.02830
185.25233;    97.02584
186.25233;    97.02252
187.25233;    97.01524
188.25233;    97.00701
189.25233;    96.99879
190.25233;    96.98971
191.25233;    96.98476
192.25233;    96.97915
193.25233;    96.97227
194.25233;    96.96205
195.25233;    96.95349
196.25233;    96.94405
197.25233;    96.93054
198.25233;    96.92013
199.25233;    96.91275
200.25233;    96.89947
201.25233;    96.88872
202.25233;    96.87506
203.25233;    96.85967
204.25233;    96.84928
205.25233;    96.83323
206.25233;    96.82312
207.25233;    96.80960
208.25233;    96.80076
209.25233;    96.78522
210.25233;    96.76988
211.25233;    96.75836
212.25233;    96.74305
213.25233;    96.72538
214.25233;    96.71507
215.25233;    96.70298
216.25233;    96.67637
217.25233;    96.65745
218.25233;    96.63731
219.25233;    96.62240
220.25233;    96.60129
221.25233;    96.58039
222.25233;    96.55634
223.25233;    96.53030
224.25233;    96.50371
225.25233;    96.48034
226.25233;    96.45621
227.25233;    96.42451
228.25233;    96.39697
229.25233;    96.36021
230.25233;    96.32880
231.25233;    96.28898
232.25233;    96.25491
233.25233;    96.21248
234.25233;    96.17594
235.25233;    96.13463
236.25233;    96.08169
237.25233;    96.03045
238.25233;    95.97864
239.25233;    95.92044
240.25233;    95.86230
241.25233;    95.80349
242.25233;    95.73821
243.25233;    95.66590
244.25233;    95.59347
245.25233;    95.51675
246.25233;    95.43708
247.25233;    95.35073
248.25233;    95.25791
249.25233;    95.13653
250.25233;    95.04255
251.25233;    94.92468
252.25233;    94.81444
253.25233;    94.69795
254.25233;    94.56180
255.25233;    94.42448
256.25233;    94.28058
257.25233;    94.12158
258.25233;    93.96156
259.25233;    93.79286
260.25233;    93.60407
261.25233;    93.41351
262.25233;    93.20780
263.25233;    92.99344
264.25233;    92.76024
265.25233;    92.51664
266.25233;    92.25478
267.25233;    91.97589
268.25233;    91.68187
269.25233;    91.37993
270.25233;    91.05301
271.25233;    90.49245
272.25233;    90.12667
273.25233;    89.76252
274.25233;    89.34442
275.25233;    88.93297
276.25233;    88.47368
277.25233;    88.02616
278.25233;    87.53356
279.25233;    87.05796
280.25233;    86.53450
281.25233;    86.01044
282.25233;    85.45416
283.25233;    84.89617
284.25233;    84.32719
285.25233;    83.71195
286.25233;    83.10835
287.25233;    82.51389
288.25233;    81.86088
289.25233;    81.23535
290.25233;    80.58258
291.25233;    79.91459
292.25233;    79.23144
293.25233;    78.57660
294.25233;    77.89449
295.25233;    77.23149
296.25233;    76.55694
297.25233;    75.86892
298.25233;    75.19022
299.25233;    74.50984
300.25233;    73.83153
301.25233;    73.16673
302.25233;    72.47253
303.25233;    71.81953
304.25233;    71.13014
305.25233;    70.46547
306.25233;    69.78108
307.25233;    69.11722
308.25233;    68.44209
309.25233;    67.76924
310.25233;    67.06831
311.25233;    66.38245
312.25233;    65.67964
313.25233;    64.95310
314.25233;    64.20401
315.25233;    63.43890
316.25233;    62.60654
317.25233;    61.80212
318.25233;    60.90935
319.25233;    60.01458
320.25233;    59.06359
321.25233;    58.04434
322.25233;    57.01763
323.25233;    55.89419
324.25233;    54.82910
325.25233;    53.66449
326.25233;    52.52322
327.25233;    51.29331
328.25233;    50.06318
329.25233;    48.81979
330.25233;    47.57657
331.25233;    46.31740
332.25233;    45.04068
333.25233;    43.75497
334.25233;    42.36636
335.25233;    40.92991
336.25233;    39.32780
337.25233;    36.95886
338.25233;    32.19105
339.25233;    31.63077
340.25233;    31.28829
341.25233;    31.00533
342.25233;    30.76436
343.25233;    30.53273
344.25233;    30.31926
345.25233;    30.11379
346.25233;    29.91405
347.25233;    29.71850
348.25233;    29.52425
349.25233;    29.33752
350.25233;    29.16017
351.25233;    28.98294
352.25233;    28.80358
353.25233;    28.62554
354.25233;    28.44783
355.25233;    28.27430
356.25233;    28.09886
357.25233;    27.92736
358.25233;    27.75153
359.25233;    27.57819
360.25233;    27.39943
361.25233;    27.23077
362.25233;    27.05803
363.25233;    26.88636
364.25233;    26.71736
365.25233;    26.54348
366.25233;    26.37259
367.25233;    26.20361
368.25233;    26.03307
369.25233;    25.86529
370.25233;    25.69512
371.25233;    25.51847
372.25233;    25.34975
373.25233;    25.18205
374.25233;    25.01305
375.25233;    24.84756
376.25233;    24.68229
377.25233;    24.51520
378.25233;    24.34425
379.25233;    24.18123
380.25233;    24.02058
381.25233;    23.85255
382.25233;    23.68784
383.25233;    23.52238
384.25233;    23.35520
385.25233;    23.19101
386.25233;    23.02040
387.25233;    22.85853
388.25233;    22.68882
389.25233;    22.52601
390.25233;    22.35953
391.25233;    22.19630
392.25233;    22.03315
393.25233;    21.86275
394.25233;    21.69423
395.25233;    21.52709
396.25233;    21.36178
397.25233;    21.18971
398.25233;    21.02033
399.25233;    20.85113
400.25233;    20.68121
401.25233;    20.50323
402.25233;    20.32773
403.25233;    20.15403
404.25233;    19.97732
405.25233;    19.80489
406.25233;    19.62657
407.25233;    19.44904
408.25233;    19.25828
409.25233;    19.07510
410.25233;    18.88324
411.25233;    18.69557
412.25233;    18.50025
413.25233;    18.30845
414.25233;    18.11218
415.25233;    17.90799
416.25233;    17.70793
417.25233;    17.49844
418.25233;    17.28797
419.25233;    17.06784
420.25233;    16.84627
421.25233;    16.62156
422.25233;    16.38699
423.25233;    16.14876
424.25233;    15.89973
425.25233;    15.64399
426.25233;    15.37679
427.25233;    15.10688
428.25233;    14.83106
429.25233;    14.54103
430.25233;    14.23386
431.25233;    13.91385
432.25233;    13.57891
433.25233;    12.97719
434.25233;    12.53220
435.25233;    12.00593
436.25233;    11.42276
437.25233;    10.84191
438.25233;    10.23897
439.25233;     9.71671
440.25233;     9.21033
441.25233;     8.71698
442.25233;     8.20377
443.25233;     7.71856
444.25233;     7.25666
445.25233;     6.78616
446.25233;     6.34406
447.25233;     5.91422
448.25233;     5.47395
449.25233;     5.06301
450.25233;     4.66399
451.25233;     4.27969
452.25233;     3.87788
453.25233;     3.52377
454.25233;     3.20821
455.25233;     2.95294
456.25233;     2.71412
457.25233;     2.41994
458.25233;     2.15601
459.25233;     1.89999
460.25233;     1.67427
461.25233;     1.48365
462.25233;     1.30946
463.25233;     1.16164
464.25233;     1.02728
465.25233;     0.89822
466.25233;     0.78712
467.25233;     0.69407
468.25233;     0.60861
469.25233;     0.52954
470.25233;     0.46264
471.25233;     0.40045
472.25233;     0.34009
473.25233;     0.29264
474.25233;     0.24533
475.25233;     0.20787
476.25233;     0.17164
477.25233;     0.14064
478.25233;     0.11970
479.25233; 9.4601e-002
480.25233; 7.5408e-002
481.25233; 6.2891e-002
482.25233; 5.4583e-002
483.25233; 3.7970e-002
484.25233; 3.1125e-002
485.25233; 2.2848e-002
486.25233; 1.9373e-002
487.25233; 1.6932e-002
488.25233; 1.5296e-002
489.25233; 1.5903e-002
490.25233; 1.5293e-002
491.25233; 1.3419e-002
492.25233; 1.5030e-002
493.25233; 1.8054e-002
494.25233; 2.0460e-002
495.25233; 2.3256e-002
496.25233; 2.7082e-002
497.25233; 3.0126e-002
498.25233; 3.1240e-002
499.25233; 3.2656e-002
500.25233; 3.5316e-002
501.25233; 3.6012e-002
502.25233; 3.6843e-002
503.25233; 3.7735e-002
504.25233; 3.8474e-002
505.25233; 3.8519e-002
506.25233; 3.9351e-002
507.25233; 4.0160e-002
508.25233; 4.0189e-002
509.25233; 4.0937e-002
510.25233; 4.3521e-002
511.25233; 4.5826e-002
512.25233; 4.6905e-002
513.25233; 4.8960e-002
514.25233; 4.9405e-002
515.25233; 4.9024e-002
516.25233; 5.0183e-002
517.25233; 5.3264e-002
518.25233; 5.4344e-002
519.25233; 5.5713e-002
520.25233; 5.5231e-002
521.25233; 5.6147e-002
522.25233; 5.6955e-002
523.25233; 5.6843e-002
524.25233; 5.9727e-002
525.25233; 6.2831e-002
526.25233; 6.4698e-002
527.25233; 6.6961e-002
528.25233; 6.6945e-002
529.25233; 6.6123e-002
530.25233; 6.7995e-002
531.25233; 6.8693e-002
532.25233; 6.7787e-002
533.25233; 7.0489e-002
534.25233; 7.1177e-002
535.25233; 7.2865e-002
536.25233; 7.2832e-002
537.25233; 7.4511e-002
538.25233; 7.5356e-002
539.25233; 7.6196e-002
540.25233; 7.6194e-002
541.25233; 7.6194e-002
542.25233; 7.6195e-002
543.25233; 7.7871e-002
544.25233; 7.8708e-002
545.25233; 8.1218e-002
546.25233; 8.4495e-002
547.25233; 8.7022e-002
548.25233; 8.9486e-002
549.25233; 8.9543e-002
550.25233; 9.0377e-002
551.25233; 9.1196e-002
552.25233; 9.1855e-002
553.25233; 9.3571e-002
554.25233; 9.4629e-002
555.25233; 9.4613e-002
556.25233; 9.3425e-002
557.25233; 9.2427e-002
558.25233; 9.0990e-002
559.25233; 9.2148e-002
560.25233; 9.0438e-002
561.25233; 9.0898e-002
562.25233; 9.1270e-002
563.25233; 9.1707e-002
564.25233; 9.1664e-002
565.25233; 9.0436e-002
566.25233; 9.1682e-002
567.25233; 9.2101e-002
568.25233; 9.2987e-002
569.25233; 9.4617e-002
570.25233; 9.3784e-002
571.25233; 9.3820e-002
572.25233; 9.1964e-002
573.25233; 8.8720e-002
574.25233; 8.9015e-002
575.25233; 9.0432e-002
576.25233; 9.2355e-002
577.25233; 9.3965e-002
578.25233; 9.4574e-002
579.25233; 9.5288e-002
580.25233; 9.4618e-002
581.25233; 9.5700e-002
582.25233; 9.8818e-002
583.25233; 9.7865e-002
584.25233; 9.7124e-002
585.25233; 9.7080e-002
586.25233;     0.10219
587.25233;     0.10301
588.25233;     0.10211
589.25233; 9.9622e-002
590.25233; 9.9670e-002
591.25233;     0.10130
592.25233;     0.10049
593.25233;     0.10216
594.25233;     0.11053
595.25233;     0.11219
596.25233;     0.11220
597.25233;     0.11302
598.25233;     0.11303
599.25233;     0.11303
600.25233;     0.11224
601.25233;     0.11059
602.25233;     0.10801
603.25233;     0.10952
604.25233;     0.11120
605.25233;     0.11138
606.25233;     0.11203
607.25233;     0.11218
608.25233;     0.11602
609.25233;     0.11870
610.25233;     0.12115
611.25233;     0.12113
612.25233;     0.11814
613.25233;     0.11667
614.25233;     0.11691
615.25233;     0.11810
616.25233;     0.11888
617.25233;     0.11777
618.25233;     0.11730
619.25233;     0.11592
620.25233;     0.11548
621.25233;     0.11676
622.25233;     0.11805
623.25233;     0.11637
624.25233;     0.11551
625.25233;     0.11721
626.25233;     0.11522
627.25233;     0.10222
628.25233; 9.9626e-002
629.25233; 9.7609e-002
630.25233; 9.6310e-002
631.25233; 9.5556e-002
632.25233; 9.4617e-002
633.25233; 9.3746e-002
634.25233; 9.3781e-002
635.25233; 9.2953e-002
636.25233; 9.1212e-002
637.25233; 9.2170e-002
638.25233; 9.1186e-002
639.25233; 9.0985e-002
640.25233; 9.0446e-002
641.25233; 9.1546e-002
642.25233; 9.2978e-002
643.25233; 9.0400e-002
644.25233; 9.0501e-002
645.25233; 9.0338e-002
646.25233; 9.5105e-002
647.25233; 9.5801e-002
648.25233; 9.1943e-002
649.25233; 8.7049e-002
650.25233; 8.5174e-002
651.25233; 8.3662e-002
652.25233; 8.6243e-002
653.25233; 8.5373e-002
654.25233; 8.6301e-002
655.25233; 8.3621e-002
656.25233; 7.9614e-002
657.25233; 8.1100e-002
658.25233; 8.0313e-002
659.25233; 7.7043e-002
660.25233; 7.4378e-002
661.25233; 7.0339e-002
662.25233; 6.5203e-002
663.25233; 6.1963e-002
664.25233; 6.0256e-002
665.25233; 5.9338e-002
666.25233; 5.1756e-002
667.25233; 4.6824e-002
668.25233; 4.5223e-002
669.25233; 4.2653e-002
670.25233; 3.6781e-002
671.25233; 3.5088e-002
672.25233; 3.2612e-002
673.25233; 3.3496e-002
674.25233; 3.5215e-002
675.25233; 3.6831e-002
676.25233; 3.1802e-002
677.25233; 3.0125e-002
678.25233; 2.8468e-002
679.25233; 2.7608e-002
680.25233; 2.6790e-002
681.25233; 2.4278e-002
682.25233; 2.5957e-002
683.25233; 2.5112e-002
684.25233; 2.2618e-002
685.25233; 2.0913e-002
686.25233; 2.1810e-002
687.25233; 1.9316e-002
688.25233; 1.5162e-002
689.25233; 1.0945e-002
690.25233; 1.0889e-002
691.25233; 1.1716e-002
692.25233; 1.0986e-002
693.25233; 1.2287e-002
694.25233; 1.5912e-002
695.25233; 1.4392e-002
696.25233; 1.2478e-002
697.25233; 1.0935e-002
698.25233; 1.0053e-002
699.25233; 1.3131e-002
700.25233; 1.5075e-002
701.25233; 1.5093e-002
702.25233; 1.5060e-002
703.25233; 1.4200e-002
704.25233; 1.2695e-002
705.25233; 1.1940e-002
706.25233; 1.0231e-002
707.25233; 1.0036e-002
708.25233; 9.0954e-003
709.25233; 9.4938e-003
710.25233; 9.1821e-003
711.25233; 9.2367e-003
712.25233; 9.1921e-003
713.25233; 7.9263e-003
714.25233; 5.3834e-003
715.25233; 3.0105e-003
716.25233; 5.1084e-003
717.25233; 5.0633e-003
718.25233; 5.7531e-003
719.25233; 6.2358e-003
720.25233; 4.5470e-003
721.25233; 2.8945e-003
722.25233; 2.1650e-003
723.25233; 9.0564e-004
724.25233; 1.3006e-003
725.25233; 3.7777e-003
726.25233; 5.3964e-003
727.25233; 7.5865e-003
728.25233; 5.3943e-003
729.25233; 5.9315e-003
730.25233; 4.9517e-003
731.25233; 5.8424e-003
732.25233; 5.0458e-003
733.25233; 5.7610e-003
734.25233; 5.4255e-003
735.25233; 4.6911e-003
736.25233; 3.9820e-003
737.25233; 2.1646e-003
738.25233; 5.0353e-003
739.25233; 5.8659e-003
740.25233; 5.8457e-003
741.25233; 4.8033e-003
742.25233; 2.0283e-003
743.25233;-5.5325e-004
744.25233; 1.8934e-006
745.25233;-2.6488e-003
746.25233; 3.2433e-005
747.25233; 6.4678e-004
748.25233;-1.0334e-003
749.25233;-2.2651e-003
750.25233;-7.7345e-004
751.25233;-1.8443e-003
752.25233;-3.2073e-003
753.25233;-3.4236e-003
754.25233;-4.8187e-004
755.25233;-1.2345e-003
756.25233;-2.4619e-003
757.25233;-4.1881e-003
758.25233;-6.0344e-003
759.25233;-6.8716e-003
760.25233;-7.3374e-003
761.25233;-7.5402e-003
762.25233;-6.5630e-003
763.25233;-5.1656e-003
764.25233;-6.8989e-003
765.25233;-8.5308e-003
766.25233;-8.3427e-003
767.25233;-9.2968e-003
768.25233;-1.0047e-002
769.25233;-9.3116e-003
770.25233;-1.1750e-002
771.25233;-1.1715e-002
772.25233;-9.9676e-003
773.25233;-7.4360e-003
774.25233;-6.7037e-003
775.25233;-8.4073e-003
776.25233;-1.0906e-002
777.25233;-1.4254e-002
778.25233;-1.4213e-002
779.25233;-1.8429e-002
780.25233;-1.7572e-002
781.25233;-1.8467e-002
782.25233;-1.8421e-002
783.25233;-1.7575e-002
784.25233;-1.9309e-002
785.25233;-2.2630e-002
786.25233;-2.4304e-002
787.25233;-2.6800e-002
788.25233;-2.5940e-002
789.25233;-2.2574e-002
790.25233;-2.1787e-002
791.25233;-2.1760e-002
792.25233;-2.0093e-002
793.25233;-2.0929e-002
794.25233;-2.2609e-002
795.25233;-2.4277e-002
796.25233;-2.4316e-002