File: examples/Birch/TGA_DSC data T18/13WaT18 10 K min air 14.2.07.DSC.txt
#FILE:                        13WaT18 10 K min air 14.2.07.dsu
#FORMAT:                      NETZSCH4
#IDENTITY:                    13 WaT18 10 K min air
#DECIMAL:                     POINT
#SEPARATOR:                   SEMICOLON
#MTYPE:                       DSC
#INSTRUMENT:                  NETZSCH STA 449C
#PROJECT:                     vtt
#DATE/TIME:                   14.2.2007 8:09:24
#CORR. FILE:                  correction 10Kmin air 800 C.bsu
#LABORATORY:                  EO
#OPERATOR:                    TL
#REMARK:
#SAMPLE:                      13 WaT18
#SAMPLE MASS /mg:             11.943
#MATERIAL:                    Empty crucibles
#REFERENCE:                   al2o3
#REFERENCE MASS /mg:          40.312
#TYPE OF CRUCIBLE:            DSC/TG pan Al2O3
#SAMPLE CRUCIBLE MASS /mg:    0.000
#REFERENCE CRUCIBLE MASS /mg: 0.000
#PROTECTIVE GAS:              N2
#PURGE GAS 1:                 air
#FLOW RATE 1 /(ml/min):       40
#PURGE GAS 2:
#FLOW RATE 2:
#DSC RANGE /æm:               5000
#TG RANGE /æm:                5000
#CORR. CODE:                  020
#EXO:                         +1
#RANGE:                       20.0/10.00(K/min)/800.0
#SEGMENT:                     S1/1

##Temp./øC;DSC/(mW/mg)
 21.25233;-3.9023e-003
 22.25233;-1.1045e-002
 23.25233;-1.9399e-002
 24.25233;-2.9031e-002
 25.25233;-3.8797e-002
 26.25233;-4.9775e-002
 27.25233;-5.9886e-002
 28.25233;-6.9734e-002
 29.25233;-7.9926e-002
 30.25233;-8.8475e-002
 31.25233;-9.7715e-002
 32.25233;    -0.10504
 33.25233;    -0.11313
 34.25233;    -0.12049
 35.25233;    -0.12752
 36.25233;    -0.13481
 37.25233;    -0.14141
 38.25233;    -0.14825
 39.25233;    -0.15526
 40.25233;    -0.16230
 41.25233;    -0.16918
 42.25233;    -0.17689
 43.25233;    -0.18448
 44.25233;    -0.19113
 45.25233;    -0.19856
 46.25233;    -0.20581
 47.25233;    -0.21336
 48.25233;    -0.22046
 49.25233;    -0.22800
 50.25233;    -0.23479
 51.25233;    -0.24208
 52.25233;    -0.24902
 53.25233;    -0.25671
 54.25233;    -0.26443
 55.25233;    -0.27106
 56.25233;    -0.27810
 57.25233;    -0.28496
 58.25233;    -0.29146
 59.25233;    -0.29827
 60.25233;    -0.30512
 61.25233;    -0.31173
 62.25233;    -0.31832
 63.25233;    -0.32452
 64.25233;    -0.33006
 65.25233;    -0.33663
 66.25233;    -0.34164
 67.25233;    -0.34703
 68.25233;    -0.35224
 69.25233;    -0.35685
 70.25233;    -0.36026
 71.25233;    -0.36464
 72.25233;    -0.36726
 73.25233;    -0.36991
 74.25233;    -0.37223
 75.25233;    -0.37395
 76.25233;    -0.37359
 77.25233;    -0.37461
 78.25233;    -0.37423
 79.25233;    -0.37276
 80.25233;    -0.37065
 81.25233;    -0.36742
 82.25233;    -0.36476
 83.25233;    -0.35955
 84.25233;    -0.35472
 85.25233;    -0.34880
 86.25233;    -0.34229
 87.25233;    -0.33486
 88.25233;    -0.32735
 89.25233;    -0.31901
 90.25233;    -0.31013
 91.25233;    -0.30049
 92.25233;    -0.28923
 93.25233;    -0.27923
 94.25233;    -0.26856
 95.25233;    -0.25671
 96.25233;    -0.24526
 97.25233;    -0.23321
 98.25233;    -0.22090
 99.25233;    -0.20788
100.25233;    -0.19604
101.25233;    -0.18378
102.25233;    -0.17144
103.25233;    -0.15901
104.25233;    -0.14699
105.25233;    -0.13472
106.25233;    -0.12221
107.25233;    -0.11177
108.25233;    -0.10060
109.25233;-9.0091e-002
110.25233;-7.9043e-002
111.25233;-6.9194e-002
112.25233;-5.9307e-002
113.25233;-5.0048e-002
114.25233;-3.9994e-002
115.25233;-3.1356e-002
116.25233;-2.3221e-002
117.25233;-1.5120e-002
118.25233;-6.5988e-003
119.25233; 3.7220e-005
120.25233; 6.7860e-003
121.25233; 1.3779e-002
122.25233; 2.1115e-002
123.25233; 2.6824e-002
124.25233; 3.3367e-002
125.25233; 3.9809e-002
126.25233; 4.5504e-002
127.25233; 5.1014e-002
128.25233; 5.5726e-002
129.25233; 6.1140e-002
130.25233; 6.6661e-002
131.25233; 7.1171e-002
132.25233; 7.5955e-002
133.25233; 8.1051e-002
134.25233; 8.5220e-002
135.25233; 9.0621e-002
136.25233; 9.4135e-002
137.25233; 9.8615e-002
138.25233;     0.10271
139.25233;     0.10678
140.25233;     0.11169
141.25233;     0.11636
142.25233;     0.11952
143.25233;     0.12419
144.25233;     0.12780
145.25233;     0.13248
146.25233;     0.13624
147.25233;     0.13952
148.25233;     0.14416
149.25233;     0.14823
150.25233;     0.15317
151.25233;     0.15622
152.25233;     0.16087
153.25233;     0.16466
154.25233;     0.16895
155.25233;     0.17343
156.25233;     0.17806
157.25233;     0.18183
158.25233;     0.18572
159.25233;     0.19013
160.25233;     0.19524
161.25233;     0.19928
162.25233;     0.20315
163.25233;     0.20761
164.25233;     0.21258
165.25233;     0.21653
166.25233;     0.22049
167.25233;     0.22529
168.25233;     0.22919
169.25233;     0.23358
170.25233;     0.23848
171.25233;     0.24308
172.25233;     0.24726
173.25233;     0.25152
174.25233;     0.25632
175.25233;     0.26052
176.25233;     0.26578
177.25233;     0.26993
178.25233;     0.27544
179.25233;     0.28047
180.25233;     0.28413
181.25233;     0.28898
182.25233;     0.29361
183.25233;     0.29876
184.25233;     0.30336
185.25233;     0.30817
186.25233;     0.31254
187.25233;     0.31731
188.25233;     0.32185
189.25233;     0.32675
190.25233;     0.33179
191.25233;     0.33616
192.25233;     0.34140
193.25233;     0.34518
194.25233;     0.35043
195.25233;     0.35467
196.25233;     0.35938
197.25233;     0.36452
198.25233;     0.36973
199.25233;     0.37433
200.25233;     0.37982
201.25233;     0.38441
202.25233;     0.38926
203.25233;     0.39479
204.25233;     0.40045
205.25233;     0.40451
206.25233;     0.41027
207.25233;     0.41574
208.25233;     0.42109
209.25233;     0.42604
210.25233;     0.43180
211.25233;     0.43787
212.25233;     0.44351
213.25233;     0.44986
214.25233;     0.45581
215.25233;     0.46207
216.25233;     0.46836
217.25233;     0.47432
218.25233;     0.48130
219.25233;     0.48811
220.25233;     0.49379
221.25233;     0.50194
222.25233;     0.50902
223.25233;     0.51683
224.25233;     0.52417
225.25233;     0.53244
226.25233;     0.54090
227.25233;     0.54880
228.25233;     0.55661
229.25233;     0.56599
230.25233;     0.57433
231.25233;     0.58449
232.25233;     0.59337
233.25233;     0.60319
234.25233;     0.61391
235.25233;     0.62508
236.25233;     0.63595
237.25233;     0.64716
238.25233;     0.65968
239.25233;     0.67231
240.25233;     0.68497
241.25233;     0.69950
242.25233;     0.71278
243.25233;     0.72736
244.25233;     0.74217
245.25233;     0.75718
246.25233;     0.77359
247.25233;     0.78976
248.25233;     0.80696
249.25233;     0.82491
250.25233;     0.84383
251.25233;     0.86292
252.25233;     0.88315
253.25233;     0.90418
254.25233;     0.92624
255.25233;     0.94963
256.25233;     0.97414
257.25233;     0.99925
258.25233;     1.02445
259.25233;     1.05050
260.25233;     1.07745
261.25233;     1.10552
262.25233;     1.13388
263.25233;     1.16323
264.25233;     1.19237
265.25233;     1.22168
266.25233;     1.25163
267.25233;     1.28435
268.25233;     1.31526
269.25233;     1.34730
270.25233;     1.37939
271.25233;     1.41210
272.25233;     1.44405
273.25233;     1.47759
274.25233;     1.51031
275.25233;     1.54383
276.25233;     1.57726
277.25233;     1.61105
278.25233;     1.64394
279.25233;     1.67735
280.25233;     1.71063
281.25233;     1.74476
282.25233;     1.77800
283.25233;     1.81077
284.25233;     1.84394
285.25233;     1.87722
286.25233;     1.91014
287.25233;     1.94207
288.25233;     1.97305
289.25233;     2.00383
290.25233;     2.03337
291.25233;     2.06186
292.25233;     2.09085
293.25233;     2.11769
294.25233;     2.14355
295.25233;     2.16954
296.25233;     2.19291
297.25233;     2.21464
298.25233;     2.23679
299.25233;     2.25763
300.25233;     2.27805
301.25233;     2.29833
302.25233;     2.31714
303.25233;     2.33477
304.25233;     2.35381
305.25233;     2.37240
306.25233;     2.39306
307.25233;     2.41195
308.25233;     2.43315
309.25233;     2.45644
310.25233;     2.48315
311.25233;     2.51023
312.25233;     2.54086
313.25233;     2.57410
314.25233;     2.61108
315.25233;     2.65356
316.25233;     2.70179
317.25233;     2.75458
318.25233;     2.81658
319.25233;     2.88352
320.25233;     2.95901
321.25233;     3.04208
322.25233;     3.13324
323.25233;     3.23336
324.25233;     3.33409
325.25233;     3.44400
326.25233;     3.55142
327.25233;     3.66303
328.25233;     3.77083
329.25233;     3.87309
330.25233;     3.97326
331.25233;     4.07128
332.25233;     4.16171
333.25233;     4.23631
334.25233;     4.28957
335.25233;     4.32243
336.25233;     4.32766
337.25233;     4.27167
338.25233;     4.81339
339.25233;     4.90279
340.25233;     4.97604
341.25233;     5.04423
342.25233;     5.10066
343.25233;     5.14378
344.25233;     5.17290
345.25233;     5.19221
346.25233;     5.20590
347.25233;     5.21566
348.25233;     5.22928
349.25233;     5.24267
350.25233;     5.25464
351.25233;     5.26284
352.25233;     5.26881
353.25233;     5.27060
354.25233;     5.26880
355.25233;     5.26358
356.25233;     5.25607
357.25233;     5.24770
358.25233;     5.23807
359.25233;     5.22729
360.25233;     5.21519
361.25233;     5.20198
362.25233;     5.18552
363.25233;     5.16880
364.25233;     5.14891
365.25233;     5.12814
366.25233;     5.10548
367.25233;     5.08260
368.25233;     5.05954
369.25233;     5.03672
370.25233;     5.01341
371.25233;     4.98946
372.25233;     4.96604
373.25233;     4.94215
374.25233;     4.91761
375.25233;     4.89357
376.25233;     4.87035
377.25233;     4.84816
378.25233;     4.82624
379.25233;     4.80456
380.25233;     4.78298
381.25233;     4.76339
382.25233;     4.74397
383.25233;     4.72749
384.25233;     4.70988
385.25233;     4.69261
386.25233;     4.67747
387.25233;     4.66300
388.25233;     4.64936
389.25233;     4.63754
390.25233;     4.62540
391.25233;     4.61545
392.25233;     4.60563
393.25233;     4.59864
394.25233;     4.59140
395.25233;     4.58675
396.25233;     4.58402
397.25233;     4.58187
398.25233;     4.58161
399.25233;     4.58311
400.25233;     4.58616
401.25233;     4.59062
402.25233;     4.59772
403.25233;     4.60632
404.25233;     4.61827
405.25233;     4.63213
406.25233;     4.64791
407.25233;     4.66650
408.25233;     4.68793
409.25233;     4.71172
410.25233;     4.73952
411.25233;     4.76958
412.25233;     4.80310
413.25233;     4.84012
414.25233;     4.88224
415.25233;     4.92645
416.25233;     4.97709
417.25233;     5.03347
418.25233;     5.09228
419.25233;     5.15930
420.25233;     5.23026
421.25233;     5.30751
422.25233;     5.39177
423.25233;     5.48363
424.25233;     5.58545
425.25233;     5.69826
426.25233;     5.82049
427.25233;     5.95569
428.25233;     6.10671
429.25233;     6.27594
430.25233;     6.47202
431.25233;     6.70364
432.25233;     6.98623
433.25233;     7.34072
434.25233;     7.78644
435.25233;     8.41144
436.25233;     9.18220
437.25233;     9.94176
438.25233;    10.56955
439.25233;    10.88761
440.25233;    10.99907
441.25233;    10.98683
442.25233;    10.90549
443.25233;    10.79242
444.25233;    10.65595
445.25233;    10.49886
446.25233;    10.32566
447.25233;    10.15542
448.25233;     9.98021
449.25233;     9.79775
450.25233;     9.62324
451.25233;     9.50351
452.25233;     9.41375
453.25233;     9.18162
454.25233;     8.84478
455.25233;     8.46929
456.25233;     8.09010
457.25233;     7.72004
458.25233;     7.31775
459.25233;     6.82849
460.25233;     6.27632
461.25233;     5.72251
462.25233;     5.17670
463.25233;     4.68274
464.25233;     4.25925
465.25233;     3.87703
466.25233;     3.52292
467.25233;     3.20572
468.25233;     2.91563
469.25233;     2.64991
470.25233;     2.40977
471.25233;     2.19508
472.25233;     1.99641
473.25233;     1.81469
474.25233;     1.64538
475.25233;     1.48938
476.25233;     1.34854
477.25233;     1.21655
478.25233;     1.08983
479.25233;     0.97030
480.25233;     0.85369
481.25233;     0.74456
482.25233;     0.64471
483.25233;     0.55369
484.25233;     0.46971
485.25233;     0.39321
486.25233;     0.32310
487.25233;     0.26157
488.25233;     0.20817
489.25233;     0.16576
490.25233;     0.13095
491.25233;     0.10337
492.25233; 8.3165e-002
493.25233; 6.6253e-002
494.25233; 5.4922e-002
495.25233; 4.6221e-002
496.25233; 4.0785e-002
497.25233; 3.6037e-002
498.25233; 3.2492e-002
499.25233; 2.9444e-002
500.25233; 2.8265e-002
501.25233; 2.7644e-002
502.25233; 2.6655e-002
503.25233; 2.6673e-002
504.25233; 2.5729e-002
505.25233; 2.5774e-002
506.25233; 2.5376e-002
507.25233; 2.5368e-002
508.25233; 2.5267e-002
509.25233; 2.4725e-002
510.25233; 2.4659e-002
511.25233; 2.4860e-002
512.25233; 2.4987e-002
513.25233; 2.4814e-002
514.25233; 2.4804e-002
515.25233; 2.4714e-002
516.25233; 2.5444e-002
517.25233; 2.6124e-002
518.25233; 2.5856e-002
519.25233; 2.6459e-002
520.25233; 2.5597e-002
521.25233; 2.5800e-002
522.25233; 2.6248e-002
523.25233; 2.6008e-002
524.25233; 2.6514e-002
525.25233; 2.6863e-002
526.25233; 2.5339e-002
527.25233; 2.6295e-002
528.25233; 2.5915e-002
529.25233; 2.6498e-002
530.25233; 2.7479e-002
531.25233; 2.7188e-002
532.25233; 2.7436e-002
533.25233; 2.7815e-002
534.25233; 2.7523e-002
535.25233; 2.7604e-002
536.25233; 2.7102e-002
537.25233; 2.7037e-002
538.25233; 2.7531e-002
539.25233; 2.7281e-002
540.25233; 2.8105e-002
541.25233; 2.7988e-002
542.25233; 2.8831e-002
543.25233; 2.8570e-002
544.25233; 2.9698e-002
545.25233; 2.8598e-002
546.25233; 2.9557e-002
547.25233; 2.9884e-002
548.25233; 2.9240e-002
549.25233; 3.0021e-002
550.25233; 3.0007e-002
551.25233; 2.9635e-002
552.25233; 3.0146e-002
553.25233; 3.0061e-002
554.25233; 3.0008e-002
555.25233; 2.9962e-002
556.25233; 3.0521e-002
557.25233; 3.0867e-002
558.25233; 3.1242e-002
559.25233; 3.1380e-002
560.25233; 3.1569e-002
561.25233; 3.2228e-002
562.25233; 3.2682e-002
563.25233; 3.2383e-002
564.25233; 3.2721e-002
565.25233; 3.3401e-002
566.25233; 3.3137e-002
567.25233; 3.4065e-002
568.25233; 3.3252e-002
569.25233; 3.3777e-002
570.25233; 3.4134e-002
571.25233; 3.3727e-002
572.25233; 3.5245e-002
573.25233; 3.4670e-002
574.25233; 3.4598e-002
575.25233; 3.4703e-002
576.25233; 3.4412e-002
577.25233; 3.4785e-002
578.25233; 3.4421e-002
579.25233; 3.4598e-002
580.25233; 3.4532e-002
581.25233; 3.4153e-002
582.25233; 3.4658e-002
583.25233; 3.4416e-002
584.25233; 3.4098e-002
585.25233; 3.5108e-002
586.25233; 3.5815e-002
587.25233; 3.5624e-002
588.25233; 3.5551e-002
589.25233; 3.6168e-002
590.25233; 3.7842e-002
591.25233; 3.7641e-002
592.25233; 3.8092e-002
593.25233; 3.8400e-002
594.25233; 3.9140e-002
595.25233; 3.9312e-002
596.25233; 3.9464e-002
597.25233; 4.0667e-002
598.25233; 4.0106e-002
599.25233; 4.1143e-002
600.25233; 4.0631e-002
601.25233; 4.0746e-002
602.25233; 4.0421e-002
603.25233; 4.0582e-002
604.25233; 4.1172e-002
605.25233; 4.3060e-002
606.25233; 4.1803e-002
607.25233; 4.2173e-002
608.25233; 4.2622e-002
609.25233; 4.2818e-002
610.25233; 4.2561e-002
611.25233; 4.2672e-002
612.25233; 4.1262e-002
613.25233; 4.2228e-002
614.25233; 4.2064e-002
615.25233; 4.1320e-002
616.25233; 4.1639e-002
617.25233; 4.1345e-002
618.25233; 4.1667e-002
619.25233; 4.2323e-002
620.25233; 4.2181e-002
621.25233; 4.2817e-002
622.25233; 4.1861e-002
623.25233; 4.2467e-002
624.25233; 4.1418e-002
625.25233; 4.1603e-002
626.25233; 4.2064e-002
627.25233; 4.2555e-002
628.25233; 4.4170e-002
629.25233; 4.3192e-002
630.25233; 4.3397e-002
631.25233; 4.3745e-002
632.25233; 4.3707e-002
633.25233; 4.3999e-002
634.25233; 4.4167e-002
635.25233; 4.3892e-002
636.25233; 4.4369e-002
637.25233; 4.4329e-002
638.25233; 4.4404e-002
639.25233; 4.4081e-002
640.25233; 4.4651e-002
641.25233; 4.4983e-002
642.25233; 4.3495e-002
643.25233; 4.2969e-002
644.25233; 4.3350e-002
645.25233; 4.4117e-002
646.25233; 4.4299e-002
647.25233; 4.5644e-002
648.25233; 4.6750e-002
649.25233; 4.7662e-002
650.25233; 4.7378e-002
651.25233; 4.7584e-002
652.25233; 4.6950e-002
653.25233; 4.7249e-002
654.25233; 4.6557e-002
655.25233; 4.6554e-002
656.25233; 4.6092e-002
657.25233; 4.3176e-002
658.25233; 3.9935e-002
659.25233; 3.6597e-002
660.25233; 3.1353e-002
661.25233; 3.0153e-002
662.25233; 2.5334e-002
663.25233; 2.4737e-002
664.25233; 2.3958e-002
665.25233; 2.6037e-002
666.25233; 2.9255e-002
667.25233; 3.4571e-002
668.25233; 4.0877e-002
669.25233; 4.4521e-002
670.25233; 4.7388e-002
671.25233; 4.9798e-002
672.25233; 5.1039e-002
673.25233; 5.1851e-002
674.25233; 5.2599e-002
675.25233; 5.2094e-002
676.25233; 5.2904e-002
677.25233; 5.2922e-002
678.25233; 5.2055e-002
679.25233; 5.2402e-002
680.25233; 5.3509e-002
681.25233; 5.4008e-002
682.25233; 5.4815e-002
683.25233; 5.6241e-002
684.25233; 5.7969e-002
685.25233; 5.9245e-002
686.25233; 6.0083e-002
687.25233; 6.1301e-002
688.25233; 6.2763e-002
689.25233; 6.2998e-002
690.25233; 6.3471e-002
691.25233; 6.4795e-002
692.25233; 6.6276e-002
693.25233; 6.7172e-002
694.25233; 6.6980e-002
695.25233; 6.7488e-002
696.25233; 6.8521e-002
697.25233; 6.7986e-002
698.25233; 6.9199e-002
699.25233; 7.0628e-002
700.25233; 7.1004e-002
701.25233; 7.1004e-002
702.25233; 7.0365e-002
703.25233; 7.1751e-002
704.25233; 7.2523e-002
705.25233; 7.3227e-002
706.25233; 7.3886e-002
707.25233; 7.3212e-002
708.25233; 7.4610e-002
709.25233; 7.4786e-002
710.25233; 5.3631e-002
711.25233; 4.5894e-002
712.25233; 4.8873e-002
713.25233; 5.1693e-002
714.25233; 5.4291e-002
715.25233; 5.4434e-002
716.25233; 5.5354e-002
717.25233; 5.5467e-002
718.25233; 5.6525e-002
719.25233; 5.6869e-002
720.25233; 5.8359e-002
721.25233; 5.9009e-002
722.25233; 5.9818e-002
723.25233; 5.9711e-002
724.25233; 5.9626e-002
725.25233; 5.9770e-002
726.25233; 5.9859e-002
727.25233; 5.9647e-002
728.25233; 5.9989e-002
729.25233; 6.1033e-002
730.25233; 5.9771e-002
731.25233; 6.0830e-002
732.25233; 6.1048e-002
733.25233; 6.1130e-002
734.25233; 6.1432e-002
735.25233; 6.2020e-002
736.25233; 6.3053e-002
737.25233; 6.3307e-002
738.25233; 6.3356e-002
739.25233; 6.3239e-002
740.25233; 6.3720e-002
741.25233; 6.2938e-002
742.25233; 6.3002e-002
743.25233; 6.3371e-002
744.25233; 6.2562e-002
745.25233; 6.2925e-002
746.25233; 6.2462e-002
747.25233; 6.3131e-002
748.25233; 6.3357e-002
749.25233; 6.4270e-002
750.25233; 6.3576e-002
751.25233; 6.2582e-002
752.25233; 6.3466e-002
753.25233; 6.2686e-002
754.25233; 6.2726e-002
755.25233; 6.4016e-002
756.25233; 6.4708e-002
757.25233; 6.6351e-002
758.25233; 6.7416e-002
759.25233; 6.8680e-002
760.25233; 6.7612e-002
761.25233; 6.7339e-002
762.25233; 6.7289e-002
763.25233; 6.7735e-002
764.25233; 6.8331e-002
765.25233; 6.8255e-002
766.25233; 6.6288e-002
767.25233; 6.5630e-002
768.25233; 6.5002e-002
769.25233; 6.6425e-002
770.25233; 6.6099e-002
771.25233; 6.7452e-002
772.25233; 6.5416e-002
773.25233; 6.5462e-002
774.25233; 6.3772e-002
775.25233; 6.4245e-002
776.25233; 6.6219e-002
777.25233; 6.6781e-002
778.25233; 6.8488e-002
779.25233; 6.9896e-002
780.25233; 7.2299e-002
781.25233; 7.2860e-002
782.25233; 7.2947e-002
783.25233; 7.3138e-002
784.25233; 7.4407e-002
785.25233; 7.4453e-002
786.25233; 7.3181e-002
787.25233; 7.3267e-002
788.25233; 7.5544e-002
789.25233; 7.6254e-002
790.25233; 7.5171e-002
791.25233; 7.5570e-002
792.25233; 7.6818e-002
793.25233; 7.7223e-002
794.25233; 7.7491e-002
795.25233; 7.8563e-002
796.25233; 7.7937e-002