File: examples/Birch/TGA_DSC data T18/13WaT18 20 K min air 7.2.2007.DSC.txt
#FILE:                        13WaT18 20 K min air 7.2.2007.dsu
#FORMAT:                      NETZSCH4
#IDENTITY:                    13WaT18 20 K min air
#DECIMAL:                     POINT
#SEPARATOR:                   SEMICOLON
#MTYPE:                       DSC
#INSTRUMENT:                  NETZSCH STA 449C
#PROJECT:                     vtt
#DATE/TIME:                   7.2.2007 8:22:58
#CORR. FILE:                  correction 20Kmin air 800 C.bsu
#LABORATORY:                  EO
#OPERATOR:                    TL
#REMARK:
#SAMPLE:                      13WaT18
#SAMPLE MASS /mg:             12.498
#MATERIAL:                    Empty crucibles
#REFERENCE:                   al2o3
#REFERENCE MASS /mg:          40.312
#TYPE OF CRUCIBLE:            DSC/TG pan Al2O3
#SAMPLE CRUCIBLE MASS /mg:    0.000
#REFERENCE CRUCIBLE MASS /mg: 0.000
#PROTECTIVE GAS:              N2
#PURGE GAS 1:                 air
#FLOW RATE 1 /(ml/min):       40
#PURGE GAS 2:
#FLOW RATE 2:
#DSC RANGE /æm:               5000
#TG RANGE /æm:                5000
#CORR. CODE:                  020
#EXO:                         +1
#RANGE:                       20.0/20.00(K/min)/800.0
#SEGMENT:                     S1/1

##Temp./øC;DSC/(mW/mg)
 19.80000; 7.3594e-004
 20.80000; 1.0125e-002
 21.80000; 2.9140e-002
 22.80000; 5.4409e-002
 23.80000; 8.7798e-002
 24.80000;     0.12010
 25.80000;     0.14457
 26.80000;     0.16118
 27.80000;     0.17006
 28.80000;     0.17130
 29.80000;     0.16829
 30.80000;     0.15978
 31.80000;     0.14803
 32.80000;     0.13506
 33.80000;     0.11986
 34.80000;     0.10435
 35.80000; 8.7718e-002
 36.80000; 7.2078e-002
 37.80000; 5.6900e-002
 38.80000; 4.3498e-002
 39.80000; 3.0514e-002
 40.80000; 1.9550e-002
 41.80000; 1.1071e-002
 42.80000; 4.4795e-003
 43.80000;-9.7008e-004
 44.80000;-4.4045e-003
 45.80000;-4.8301e-003
 46.80000;-4.5153e-003
 47.80000;-2.9499e-003
 48.80000;-6.0673e-004
 49.80000; 2.5771e-003
 50.80000; 5.4555e-003
 51.80000; 7.3108e-003
 52.80000; 9.0432e-003
 53.80000; 1.0178e-002
 54.80000; 1.0756e-002
 55.80000; 9.6049e-003
 56.80000; 7.1630e-003
 57.80000; 3.7977e-003
 58.80000;-6.5571e-004
 59.80000;-4.2777e-003
 60.80000;-1.0781e-002
 61.80000;-1.6457e-002
 62.80000;-2.3693e-002
 63.80000;-3.0630e-002
 64.80000;-3.8697e-002
 65.80000;-4.6142e-002
 66.80000;-5.5506e-002
 67.80000;-6.3476e-002
 68.80000;-7.1262e-002
 69.80000;-7.9744e-002
 70.80000;-8.5936e-002
 71.80000;-9.2167e-002
 72.80000;-9.8839e-002
 73.80000;    -0.10501
 74.80000;    -0.11048
 75.80000;    -0.11500
 76.80000;    -0.11859
 77.80000;    -0.12291
 78.80000;    -0.12586
 79.80000;    -0.12884
 80.80000;    -0.13052
 81.80000;    -0.13259
 82.80000;    -0.13441
 83.80000;    -0.13534
 84.80000;    -0.13665
 85.80000;    -0.13722
 86.80000;    -0.13773
 87.80000;    -0.13768
 88.80000;    -0.13691
 89.80000;    -0.13685
 90.80000;    -0.13628
 91.80000;    -0.13524
 92.80000;    -0.13328
 93.80000;    -0.13105
 94.80000;    -0.12821
 95.80000;    -0.12560
 96.80000;    -0.12185
 97.80000;    -0.11748
 98.80000;    -0.11194
 99.80000;    -0.10587
100.80000;-9.8742e-002
101.80000;-9.1250e-002
102.80000;-8.2083e-002
103.80000;-7.3163e-002
104.80000;-6.4846e-002
105.80000;-5.3207e-002
106.80000;-4.2040e-002
107.80000;-2.9423e-002
108.80000;-1.6245e-002
109.80000;-2.1752e-003
110.80000; 1.0438e-002
111.80000; 2.5679e-002
112.80000; 3.9705e-002
113.80000; 5.4601e-002
114.80000; 7.0714e-002
115.80000; 8.6107e-002
116.80000;     0.10205
117.80000;     0.11767
118.80000;     0.13369
119.80000;     0.14822
120.80000;     0.16393
121.80000;     0.17861
122.80000;     0.19319
123.80000;     0.20850
124.80000;     0.22199
125.80000;     0.23657
126.80000;     0.24950
127.80000;     0.26327
128.80000;     0.27647
129.80000;     0.28868
130.80000;     0.30165
131.80000;     0.31317
132.80000;     0.32514
133.80000;     0.33638
134.80000;     0.34748
135.80000;     0.35846
136.80000;     0.36836
137.80000;     0.37921
138.80000;     0.38987
139.80000;     0.39997
140.80000;     0.40994
141.80000;     0.41933
142.80000;     0.42868
143.80000;     0.43800
144.80000;     0.44711
145.80000;     0.45635
146.80000;     0.46444
147.80000;     0.47283
148.80000;     0.48127
149.80000;     0.48993
150.80000;     0.49761
151.80000;     0.50559
152.80000;     0.51406
153.80000;     0.52189
154.80000;     0.52960
155.80000;     0.53700
156.80000;     0.54450
157.80000;     0.55293
158.80000;     0.56027
159.80000;     0.56737
160.80000;     0.57488
161.80000;     0.58258
162.80000;     0.58949
163.80000;     0.59800
164.80000;     0.60474
165.80000;     0.61311
166.80000;     0.62058
167.80000;     0.62930
168.80000;     0.63697
169.80000;     0.64433
170.80000;     0.65236
171.80000;     0.66098
172.80000;     0.66827
173.80000;     0.67641
174.80000;     0.68387
175.80000;     0.69239
176.80000;     0.70060
177.80000;     0.70850
178.80000;     0.71602
179.80000;     0.72459
180.80000;     0.73217
181.80000;     0.73992
182.80000;     0.74674
183.80000;     0.75531
184.80000;     0.76312
185.80000;     0.77170
186.80000;     0.77893
187.80000;     0.78660
188.80000;     0.79453
189.80000;     0.80299
190.80000;     0.81051
191.80000;     0.81825
192.80000;     0.82596
193.80000;     0.83354
194.80000;     0.84159
195.80000;     0.84938
196.80000;     0.85717
197.80000;     0.86509
198.80000;     0.87300
199.80000;     0.88141
200.80000;     0.88799
201.80000;     0.89659
202.80000;     0.90489
203.80000;     0.91335
204.80000;     0.92046
205.80000;     0.92935
206.80000;     0.93734
207.80000;     0.94535
208.80000;     0.95395
209.80000;     0.96261
210.80000;     0.97034
211.80000;     0.97944
212.80000;     0.98693
213.80000;     0.99635
214.80000;     1.00518
215.80000;     1.01294
216.80000;     1.02256
217.80000;     1.03157
218.80000;     1.04066
219.80000;     1.04975
220.80000;     1.05840
221.80000;     1.06837
222.80000;     1.07741
223.80000;     1.08715
224.80000;     1.09637
225.80000;     1.10574
226.80000;     1.11594
227.80000;     1.12627
228.80000;     1.13712
229.80000;     1.14745
230.80000;     1.15834
231.80000;     1.16973
232.80000;     1.18176
233.80000;     1.19322
234.80000;     1.20491
235.80000;     1.21647
236.80000;     1.22926
237.80000;     1.24164
238.80000;     1.25680
239.80000;     1.26937
240.80000;     1.28298
241.80000;     1.29804
242.80000;     1.31315
243.80000;     1.32939
244.80000;     1.34579
245.80000;     1.36222
246.80000;     1.37976
247.80000;     1.39769
248.80000;     1.41703
249.80000;     1.43749
250.80000;     1.45877
251.80000;     1.48186
252.80000;     1.50432
253.80000;     1.52946
254.80000;     1.55520
255.80000;     1.58232
256.80000;     1.61027
257.80000;     1.63877
258.80000;     1.66959
259.80000;     1.69905
260.80000;     1.73067
261.80000;     1.76404
262.80000;     1.79696
263.80000;     1.83197
264.80000;     1.86818
265.80000;     1.90365
266.80000;     1.94209
267.80000;     1.98060
268.80000;     2.01916
269.80000;     2.06011
270.80000;     2.09990
271.80000;     2.14198
272.80000;     2.18349
273.80000;     2.22681
274.80000;     2.27152
275.80000;     2.31614
276.80000;     2.36204
277.80000;     2.40921
278.80000;     2.45462
279.80000;     2.50477
280.80000;     2.55173
281.80000;     2.60039
282.80000;     2.65082
283.80000;     2.70004
284.80000;     2.75248
285.80000;     2.80220
286.80000;     2.85258
287.80000;     2.90495
288.80000;     2.95635
289.80000;     3.00798
290.80000;     3.06063
291.80000;     3.11271
292.80000;     3.16462
293.80000;     3.21599
294.80000;     3.26794
295.80000;     3.32027
296.80000;     3.37057
297.80000;     3.41854
298.80000;     3.46836
299.80000;     3.51804
300.80000;     3.56437
301.80000;     3.61041
302.80000;     3.65547
303.80000;     3.69920
304.80000;     3.74065
305.80000;     3.78210
306.80000;     3.81981
307.80000;     3.85783
308.80000;     3.89155
309.80000;     3.92484
310.80000;     3.95609
311.80000;     3.98617
312.80000;     4.01477
313.80000;     4.04301
314.80000;     4.06925
315.80000;     4.09351
316.80000;     4.11883
317.80000;     4.14182
318.80000;     4.16621
319.80000;     4.18980
320.80000;     4.21548
321.80000;     4.24094
322.80000;     4.26760
323.80000;     4.29360
324.80000;     4.32329
325.80000;     4.35541
326.80000;     4.39114
327.80000;     4.42943
328.80000;     4.47204
329.80000;     4.52173
330.80000;     4.57479
331.80000;     4.63002
332.80000;     4.69051
333.80000;     4.75481
334.80000;     4.82079
335.80000;     4.88968
336.80000;     4.96011
337.80000;     5.02971
338.80000;     5.09914
339.80000;     5.16772
340.80000;     5.22946
341.80000;     5.29275
342.80000;     5.34650
343.80000;     5.39792
344.80000;     5.44267
345.80000;     5.47494
346.80000;     5.49915
347.80000;     5.51242
348.80000;     5.51444
349.80000;     5.49976
350.80000;     5.46934
351.80000;     5.41762
352.80000;     5.34040
353.80000;     5.23597
354.80000;     5.08133
355.80000;     4.86070
356.80000;     4.48202
357.80000;     3.95306
358.80000;     4.13461
359.80000;     4.35583
360.80000;     4.52777
361.80000;     4.67119
362.80000;     4.80857
363.80000;     4.94187
364.80000;     5.07271
365.80000;     5.19542
366.80000;     5.30797
367.80000;     5.41301
368.80000;     5.50371
369.80000;     5.58682
370.80000;     5.65733
371.80000;     5.72264
372.80000;     5.78153
373.80000;     5.83289
374.80000;     5.88429
375.80000;     5.93105
376.80000;     5.97909
377.80000;     6.02512
378.80000;     6.06974
379.80000;     6.11359
380.80000;     6.15553
381.80000;     6.19545
382.80000;     6.23097
383.80000;     6.26585
384.80000;     6.29752
385.80000;     6.32364
386.80000;     6.35113
387.80000;     6.37433
388.80000;     6.39657
389.80000;     6.41793
390.80000;     6.43852
391.80000;     6.45818
392.80000;     6.47695
393.80000;     6.49542
394.80000;     6.51420
395.80000;     6.53337
396.80000;     6.55160
397.80000;     6.56924
398.80000;     6.58758
399.80000;     6.60501
400.80000;     6.62148
401.80000;     6.63649
402.80000;     6.65329
403.80000;     6.66781
404.80000;     6.68292
405.80000;     6.69753
406.80000;     6.71249
407.80000;     6.72842
408.80000;     6.74298
409.80000;     6.75969
410.80000;     6.77551
411.80000;     6.79207
412.80000;     6.80853
413.80000;     6.82506
414.80000;     6.84204
415.80000;     6.85902
416.80000;     6.87758
417.80000;     6.89536
418.80000;     6.91354
419.80000;     6.93317
420.80000;     6.95160
421.80000;     6.97135
422.80000;     6.99254
423.80000;     7.01412
424.80000;     7.03548
425.80000;     7.05779
426.80000;     7.08045
427.80000;     7.10438
428.80000;     7.12910
429.80000;     7.15405
430.80000;     7.18063
431.80000;     7.20620
432.80000;     7.23267
433.80000;     7.26092
434.80000;     7.28964
435.80000;     7.31878
436.80000;     7.34912
437.80000;     7.37844
438.80000;     7.41160
439.80000;     7.44338
440.80000;     7.47636
441.80000;     7.51058
442.80000;     7.54481
443.80000;     7.58026
444.80000;     7.61589
445.80000;     7.65132
446.80000;     7.68883
447.80000;     7.72584
448.80000;     7.76880
449.80000;     7.81091
450.80000;     7.85440
451.80000;     7.89676
452.80000;     7.93795
453.80000;     7.98181
454.80000;     8.02839
455.80000;     8.07518
456.80000;     8.12180
457.80000;     8.16814
458.80000;     8.21590
459.80000;     8.26462
460.80000;     8.31975
461.80000;     8.37674
462.80000;     8.43298
463.80000;     8.49012
464.80000;     8.55035
465.80000;     8.61165
466.80000;     8.67485
467.80000;     8.73895
468.80000;     8.80258
469.80000;     8.87075
470.80000;     8.94041
471.80000;     9.01039
472.80000;     9.08336
473.80000;     9.15503
474.80000;     9.22631
475.80000;     9.29490
476.80000;     9.35899
477.80000;     9.41864
478.80000;     9.47450
479.80000;     9.52332
480.80000;     9.56938
481.80000;     9.60776
482.80000;     9.64086
483.80000;     9.66888
484.80000;     9.69176
485.80000;     9.71058
486.80000;     9.72555
487.80000;     9.73919
488.80000;     9.75223
489.80000;     9.76403
490.80000;     9.77320
491.80000;     9.78284
492.80000;     9.78984
493.80000;     9.79920
494.80000;     9.80577
495.80000;     9.81144
496.80000;     9.81723
497.80000;     9.82123
498.80000;     9.82566
499.80000;     9.82795
500.80000;     9.83110
501.80000;     9.83136
502.80000;     9.83158
503.80000;     9.83189
504.80000;     9.83158
505.80000;     9.83115
506.80000;     9.82952
507.80000;     9.82655
508.80000;     9.82222
509.80000;     9.81671
510.80000;     9.80792
511.80000;     9.79966
512.80000;     9.78936
513.80000;     9.77929
514.80000;     9.77034
515.80000;     9.75958
516.80000;     9.74693
517.80000;     9.73389
518.80000;     9.71647
519.80000;     9.69604
520.80000;     9.67551
521.80000;     9.65147
522.80000;     9.62244
523.80000;     9.59151
524.80000;     9.55799
525.80000;     9.52619
526.80000;     9.49472
527.80000;     9.46475
528.80000;     9.43437
529.80000;     9.40416
530.80000;     9.37145
531.80000;     9.33638
532.80000;     9.29690
533.80000;     9.25569
534.80000;     9.20879
535.80000;     9.15550
536.80000;     9.09145
537.80000;     9.02139
538.80000;     8.94150
539.80000;     8.86713
540.80000;     8.79332
541.80000;     8.70835
542.80000;     8.61472
543.80000;     8.52241
544.80000;     8.41902
545.80000;     8.30371
546.80000;     8.17610
547.80000;     8.03342
548.80000;     7.87440
549.80000;     7.70933
550.80000;     7.52480
551.80000;     7.30849
552.80000;     7.03727
553.80000;     6.68998
554.80000;     6.24580
555.80000;     5.62486
556.80000;     4.55270
557.80000;     3.60545
558.80000;     2.88204
559.80000;     2.30543
560.80000;     1.84270
561.80000;     1.47732
562.80000;     1.20000
563.80000;     0.97475
564.80000;     0.79712
565.80000;     0.65537
566.80000;     0.54331
567.80000;     0.45313
568.80000;     0.38377
569.80000;     0.32632
570.80000;     0.28054
571.80000;     0.24489
572.80000;     0.21590
573.80000;     0.19326
574.80000;     0.17510
575.80000;     0.15980
576.80000;     0.14657
577.80000;     0.13682
578.80000;     0.12936
579.80000;     0.12345
580.80000;     0.11730
581.80000;     0.11234
582.80000;     0.11083
583.80000;     0.10813
584.80000;     0.10354
585.80000;     0.10228
586.80000;     0.10044
587.80000; 9.9438e-002
588.80000; 9.7197e-002
589.80000; 9.7707e-002
590.80000; 9.5587e-002
591.80000; 9.4940e-002
592.80000; 9.3975e-002
593.80000; 9.3512e-002
594.80000; 9.3363e-002
595.80000; 9.2739e-002
596.80000; 9.1509e-002
597.80000; 9.1424e-002
598.80000; 9.1651e-002
599.80000; 9.1245e-002
600.80000; 9.0459e-002
601.80000; 9.1697e-002
602.80000; 9.0776e-002
603.80000; 9.1108e-002
604.80000; 8.9728e-002
605.80000; 9.0079e-002
606.80000; 8.9367e-002
607.80000; 8.9821e-002
608.80000; 8.9439e-002
609.80000; 8.9276e-002
610.80000; 8.8851e-002
611.80000; 8.9376e-002
612.80000; 8.9149e-002
613.80000; 8.9982e-002
614.80000; 8.8418e-002
615.80000; 8.6941e-002
616.80000; 8.7788e-002
617.80000; 8.7825e-002
618.80000; 8.7295e-002
619.80000; 8.6528e-002
620.80000; 8.7293e-002
621.80000; 8.7425e-002
622.80000; 8.7143e-002
623.80000; 8.7384e-002
624.80000; 8.6780e-002
625.80000; 8.6599e-002
626.80000; 8.6622e-002
627.80000; 8.7392e-002
628.80000; 8.6318e-002
629.80000; 8.6228e-002
630.80000; 8.6796e-002
631.80000; 8.6103e-002
632.80000; 8.6181e-002
633.80000; 8.6513e-002
634.80000; 8.6492e-002
635.80000; 8.6054e-002
636.80000; 8.6298e-002
637.80000; 8.6416e-002
638.80000; 8.5601e-002
639.80000; 8.4279e-002
640.80000; 8.5023e-002
641.80000; 8.4764e-002
642.80000; 8.3919e-002
643.80000; 8.4480e-002
644.80000; 8.3470e-002
645.80000; 8.2936e-002
646.80000; 8.3642e-002
647.80000; 8.3587e-002
648.80000; 8.3062e-002
649.80000; 8.3183e-002
650.80000; 8.2104e-002
651.80000; 8.1607e-002
652.80000; 8.1207e-002
653.80000; 8.0058e-002
654.80000; 7.8132e-002
655.80000; 7.7360e-002
656.80000; 7.9334e-002
657.80000; 7.9144e-002
658.80000; 7.8439e-002
659.80000; 7.8145e-002
660.80000; 7.8555e-002
661.80000; 7.8065e-002
662.80000; 7.7372e-002
663.80000; 7.7846e-002
664.80000; 7.7892e-002
665.80000; 7.8338e-002
666.80000; 7.7612e-002
667.80000; 7.6510e-002
668.80000; 7.5050e-002
669.80000; 7.3993e-002
670.80000; 7.3493e-002
671.80000; 7.3119e-002
672.80000; 7.2782e-002
673.80000; 6.8619e-002
674.80000; 6.5136e-002
675.80000; 6.4546e-002
676.80000; 6.2899e-002
677.80000; 6.1815e-002
678.80000; 6.0345e-002
679.80000; 6.0106e-002
680.80000; 5.8675e-002
681.80000; 5.8657e-002
682.80000; 5.6532e-002
683.80000; 5.6884e-002
684.80000; 5.6999e-002
685.80000; 5.4700e-002
686.80000; 5.4397e-002
687.80000; 5.3459e-002
688.80000; 5.3606e-002
689.80000; 5.2720e-002
690.80000; 5.2150e-002
691.80000; 5.2735e-002
692.80000; 5.1564e-002
693.80000; 5.1698e-002
694.80000; 5.1416e-002
695.80000; 5.0267e-002
696.80000; 5.1513e-002
697.80000; 5.1133e-002
698.80000; 5.0491e-002
699.80000; 5.0923e-002
700.80000; 5.0306e-002
701.80000; 5.0820e-002
702.80000; 4.9348e-002
703.80000; 5.0247e-002
704.80000; 5.0485e-002
705.80000; 4.9121e-002
706.80000; 4.8722e-002
707.80000; 4.7436e-002
708.80000; 4.8050e-002
709.80000; 4.8289e-002
710.80000; 4.8049e-002
711.80000; 4.8133e-002
712.80000; 4.8096e-002
713.80000; 4.8349e-002
714.80000; 4.8336e-002
715.80000; 4.8361e-002
716.80000; 4.7217e-002
717.80000; 4.7024e-002
718.80000; 4.7329e-002
719.80000; 4.6316e-002
720.80000; 4.6519e-002
721.80000; 4.6068e-002
722.80000; 4.6319e-002
723.80000; 4.5858e-002
724.80000; 4.7508e-002
725.80000; 4.5113e-002
726.80000; 4.2806e-002
727.80000; 3.8490e-002
728.80000; 3.0534e-002
729.80000; 2.1682e-002
730.80000; 1.4118e-002
731.80000; 6.9266e-003
732.80000; 2.0953e-004
733.80000;-3.2705e-003
734.80000;-4.9213e-003
735.80000;-1.0877e-003
736.80000; 6.6464e-003
737.80000; 1.5664e-002
738.80000; 2.1907e-002
739.80000; 2.8180e-002
740.80000; 3.2532e-002
741.80000; 3.5551e-002
742.80000; 3.8383e-002
743.80000; 3.8955e-002
744.80000; 4.0578e-002
745.80000; 4.0767e-002
746.80000; 4.0857e-002
747.80000; 3.9651e-002
748.80000; 3.8071e-002
749.80000; 3.8748e-002
750.80000; 3.6866e-002
751.80000; 3.4890e-002
752.80000; 3.2368e-002
753.80000; 2.9528e-002
754.80000; 3.0459e-002
755.80000; 2.9949e-002
756.80000; 3.2428e-002
757.80000; 3.4399e-002
758.80000; 3.7582e-002
759.80000; 4.1148e-002
760.80000; 4.3250e-002
761.80000; 4.4255e-002
762.80000; 4.5682e-002
763.80000; 4.6318e-002
764.80000; 4.9247e-002
765.80000; 5.0672e-002
766.80000; 5.1736e-002
767.80000; 5.3340e-002
768.80000; 5.4384e-002
769.80000; 5.4565e-002
770.80000; 5.5955e-002
771.80000; 5.7939e-002
772.80000; 5.7325e-002
773.80000; 5.8690e-002
774.80000; 5.9127e-002
775.80000; 5.7613e-002
776.80000; 5.7207e-002
777.80000; 5.8192e-002
778.80000; 5.6943e-002
779.80000; 5.5794e-002
780.80000; 5.6687e-002
781.80000; 5.6895e-002
782.80000; 5.6123e-002
783.80000; 5.5715e-002
784.80000; 5.6098e-002
785.80000; 5.6650e-002
786.80000; 5.6842e-002
787.80000; 5.6716e-002
788.80000; 5.7205e-002
789.80000; 5.6409e-002
790.80000; 5.5811e-002
791.80000; 5.5888e-002
792.80000; 5.7510e-002
793.80000; 5.7323e-002