File: examples/Birch/TGA_DSC data T18/13WaT18 5 K min air 16.2.07.TG.txt
#FILE:                        13WaT18 5 K min air 16.2.07.dsu
#FORMAT:                      NETZSCH4
#IDENTITY:                    13 WaT18 5 K min air
#DECIMAL:                     POINT
#SEPARATOR:                   SEMICOLON
#MTYPE:                       TG
#INSTRUMENT:                  NETZSCH STA 449C
#PROJECT:                     vtt
#DATE/TIME:                   16.2.2007 14:13:33
#CORR. FILE:                  correction 5Kmin air 800 C.bsu
#LABORATORY:                  EO
#OPERATOR:                    TL
#REMARK:
#SAMPLE:                      13 WaT18
#SAMPLE MASS /mg:             12.341
#MATERIAL:                    Empty crucibles
#REFERENCE:                   al2o3
#REFERENCE MASS /mg:          40.312
#TYPE OF CRUCIBLE:            DSC/TG pan Al2O3
#SAMPLE CRUCIBLE MASS /mg:    0.000
#REFERENCE CRUCIBLE MASS /mg: 0.000
#PROTECTIVE GAS:              N2
#PURGE GAS 1:                 air
#FLOW RATE 1 /(ml/min):       40
#PURGE GAS 2:
#FLOW RATE 2:
#DSC RANGE /æm:               5000
#TG RANGE /æm:                5000
#CORR. CODE:                  020
#EXO:                         +1
#RANGE:                       20.0/5.00(K/min)/800.0
#SEGMENT:                     S1/1

##Temp./øC;Mass/%
 21.94700;100.00000
 22.94700;100.10236
 23.94700;100.11809
 24.94700;100.10204
 25.94700;100.07468
 26.94700;100.04465
 27.94700;100.00964
 28.94700; 99.98638
 29.94700; 99.96029
 30.94700; 99.93144
 31.94700; 99.89799
 32.94700; 99.87311
 33.94700; 99.84309
 34.94700; 99.81187
 35.94700; 99.78504
 36.94700; 99.76274
 37.94700; 99.73251
 38.94700; 99.69918
 39.94700; 99.65996
 40.94700; 99.61990
 41.94700; 99.57827
 42.94700; 99.53985
 43.94700; 99.50756
 44.94700; 99.45946
 45.94700; 99.41829
 46.94700; 99.38200
 47.94700; 99.33395
 48.94700; 99.28601
 49.94700; 99.23912
 50.94700; 99.19093
 51.94700; 99.14072
 52.94700; 99.08481
 53.94700; 99.02954
 54.94700; 98.97456
 55.94700; 98.91750
 56.94700; 98.85999
 57.94700; 98.79823
 58.94700; 98.73827
 59.94700; 98.67420
 60.94700; 98.61616
 61.94700; 98.55464
 62.94700; 98.49167
 63.94700; 98.42363
 64.94700; 98.36042
 65.94700; 98.29244
 66.94700; 98.22553
 67.94700; 98.16289
 68.94700; 98.09407
 69.94700; 98.02910
 70.94700; 97.97072
 71.94700; 97.90275
 72.94700; 97.84308
 73.94700; 97.78116
 74.94700; 97.72103
 75.94700; 97.66657
 76.94700; 97.61214
 77.94700; 97.55559
 78.94700; 97.50045
 79.94700; 97.44909
 80.94700; 97.40716
 81.94700; 97.35657
 82.94700; 97.30950
 83.94700; 97.26838
 84.94700; 97.22830
 85.94700; 97.18326
 86.94700; 97.14673
 87.94700; 97.11780
 88.94700; 97.08653
 89.94700; 97.05106
 90.94700; 97.02358
 91.94700; 96.99558
 92.94700; 96.97070
 93.94700; 96.94514
 94.94700; 96.92727
 95.94700; 96.90424
 96.94700; 96.88610
 97.94700; 96.87261
 98.94700; 96.85567
 99.94700; 96.83599
100.94700; 96.82263
101.94700; 96.80446
102.94700; 96.79557
103.94700; 96.78781
104.94700; 96.77799
105.94700; 96.76528
106.94700; 96.75640
107.94700; 96.74715
108.94700; 96.74071
109.94700; 96.73405
110.94700; 96.72923
111.94700; 96.72271
112.94700; 96.71488
113.94700; 96.71249
114.94700; 96.70761
115.94700; 96.70119
116.94700; 96.69721
117.94700; 96.69557
118.94700; 96.69085
119.94700; 96.68610
120.94700; 96.68291
121.94700; 96.67985
122.94700; 96.67610
123.94700; 96.67498
124.94700; 96.67097
125.94700; 96.66779
126.94700; 96.66559
127.94700; 96.66316
128.94700; 96.66072
129.94700; 96.66574
130.94700; 96.66965
131.94700; 96.66880
132.94700; 96.66478
133.94700; 96.66315
134.94700; 96.65844
135.94700; 96.64712
136.94700; 96.64382
137.94700; 96.64426
138.94700; 96.64323
139.94700; 96.63999
140.94700; 96.64017
141.94700; 96.64091
142.94700; 96.64175
143.94700; 96.63772
144.94700; 96.63479
145.94700; 96.63487
146.94700; 96.63367
147.94700; 96.63212
148.94700; 96.63317
149.94700; 96.63299
150.94700; 96.63163
151.94700; 96.62907
152.94700; 96.62654
153.94700; 96.62587
154.94700; 96.62231
155.94700; 96.62170
156.94700; 96.61924
157.94700; 96.61697
158.94700; 96.61426
159.94700; 96.61211
160.94700; 96.61050
161.94700; 96.60893
162.94700; 96.60541
163.94700; 96.60401
164.94700; 96.60335
165.94700; 96.60141
166.94700; 96.60000
167.94700; 96.59651
168.94700; 96.59275
169.94700; 96.58707
170.94700; 96.58158
171.94700; 96.57562
172.94700; 96.57369
173.94700; 96.56968
174.94700; 96.56516
175.94700; 96.56153
176.94700; 96.55713
177.94700; 96.54939
178.94700; 96.54416
179.94700; 96.53558
180.94700; 96.52463
181.94700; 96.52061
182.94700; 96.51246
183.94700; 96.50234
184.94700; 96.49017
185.94700; 96.48267
186.94700; 96.47224
187.94700; 96.46172
188.94700; 96.45346
189.94700; 96.43717
190.94700; 96.42713
191.94700; 96.41814
192.94700; 96.40504
193.94700; 96.38698
194.94700; 96.37196
195.94700; 96.35881
196.94700; 96.34602
197.94700; 96.33323
198.94700; 96.31253
199.94700; 96.30205
200.94700; 96.27924
201.94700; 96.26300
202.94700; 96.24506
203.94700; 96.23123
204.94700; 96.20527
205.94700; 96.19226
206.94700; 96.16863
207.94700; 96.14685
208.94700; 96.12328
209.94700; 96.10120
210.94700; 96.08311
211.94700; 96.05336
212.94700; 96.03094
213.94700; 96.00356
214.94700; 95.97587
215.94700; 95.94584
216.94700; 95.92048
217.94700; 95.88749
218.94700; 95.85178
219.94700; 95.82195
220.94700; 95.78486
221.94700; 95.74496
222.94700; 95.70560
223.94700; 95.66044
224.94700; 95.61197
225.94700; 95.56801
226.94700; 95.51887
227.94700; 95.46836
228.94700; 95.41124
229.94700; 95.35061
230.94700; 95.29364
231.94700; 95.22763
232.94700; 95.16024
233.94700; 95.08999
234.94700; 95.00803
235.94700; 94.92679
236.94700; 94.83947
237.94700; 94.75234
238.94700; 94.65683
239.94700; 94.55301
240.94700; 94.44043
241.94700; 94.32969
242.94700; 94.20356
243.94700; 94.07696
244.94700; 93.93860
245.94700; 93.79313
246.94700; 93.63528
247.94700; 93.47186
248.94700; 93.28295
249.94700; 93.08938
250.94700; 92.89083
251.94700; 92.67449
252.94700; 92.44333
253.94700; 92.19013
254.94700; 91.94330
255.94700; 91.66109
256.94700; 91.36992
257.94700; 91.04799
258.94700; 90.71532
259.94700; 90.36542
260.94700; 89.98785
261.94700; 89.60111
262.94700; 89.18504
263.94700; 88.75787
264.94700; 88.29803
265.94700; 87.83863
266.94700; 87.34933
267.94700; 86.83568
268.94700; 86.31431
269.94700; 85.79952
270.94700; 85.25765
271.94700; 84.69945
272.94700; 84.00052
273.94700; 83.60003
274.94700; 82.99777
275.94700; 82.42827
276.94700; 81.87390
277.94700; 81.47402
278.94700; 80.86417
279.94700; 80.26105
280.94700; 79.62774
281.94700; 78.92673
282.94700; 78.17901
283.94700; 77.44947
284.94700; 76.68197
285.94700; 75.91833
286.94700; 75.15760
287.94700; 74.43098
288.94700; 73.72747
289.94700; 72.99325
290.94700; 72.45333
291.94700; 71.81399
292.94700; 71.12324
293.94700; 70.39779
294.94700; 69.72597
295.94700; 69.03570
296.94700; 68.33799
297.94700; 67.64692
298.94700; 66.93020
299.94700; 66.13576
300.94700; 65.35595
301.94700; 64.78521
302.94700; 63.91467
303.94700; 62.96103
304.94700; 61.96536
305.94700; 60.89780
306.94700; 59.78445
307.94700; 58.40302
308.94700; 57.10018
309.94700; 55.74884
310.94700; 54.28696
311.94700; 52.74650
312.94700; 51.14707
313.94700; 49.56287
314.94700; 47.81643
315.94700; 46.06673
316.94700; 44.27079
317.94700; 42.00799
318.94700; 37.62247
319.94700; 36.38377
320.94700; 35.79395
321.94700; 35.36071
322.94700; 34.98197
323.94700; 34.63985
324.94700; 34.34202
325.94700; 34.04115
326.94700; 33.77904
327.94700; 33.49499
328.94700; 33.23470
329.94700; 32.97118
330.94700; 32.72669
331.94700; 32.49132
332.94700; 32.23171
333.94700; 31.99959
334.94700; 31.75124
335.94700; 31.52324
336.94700; 31.29362
337.94700; 31.05602
338.94700; 30.83366
339.94700; 30.61845
340.94700; 30.39078
341.94700; 30.17729
342.94700; 29.96007
343.94700; 29.74704
344.94700; 29.53633
345.94700; 29.33095
346.94700; 29.12279
347.94700; 28.92463
348.94700; 28.73265
349.94700; 28.52778
350.94700; 28.33411
351.94700; 28.12994
352.94700; 27.95617
353.94700; 27.76139
354.94700; 27.57502
355.94700; 27.38211
356.94700; 27.21043
357.94700; 27.02249
358.94700; 26.84880
359.94700; 26.66711
360.94700; 26.48137
361.94700; 26.31244
362.94700; 26.13356
363.94700; 25.95116
364.94700; 25.78876
365.94700; 25.61760
366.94700; 25.44787
367.94700; 25.26909
368.94700; 25.09670
369.94700; 24.92589
370.94700; 24.75325
371.94700; 24.58728
372.94700; 24.42123
373.94700; 24.24712
374.94700; 24.08581
375.94700; 23.90747
376.94700; 23.74785
377.94700; 23.58603
378.94700; 23.40452
379.94700; 23.24621
380.94700; 23.06957
381.94700; 22.91654
382.94700; 22.73578
383.94700; 22.57980
384.94700; 22.39885
385.94700; 22.23885
386.94700; 22.06838
387.94700; 21.89664
388.94700; 21.72907
389.94700; 21.55404
390.94700; 21.38367
391.94700; 21.21694
392.94700; 21.04997
393.94700; 20.87576
394.94700; 20.69752
395.94700; 20.51874
396.94700; 20.34267
397.94700; 20.16383
398.94700; 19.97794
399.94700; 19.79177
400.94700; 19.60103
401.94700; 19.42659
402.94700; 19.24108
403.94700; 19.05045
404.94700; 18.85812
405.94700; 18.66138
406.94700; 18.46410
407.94700; 18.25517
408.94700; 18.05489
409.94700; 17.85399
410.94700; 17.63354
411.94700; 17.42502
412.94700; 17.21039
413.94700; 16.97884
414.94700; 16.75253
415.94700; 16.51263
416.94700; 16.28228
417.94700; 16.03933
418.94700; 15.77762
419.94700; 15.51094
420.94700; 15.24735
421.94700; 14.96904
422.94700; 14.67994
423.94700; 14.38095
424.94700; 14.07646
425.94700; 13.76015
426.94700; 13.41764
427.94700; 13.06441
428.94700; 12.69011
429.94700; 12.27314
430.94700; 11.82881
431.94700; 11.32521
432.94700; 10.65733
433.94700;  9.18096
434.94700;  7.97862
435.94700;  7.03149
436.94700;  6.03306
437.94700;  4.81679
438.94700;  3.78084
439.94700;  2.84844
440.94700;  2.64469
441.94700;  2.51158
442.94700;  2.39167
443.94700;  2.27349
444.94700;  2.15748
445.94700;  2.04149
446.94700;  1.91415
447.94700;  1.78652
448.94700;  1.67772
449.94700;  1.58548
450.94700;  1.49607
451.94700;  1.41705
452.94700;  1.34575
453.94700;  1.27849
454.94700;  1.22165
455.94700;  1.17503
456.94700;  1.13485
457.94700;  1.09923
458.94700;  1.08134
459.94700;  1.05740
460.94700;  1.04684
461.94700;  1.03470
462.94700;  1.02906
463.94700;  1.02342
464.94700;  1.02099
465.94700;  1.01782
466.94700;  1.02083
467.94700;  1.02091
468.94700;  1.02177
469.94700;  1.02387
470.94700;  1.02822
471.94700;  1.03070
472.94700;  1.03230
473.94700;  1.03561
474.94700;  1.03722
475.94700;  1.03885
476.94700;  1.03882
477.94700;  1.04048
478.94700;  1.04208
479.94700;  1.04529
480.94700;  1.04847
481.94700;  1.05068
482.94700;  1.05096
483.94700;  1.05095
484.94700;  1.05502
485.94700;  1.05505
486.94700;  1.05682
487.94700;  1.05950
488.94700;  1.06149
489.94700;  1.06230
490.94700;  1.06593
491.94700;  1.06562
492.94700;  1.06474
493.94700;  1.06553
494.94700;  1.06719
495.94700;  1.07200
496.94700;  1.07449
497.94700;  1.07358
498.94700;  1.07293
499.94700;  1.07615
500.94700;  1.07851
501.94700;  1.07770
502.94700;  1.08094
503.94700;  1.08256
504.94700;  1.08335
505.94700;  1.08419
506.94700;  1.08581
507.94700;  1.08419
508.94700;  1.08729
509.94700;  1.08886
510.94700;  1.08661
511.94700;  1.08662
512.94700;  1.08655
513.94700;  1.08861
514.94700;  1.08745
515.94700;  1.09029
516.94700;  1.09180
517.94700;  1.09514
518.94700;  1.09225
519.94700;  1.09344
520.94700;  1.09705
521.94700;  1.09877
522.94700;  1.09872
523.94700;  1.10042
524.94700;  1.09629
525.94700;  1.09793
526.94700;  1.10025
527.94700;  1.10119
528.94700;  1.10116
529.94700;  1.10036
530.94700;  1.10365
531.94700;  1.10451
532.94700;  1.10772
533.94700;  1.10599
534.94700;  1.10525
535.94700;  1.10607
536.94700;  1.10606
537.94700;  1.10606
538.94700;  1.10607
539.94700;  1.10769
540.94700;  1.10931
541.94700;  1.11012
542.94700;  1.10931
543.94700;  1.10846
544.94700;  1.11011
545.94700;  1.11093
546.94700;  1.11266
547.94700;  1.11085
548.94700;  1.11410
549.94700;  1.11586
550.94700;  1.11581
551.94700;  1.11746
552.94700;  1.11569
553.94700;  1.11620
554.94700;  1.11417
555.94700;  1.11410
556.94700;  1.11469
557.94700;  1.11050
558.94700;  1.11174
559.94700;  1.11174
560.94700;  1.11360
561.94700;  1.11470
562.94700;  1.11366
563.94700;  1.11573
564.94700;  1.11741
565.94700;  1.11881
566.94700;  1.11822
567.94700;  1.11660
568.94700;  1.11741
569.94700;  1.11559
570.94700;  1.11663
571.94700;  1.11822
572.94700;  1.12074
573.94700;  1.12219
574.94700;  1.12229
575.94700;  1.12075
576.94700;  1.12308
577.94700;  1.12464
578.94700;  1.12308
579.94700;  1.12389
580.94700;  1.12307
581.94700;  1.12309
582.94700;  1.12308
583.94700;  1.12634
584.94700;  1.12551
585.94700;  1.12387
586.94700;  1.12469
587.94700;  1.12389
588.94700;  1.12556
589.94700;  1.12481
590.94700;  1.12386
591.94700;  1.12539
592.94700;  1.12632
593.94700;  1.12548
594.94700;  1.12393
595.94700;  1.12860
596.94700;  1.13116
597.94700;  1.12814
598.94700;  1.12708
599.94700;  1.12768
600.94700;  1.13036
601.94700;  1.12793
602.94700;  1.12712
603.94700;  1.12711
604.94700;  1.12707
605.94700;  1.12875
606.94700;  1.12797
607.94700;  1.12844
608.94700;  1.12954
609.94700;  1.13039
610.94700;  1.12903
611.94700;  1.12648
612.94700;  1.12154
613.94700;  1.12067
614.94700;  1.12152
615.94700;  1.12113
616.94700;  1.12279
617.94700;  1.11694
618.94700;  1.11587
619.94700;  1.11415
620.94700;  1.11297
621.94700;  1.10732
622.94700;  1.10677
623.94700;  1.10608
624.94700;  1.10494
625.94700;  1.10318
626.94700;  1.10282
627.94700;  1.10283
628.94700;  1.10334
629.94700;  1.10208
630.94700;  1.10091
631.94700;  1.10125
632.94700;  1.10045
633.94700;  1.10144
634.94700;  1.10199
635.94700;  1.10201
636.94700;  1.10201
637.94700;  1.10039
638.94700;  1.09710
639.94700;  1.09838
640.94700;  1.09557
641.94700;  1.09559
642.94700;  1.09307
643.94700;  1.09476
644.94700;  1.09441
645.94700;  1.09289
646.94700;  1.09227
647.94700;  1.09226
648.94700;  1.09307
649.94700;  1.09223
650.94700;  1.09069
651.94700;  1.09153
652.94700;  1.09173
653.94700;  1.09062
654.94700;  1.08966
655.94700;  1.08900
656.94700;  1.09074
657.94700;  1.08901
658.94700;  1.08560
659.94700;  1.08490
660.94700;  1.08336
661.94700;  1.08268
662.94700;  1.08519
663.94700;  1.08353
664.94700;  1.08252
665.94700;  1.08420
666.94700;  1.08489
667.94700;  1.08186
668.94700;  1.08244
669.94700;  1.07688
670.94700;  1.07848
671.94700;  1.07933
672.94700;  1.07933
673.94700;  1.08012
674.94700;  1.07941
675.94700;  1.08087
676.94700;  1.07771
677.94700;  1.07692
678.94700;  1.07689
679.94700;  1.07280
680.94700;  1.07378
681.94700;  1.07625
682.94700;  1.07680
683.94700;  1.07445
684.94700;  1.07446
685.94700;  1.07527
686.94700;  1.07611
687.94700;  1.07690
688.94700;  1.07770
689.94700;  1.07607
690.94700;  1.07529
691.94700;  1.07447
692.94700;  1.07443
693.94700;  1.07608
694.94700;  1.07608
695.94700;  1.07370
696.94700;  1.07932
697.94700;  1.08013
698.94700;  1.08013
699.94700;  1.07771
700.94700;  1.07852
701.94700;  1.07932
702.94700;  1.08010
703.94700;  1.07932
704.94700;  1.08016
705.94700;  1.07773
706.94700;  1.07695
707.94700;  1.07608
708.94700;  1.07854
709.94700;  1.07689
710.94700;  1.07675
711.94700;  1.07760
712.94700;  1.07461
713.94700;  1.07447
714.94700;  1.07693
715.94700;  1.07442
716.94700;  1.07528
717.94700;  1.07758
718.94700;  1.07932
719.94700;  1.07913
720.94700;  1.07623
721.94700;  1.07528
722.94700;  1.07464
723.94700;  1.07530
724.94700;  1.07419
725.94700;  1.07518
726.94700;  1.07748
727.94700;  1.07827
728.94700;  1.08179
729.94700;  1.08176
730.94700;  1.08101
731.94700;  1.07709
732.94700;  1.07851
733.94700;  1.07798
734.94700;  1.07771
735.94700;  1.07934
736.94700;  1.07919
737.94700;  1.08193
738.94700;  1.08210
739.94700;  1.08052
740.94700;  1.07720
741.94700;  1.07606
742.94700;  1.07660
743.94700;  1.07688
744.94700;  1.07894
745.94700;  1.07614
746.94700;  1.07605
747.94700;  1.07729
748.94700;  1.08061
749.94700;  1.07976
750.94700;  1.08098
751.94700;  1.08104
752.94700;  1.08140
753.94700;  1.08095
754.94700;  1.08177
755.94700;  1.08028
756.94700;  1.07852
757.94700;  1.07844
758.94700;  1.08000
759.94700;  1.08095
760.94700;  1.08169
761.94700;  1.08577
762.94700;  1.08342
763.94700;  1.08148
764.94700;  1.08007
765.94700;  1.07930
766.94700;  1.08016
767.94700;  1.08116
768.94700;  1.08017
769.94700;  1.07769
770.94700;  1.07882
771.94700;  1.07694
772.94700;  1.07679
773.94700;  1.07719
774.94700;  1.07878
775.94700;  1.07741
776.94700;  1.07508
777.94700;  1.07444
778.94700;  1.07611
779.94700;  1.07504
780.94700;  1.07451
781.94700;  1.07506
782.94700;  1.07365
783.94700;  1.07387
784.94700;  1.07531
785.94700;  1.07444
786.94700;  1.07604
787.94700;  1.07529
788.94700;  1.07366
789.94700;  1.07207
790.94700;  1.07202
791.94700;  1.06960
792.94700;  1.06554
793.94700;  1.06445
794.94700;  1.06470
795.94700;  1.06416
796.94700;  1.06805
797.94700;  1.06474