File: examples/Birch/TGA_DSC data T18/13WaT18 20 K min air 7.2.2007.TG.txt
#FILE:                        13WaT18 20 K min air 7.2.2007.dsu
#FORMAT:                      NETZSCH4
#IDENTITY:                    13WaT18 20 K min air
#DECIMAL:                     POINT
#SEPARATOR:                   SEMICOLON
#MTYPE:                       TG
#INSTRUMENT:                  NETZSCH STA 449C
#PROJECT:                     vtt
#DATE/TIME:                   7.2.2007 8:22:58
#CORR. FILE:                  correction 20Kmin air 800 C.bsu
#LABORATORY:                  EO
#OPERATOR:                    TL
#REMARK:
#SAMPLE:                      13WaT18
#SAMPLE MASS /mg:             12.498
#MATERIAL:                    Empty crucibles
#REFERENCE:                   al2o3
#REFERENCE MASS /mg:          40.312
#TYPE OF CRUCIBLE:            DSC/TG pan Al2O3
#SAMPLE CRUCIBLE MASS /mg:    0.000
#REFERENCE CRUCIBLE MASS /mg: 0.000
#PROTECTIVE GAS:              N2
#PURGE GAS 1:                 air
#FLOW RATE 1 /(ml/min):       40
#PURGE GAS 2:
#FLOW RATE 2:
#DSC RANGE /æm:               5000
#TG RANGE /æm:                5000
#CORR. CODE:                  020
#EXO:                         +1
#RANGE:                       20.0/20.00(K/min)/800.0
#SEGMENT:                     S1/1

##Temp./øC;Mass/%
 19.80000;99.98172
 20.80000;99.97887
 21.80000;99.97382
 22.80000;99.97205
 23.80000;99.97530
 24.80000;99.96421
 25.80000;99.95798
 26.80000;99.97042
 27.80000;99.96770
 28.80000;99.96715
 29.80000;99.96724
 30.80000;99.96886
 31.80000;99.96374
 32.80000;99.96042
 33.80000;99.96799
 34.80000;99.96644
 35.80000;99.96572
 36.80000;99.96549
 37.80000;99.96217
 38.80000;99.95431
 39.80000;99.94895
 40.80000;99.94559
 41.80000;99.93988
 42.80000;99.93599
 43.80000;99.93118
 44.80000;99.92047
 45.80000;99.91036
 46.80000;99.89985
 47.80000;99.88935
 48.80000;99.88307
 49.80000;99.87750
 50.80000;99.86662
 51.80000;99.85449
 52.80000;99.84345
 53.80000;99.83414
 54.80000;99.81989
 55.80000;99.80572
 56.80000;99.79075
 57.80000;99.78148
 58.80000;99.77440
 59.80000;99.76431
 60.80000;99.75081
 61.80000;99.73964
 62.80000;99.72823
 63.80000;99.70941
 64.80000;99.68668
 65.80000;99.66598
 66.80000;99.64593
 67.80000;99.62830
 68.80000;99.60741
 69.80000;99.58703
 70.80000;99.56657
 71.80000;99.54529
 72.80000;99.52214
 73.80000;99.49755
 74.80000;99.47243
 75.80000;99.44782
 76.80000;99.42155
 77.80000;99.39146
 78.80000;99.36661
 79.80000;99.34195
 80.80000;99.31693
 81.80000;99.28781
 82.80000;99.25698
 83.80000;99.22528
 84.80000;99.19806
 85.80000;99.17061
 86.80000;99.13822
 87.80000;99.10840
 88.80000;99.08105
 89.80000;99.05455
 90.80000;99.02458
 91.80000;98.99582
 92.80000;98.96296
 93.80000;98.93157
 94.80000;98.90146
 95.80000;98.87310
 96.80000;98.84610
 97.80000;98.81707
 98.80000;98.78862
 99.80000;98.76209
100.80000;98.73782
101.80000;98.71531
102.80000;98.69374
103.80000;98.67258
104.80000;98.65129
105.80000;98.63006
106.80000;98.60843
107.80000;98.58579
108.80000;98.56542
109.80000;98.54953
110.80000;98.53643
111.80000;98.52166
112.80000;98.50850
113.80000;98.49668
114.80000;98.48465
115.80000;98.47470
116.80000;98.46323
117.80000;98.45142
118.80000;98.43924
119.80000;98.42757
120.80000;98.41809
121.80000;98.41201
122.80000;98.40582
123.80000;98.40191
124.80000;98.39660
125.80000;98.38854
126.80000;98.38114
127.80000;98.37462
128.80000;98.37216
129.80000;98.36771
130.80000;98.36689
131.80000;98.36452
132.80000;98.36140
133.80000;98.35708
134.80000;98.35365
135.80000;98.35076
136.80000;98.34799
137.80000;98.34416
138.80000;98.33757
139.80000;98.33327
140.80000;98.33253
141.80000;98.33253
142.80000;98.33214
143.80000;98.33172
144.80000;98.32889
145.80000;98.32692
146.80000;98.32458
147.80000;98.32293
148.80000;98.32107
149.80000;98.31724
150.80000;98.30992
151.80000;98.30289
152.80000;98.30061
153.80000;98.29973
154.80000;98.29966
155.80000;98.30049
156.80000;98.30128
157.80000;98.30215
158.80000;98.30293
159.80000;98.30331
160.80000;98.30210
161.80000;98.30081
162.80000;98.29872
163.80000;98.29578
164.80000;98.29340
165.80000;98.28998
166.80000;98.28788
167.80000;98.28588
168.80000;98.28293
169.80000;98.28083
170.80000;98.27951
171.80000;98.27812
172.80000;98.27606
173.80000;98.27395
174.80000;98.27031
175.80000;98.26813
176.80000;98.26601
177.80000;98.26310
178.80000;98.25988
179.80000;98.25550
180.80000;98.24982
181.80000;98.24350
182.80000;98.23813
183.80000;98.23363
184.80000;98.23224
185.80000;98.23005
186.80000;98.22701
187.80000;98.22111
188.80000;98.21193
189.80000;98.20543
190.80000;98.20378
191.80000;98.19954
192.80000;98.19195
193.80000;98.17973
194.80000;98.17289
195.80000;98.16684
196.80000;98.15883
197.80000;98.14816
198.80000;98.14012
199.80000;98.13105
200.80000;98.12433
201.80000;98.11901
202.80000;98.10736
203.80000;98.09728
204.80000;98.08615
205.80000;98.07170
206.80000;98.05713
207.80000;98.04396
208.80000;98.03466
209.80000;98.02055
210.80000;98.00427
211.80000;97.98944
212.80000;97.97565
213.80000;97.96022
214.80000;97.94257
215.80000;97.92657
216.80000;97.91115
217.80000;97.89598
218.80000;97.87866
219.80000;97.85961
220.80000;97.83965
221.80000;97.82172
222.80000;97.79964
223.80000;97.77594
224.80000;97.75390
225.80000;97.73460
226.80000;97.71290
227.80000;97.68872
228.80000;97.66665
229.80000;97.64543
230.80000;97.62186
231.80000;97.59374
232.80000;97.56470
233.80000;97.53547
234.80000;97.50492
235.80000;97.47070
236.80000;97.43317
237.80000;97.39672
238.80000;97.35827
239.80000;97.31665
240.80000;97.27740
241.80000;97.23439
242.80000;97.18907
243.80000;97.14210
244.80000;97.07359
245.80000;97.01555
246.80000;96.96121
247.80000;96.89080
248.80000;96.82530
249.80000;96.76078
250.80000;96.69090
251.80000;96.61362
252.80000;96.53633
253.80000;96.45593
254.80000;96.36158
255.80000;96.27188
256.80000;96.17912
257.80000;96.08372
258.80000;95.98299
259.80000;95.88074
260.80000;95.76778
261.80000;95.64262
262.80000;95.50869
263.80000;95.37271
264.80000;95.23097
265.80000;94.98834
266.80000;94.73018
267.80000;94.60514
268.80000;94.43310
269.80000;94.28369
270.80000;94.11778
271.80000;93.71960
272.80000;93.52891
273.80000;93.28943
274.80000;93.00091
275.80000;92.71066
276.80000;92.43120
277.80000;92.12333
278.80000;91.82759
279.80000;91.45207
280.80000;91.13074
281.80000;90.77070
282.80000;90.40030
283.80000;90.03888
284.80000;89.59575
285.80000;89.20910
286.80000;88.79422
287.80000;88.33041
288.80000;87.81350
289.80000;87.34152
290.80000;86.86936
291.80000;86.37423
292.80000;85.82599
293.80000;85.27187
294.80000;84.71669
295.80000;84.16117
296.80000;83.57648
297.80000;83.02645
298.80000;82.42854
299.80000;81.80578
300.80000;81.20547
301.80000;80.55149
302.80000;79.93786
303.80000;79.32331
304.80000;78.67984
305.80000;77.96373
306.80000;77.35412
307.80000;76.70808
308.80000;76.07329
309.80000;75.36949
310.80000;74.71063
311.80000;74.04665
312.80000;73.38216
313.80000;72.68715
314.80000;72.00846
315.80000;71.31579
316.80000;70.64228
317.80000;69.95175
318.80000;69.27699
319.80000;68.58760
320.80000;67.90320
321.80000;67.21566
322.80000;66.55094
323.80000;65.86404
324.80000;65.16317
325.80000;64.39305
326.80000;63.68056
327.80000;62.93943
328.80000;62.20335
329.80000;61.45564
330.80000;60.68965
331.80000;59.92963
332.80000;59.10005
333.80000;58.26614
334.80000;57.43902
335.80000;56.64370
336.80000;55.80307
337.80000;54.83191
338.80000;53.98050
339.80000;53.12884
340.80000;52.17544
341.80000;51.26026
342.80000;50.35311
343.80000;49.43480
344.80000;48.47841
345.80000;47.61417
346.80000;46.67189
347.80000;45.72890
348.80000;44.74298
349.80000;43.79151
350.80000;42.88257
351.80000;41.78028
352.80000;40.81899
353.80000;39.79947
354.80000;38.63722
355.80000;37.35681
356.80000;35.65074
357.80000;32.78398
358.80000;31.70323
359.80000;31.11918
360.80000;30.55745
361.80000;30.32676
362.80000;30.12177
363.80000;29.93904
364.80000;29.77350
365.80000;29.62212
366.80000;29.48621
367.80000;29.34894
368.80000;29.22113
369.80000;29.09039
370.80000;28.96192
371.80000;28.83476
372.80000;28.70700
373.80000;28.57543
374.80000;28.45559
375.80000;28.33667
376.80000;28.21931
377.80000;28.09837
378.80000;27.98078
379.80000;27.86036
380.80000;27.74112
381.80000;27.62897
382.80000;27.51622
383.80000;27.40054
384.80000;27.28535
385.80000;27.15807
386.80000;27.03998
387.80000;26.92335
388.80000;26.80697
389.80000;26.69130
390.80000;26.57419
391.80000;26.45461
392.80000;26.34002
393.80000;26.22035
394.80000;26.09872
395.80000;25.97516
396.80000;25.85870
397.80000;25.74474
398.80000;25.63075
399.80000;25.51328
400.80000;25.39420
401.80000;25.27445
402.80000;25.15548
403.80000;25.03570
404.80000;24.91292
405.80000;24.79706
406.80000;24.67808
407.80000;24.55817
408.80000;24.44177
409.80000;24.32531
410.80000;24.20918
411.80000;24.09069
412.80000;23.96119
413.80000;23.84212
414.80000;23.72212
415.80000;23.60349
416.80000;23.48592
417.80000;23.36389
418.80000;23.24224
419.80000;23.12134
420.80000;22.99979
421.80000;22.87544
422.80000;22.74810
423.80000;22.61573
424.80000;22.49343
425.80000;22.37036
426.80000;22.24406
427.80000;22.11960
428.80000;21.99257
429.80000;21.86430
430.80000;21.73434
431.80000;21.60571
432.80000;21.47496
433.80000;21.34017
434.80000;21.19868
435.80000;21.06566
436.80000;20.92895
437.80000;20.78195
438.80000;20.63788
439.80000;20.49485
440.80000;20.35532
441.80000;20.21471
442.80000;20.07181
443.80000;19.92446
444.80000;19.77811
445.80000;19.63202
446.80000;19.47935
447.80000;19.32875
448.80000;19.16738
449.80000;19.01366
450.80000;18.85595
451.80000;18.69723
452.80000;18.53617
453.80000;18.37377
454.80000;18.01577
455.80000;17.90014
456.80000;17.78419
457.80000;17.62703
458.80000;17.51864
459.80000;17.20411
460.80000;17.04765
461.80000;16.89841
462.80000;16.74851
463.80000;16.43492
464.80000;16.28010
465.80000;16.15177
466.80000;15.97789
467.80000;15.87769
468.80000;15.50683
469.80000;15.34397
470.80000;15.17480
471.80000;14.99980
472.80000;14.63317
473.80000;14.47728
474.80000;14.33057
475.80000;14.13144
476.80000;13.75452
477.80000;13.59424
478.80000;13.45096
479.80000;13.26211
480.80000;13.07361
481.80000;12.74698
482.80000;12.57203
483.80000;12.39181
484.80000;12.22659
485.80000;11.87352
486.80000;11.70425
487.80000;11.54513
488.80000;11.37464
489.80000;10.99373
490.80000;10.84206
491.80000;10.70087
492.80000;10.52275
493.80000;10.29841
494.80000;10.03210
495.80000; 9.88787
496.80000; 9.71227
497.80000; 9.60216
498.80000; 9.23285
499.80000; 9.07978
500.80000; 8.90814
501.80000; 8.76881
502.80000; 8.43513
503.80000; 8.26477
504.80000; 8.10583
505.80000; 7.95985
506.80000; 7.64535
507.80000; 7.49506
508.80000; 7.33858
509.80000; 7.20671
510.80000; 6.86343
511.80000; 6.68235
512.80000; 6.49014
513.80000; 6.34464
514.80000; 6.19465
515.80000; 6.04298
516.80000; 5.90564
517.80000; 5.73546
518.80000; 5.42510
519.80000; 5.30084
520.80000; 5.14048
521.80000; 5.03823
522.80000; 4.86068
523.80000; 4.55323
524.80000; 4.40432
525.80000; 4.26882
526.80000; 4.13586
527.80000; 3.86573
528.80000; 3.73075
529.80000; 3.60201
530.80000; 3.47392
531.80000; 3.35782
532.80000; 3.20040
533.80000; 3.04610
534.80000; 2.89268
535.80000; 2.73834
536.80000; 2.57953
537.80000; 2.43571
538.80000; 2.29280
539.80000; 2.14889
540.80000; 2.01101
541.80000; 1.87483
542.80000; 1.74088
543.80000; 1.61584
544.80000; 1.49147
545.80000; 1.36667
546.80000; 1.24453
547.80000; 1.12623
548.80000; 1.00902
549.80000; 0.90074
550.80000; 0.79571
551.80000; 0.69837
552.80000; 0.60739
553.80000; 0.52256
554.80000; 0.44897
555.80000; 0.38652
556.80000; 0.33322
557.80000; 0.29750
558.80000; 0.28860
559.80000; 0.28641
560.80000; 0.28565
561.80000; 0.28565
562.80000; 0.28656
563.80000; 0.28820
564.80000; 0.28996
565.80000; 0.29037
566.80000; 0.29207
567.80000; 0.29281
568.80000; 0.29503
569.80000; 0.29750
570.80000; 0.29838
571.80000; 0.30000
572.80000; 0.30086
573.80000; 0.30158
574.80000; 0.30163
575.80000; 0.30325
576.80000; 0.30390
577.80000; 0.30463
578.80000; 0.30646
579.80000; 0.30726
580.80000; 0.30727
581.80000; 0.30804
582.80000; 0.30807
583.80000; 0.30923
584.80000; 0.31047
585.80000; 0.31128
586.80000; 0.31210
587.80000; 0.31289
588.80000; 0.31206
589.80000; 0.31305
590.80000; 0.31381
591.80000; 0.31528
592.80000; 0.31602
593.80000; 0.31685
594.80000; 0.31768
595.80000; 0.31925
596.80000; 0.32085
597.80000; 0.32166
598.80000; 0.32245
599.80000; 0.32396
600.80000; 0.32477
601.80000; 0.32471
602.80000; 0.32561
603.80000; 0.32896
604.80000; 0.33238
605.80000; 0.33447
606.80000; 0.33366
607.80000; 0.33367
608.80000; 0.33438
609.80000; 0.33562
610.80000; 0.33725
611.80000; 0.33847
612.80000; 0.33916
613.80000; 0.34193
614.80000; 0.34358
615.80000; 0.34407
616.80000; 0.34561
617.80000; 0.34723
618.80000; 0.34916
619.80000; 0.34941
620.80000; 0.34970
621.80000; 0.35040
622.80000; 0.35145
623.80000; 0.35289
624.80000; 0.35282
625.80000; 0.35366
626.80000; 0.35531
627.80000; 0.35686
628.80000; 0.35761
629.80000; 0.35923
630.80000; 0.36002
631.80000; 0.36089
632.80000; 0.36087
633.80000; 0.36167
634.80000; 0.36325
635.80000; 0.36337
636.80000; 0.36486
637.80000; 0.36486
638.80000; 0.36486
639.80000; 0.36567
640.80000; 0.36727
641.80000; 0.36805
642.80000; 0.36806
643.80000; 0.36886
644.80000; 0.36965
645.80000; 0.37126
646.80000; 0.37285
647.80000; 0.37444
648.80000; 0.37446
649.80000; 0.37527
650.80000; 0.37526
651.80000; 0.37682
652.80000; 0.37606
653.80000; 0.37606
654.80000; 0.37606
655.80000; 0.37677
656.80000; 0.37755
657.80000; 0.37847
658.80000; 0.37846
659.80000; 0.37913
660.80000; 0.37928
661.80000; 0.38006
662.80000; 0.38008
663.80000; 0.38088
664.80000; 0.38160
665.80000; 0.38304
666.80000; 0.38549
667.80000; 0.38643
668.80000; 0.38886
669.80000; 0.38944
670.80000; 0.39023
671.80000; 0.39046
672.80000; 0.39048
673.80000; 0.39119
674.80000; 0.39206
675.80000; 0.39155
676.80000; 0.39127
677.80000; 0.39128
678.80000; 0.39192
679.80000; 0.39362
680.80000; 0.39526
681.80000; 0.39529
682.80000; 0.39605
683.80000; 0.39599
684.80000; 0.39686
685.80000; 0.39684
686.80000; 0.39606
687.80000; 0.39688
688.80000; 0.39768
689.80000; 0.39850
690.80000; 0.40010
691.80000; 0.40086
692.80000; 0.40124
693.80000; 0.40246
694.80000; 0.40281
695.80000; 0.40327
696.80000; 0.40327
697.80000; 0.40327
698.80000; 0.40321
699.80000; 0.40407
700.80000; 0.40435
701.80000; 0.40571
702.80000; 0.40646
703.80000; 0.40674
704.80000; 0.40806
705.80000; 0.40807
706.80000; 0.40801
707.80000; 0.40887
708.80000; 0.40909
709.80000; 0.41050
710.80000; 0.41047
711.80000; 0.41131
712.80000; 0.41289
713.80000; 0.41391
714.80000; 0.41525
715.80000; 0.41609
716.80000; 0.41607
717.80000; 0.41607
718.80000; 0.41607
719.80000; 0.41607
720.80000; 0.41607
721.80000; 0.41606
722.80000; 0.41686
723.80000; 0.41764
724.80000; 0.41857
725.80000; 0.41936
726.80000; 0.42007
727.80000; 0.42010
728.80000; 0.41844
729.80000; 0.42011
730.80000; 0.41919
731.80000; 0.41763
732.80000; 0.41285
733.80000; 0.40882
734.80000; 0.40315
735.80000; 0.39435
736.80000; 0.38800
737.80000; 0.38402
738.80000; 0.38167
739.80000; 0.38085
740.80000; 0.37927
741.80000; 0.38006
742.80000; 0.38006
743.80000; 0.37926
744.80000; 0.37846
745.80000; 0.37768
746.80000; 0.37689
747.80000; 0.37763
748.80000; 0.37841
749.80000; 0.37923
750.80000; 0.37769
751.80000; 0.37769
752.80000; 0.37679
753.80000; 0.37525
754.80000; 0.37365
755.80000; 0.37208
756.80000; 0.36907
757.80000; 0.36725
758.80000; 0.36571
759.80000; 0.36641
760.80000; 0.36646
761.80000; 0.36576
762.80000; 0.36566
763.80000; 0.36566
764.80000; 0.36634
765.80000; 0.36714
766.80000; 0.36806
767.80000; 0.36806
768.80000; 0.36725
769.80000; 0.36710
770.80000; 0.36728
771.80000; 0.36811
772.80000; 0.36721
773.80000; 0.36803
774.80000; 0.36966
775.80000; 0.37047
776.80000; 0.37046
777.80000; 0.37046
778.80000; 0.37129
779.80000; 0.37206
780.80000; 0.37201
781.80000; 0.37286
782.80000; 0.37225
783.80000; 0.37069
784.80000; 0.36965
785.80000; 0.36942
786.80000; 0.36959
787.80000; 0.37046
788.80000; 0.37101
789.80000; 0.37065
790.80000; 0.37067
791.80000; 0.37044
792.80000; 0.37039
793.80000; 0.37126