File: examples/Birch/TGA_DSC data T18/13WaT18 20 K min N2 7.2.2007.DSC.txt
#FILE:                        13WaT18 20 K min N2 7.2.2007.dsu
#FORMAT:                      NETZSCH4
#IDENTITY:                    13WaT18 20 K min N2
#DECIMAL:                     POINT
#SEPARATOR:                   SEMICOLON
#MTYPE:                       DSC
#INSTRUMENT:                  NETZSCH STA 449C
#PROJECT:                     vtt
#DATE/TIME:                   7.2.2007 14:10:03
#CORR. FILE:                  correction 20K min N2 800 C.bsu
#LABORATORY:                  EO
#OPERATOR:                    TL
#REMARK:
#SAMPLE:                      13WaT18
#SAMPLE MASS /mg:             12.208
#MATERIAL:                    Empty crucibles
#REFERENCE:                   al2o3
#REFERENCE MASS /mg:          40.312
#TYPE OF CRUCIBLE:            DSC/TG pan Al2O3
#SAMPLE CRUCIBLE MASS /mg:    0.000
#REFERENCE CRUCIBLE MASS /mg: 0.000
#PROTECTIVE GAS:              N2
#PURGE GAS 1:                 air
#FLOW RATE 1 /(ml/min):       40
#PURGE GAS 2:
#FLOW RATE 2:
#DSC RANGE /æm:               5000
#TG RANGE /æm:                5000
#CORR. CODE:                  020
#EXO:                         +1
#RANGE:                       20.0/20.00(K/min)/800.0
#SEGMENT:                     S1/2

##Temp./øC;DSC/(mW/mg)
 20.05544;-3.2022e-003
 21.05544;-1.3659e-003
 22.05544; 1.1193e-002
 23.05544; 3.2172e-002
 24.05544; 5.7446e-002
 25.05544; 8.2793e-002
 26.05544;     0.10272
 27.05544;     0.11472
 28.05544;     0.11892
 29.05544;     0.11807
 30.05544;     0.11122
 31.05544;     0.10194
 32.05544; 8.9137e-002
 33.05544; 7.6200e-002
 34.05544; 6.0156e-002
 35.05544; 4.4991e-002
 36.05544; 3.1132e-002
 37.05544; 1.5373e-002
 38.05544; 1.0583e-003
 39.05544;-1.1414e-002
 40.05544;-2.1414e-002
 41.05544;-3.1683e-002
 42.05544;-3.8222e-002
 43.05544;-4.3676e-002
 44.05544;-4.7383e-002
 45.05544;-4.9707e-002
 46.05544;-4.9403e-002
 47.05544;-4.9245e-002
 48.05544;-4.7847e-002
 49.05544;-4.5435e-002
 50.05544;-4.3166e-002
 51.05544;-4.1140e-002
 52.05544;-3.9825e-002
 53.05544;-3.8599e-002
 54.05544;-3.7964e-002
 55.05544;-3.8682e-002
 56.05544;-4.1235e-002
 57.05544;-4.4327e-002
 58.05544;-4.7841e-002
 59.05544;-5.1940e-002
 60.05544;-5.7550e-002
 61.05544;-6.4162e-002
 62.05544;-7.1316e-002
 63.05544;-7.8858e-002
 64.05544;-8.7072e-002
 65.05544;-9.5260e-002
 66.05544;    -0.10223
 67.05544;    -0.11005
 68.05544;    -0.11725
 69.05544;    -0.12459
 70.05544;    -0.13230
 71.05544;    -0.13876
 72.05544;    -0.14544
 73.05544;    -0.15058
 74.05544;    -0.15687
 75.05544;    -0.16121
 76.05544;    -0.16650
 77.05544;    -0.17081
 78.05544;    -0.17426
 79.05544;    -0.17794
 80.05544;    -0.18109
 81.05544;    -0.18345
 82.05544;    -0.18539
 83.05544;    -0.18750
 84.05544;    -0.18999
 85.05544;    -0.19219
 86.05544;    -0.19379
 87.05544;    -0.19495
 88.05544;    -0.19637
 89.05544;    -0.19738
 90.05544;    -0.19807
 91.05544;    -0.19842
 92.05544;    -0.19949
 93.05544;    -0.19834
 94.05544;    -0.19716
 95.05544;    -0.19663
 96.05544;    -0.19503
 97.05544;    -0.19274
 98.05544;    -0.19013
 99.05544;    -0.18627
100.05544;    -0.18202
101.05544;    -0.17716
102.05544;    -0.17050
103.05544;    -0.16365
104.05544;    -0.15704
105.05544;    -0.14848
106.05544;    -0.13880
107.05544;    -0.13016
108.05544;    -0.11832
109.05544;    -0.10739
110.05544;-9.5984e-002
111.05544;-8.4137e-002
112.05544;-7.0628e-002
113.05544;-5.7715e-002
114.05544;-4.4373e-002
115.05544;-3.0409e-002
116.05544;-1.7028e-002
117.05544;-2.5080e-003
118.05544; 1.1212e-002
119.05544; 2.5726e-002
120.05544; 3.9358e-002
121.05544; 5.3333e-002
122.05544; 6.7727e-002
123.05544; 8.0763e-002
124.05544; 9.4320e-002
125.05544;     0.10721
126.05544;     0.12062
127.05544;     0.13326
128.05544;     0.14588
129.05544;     0.15689
130.05544;     0.17055
131.05544;     0.18013
132.05544;     0.19260
133.05544;     0.20345
134.05544;     0.21447
135.05544;     0.22455
136.05544;     0.23457
137.05544;     0.24433
138.05544;     0.25404
139.05544;     0.26429
140.05544;     0.27237
141.05544;     0.28220
142.05544;     0.29131
143.05544;     0.29890
144.05544;     0.30711
145.05544;     0.31501
146.05544;     0.32339
147.05544;     0.33069
148.05544;     0.33923
149.05544;     0.34655
150.05544;     0.35325
151.05544;     0.36111
152.05544;     0.36787
153.05544;     0.37468
154.05544;     0.38205
155.05544;     0.38861
156.05544;     0.39548
157.05544;     0.40220
158.05544;     0.40931
159.05544;     0.41706
160.05544;     0.42265
161.05544;     0.42962
162.05544;     0.43659
163.05544;     0.44340
164.05544;     0.45074
165.05544;     0.45663
166.05544;     0.46323
167.05544;     0.46989
168.05544;     0.47676
169.05544;     0.48282
170.05544;     0.48952
171.05544;     0.49558
172.05544;     0.50322
173.05544;     0.50903
174.05544;     0.51551
175.05544;     0.52242
176.05544;     0.52862
177.05544;     0.53457
178.05544;     0.54127
179.05544;     0.54686
180.05544;     0.55341
181.05544;     0.56052
182.05544;     0.56608
183.05544;     0.57284
184.05544;     0.57904
185.05544;     0.58544
186.05544;     0.59089
187.05544;     0.59714
188.05544;     0.60242
189.05544;     0.60911
190.05544;     0.61443
191.05544;     0.62086
192.05544;     0.62654
193.05544;     0.63255
194.05544;     0.63778
195.05544;     0.64343
196.05544;     0.64887
197.05544;     0.65432
198.05544;     0.65911
199.05544;     0.66450
200.05544;     0.67091
201.05544;     0.67585
202.05544;     0.68099
203.05544;     0.68595
204.05544;     0.69110
205.05544;     0.69605
206.05544;     0.70103
207.05544;     0.70722
208.05544;     0.71146
209.05544;     0.71753
210.05544;     0.72313
211.05544;     0.72866
212.05544;     0.73301
213.05544;     0.73867
214.05544;     0.74465
215.05544;     0.75086
216.05544;     0.75526
217.05544;     0.76087
218.05544;     0.76604
219.05544;     0.77252
220.05544;     0.77754
221.05544;     0.78227
222.05544;     0.78762
223.05544;     0.79287
224.05544;     0.79801
225.05544;     0.80379
226.05544;     0.80811
227.05544;     0.81266
228.05544;     0.81715
229.05544;     0.82160
230.05544;     0.82565
231.05544;     0.82939
232.05544;     0.83209
233.05544;     0.83484
234.05544;     0.83714
235.05544;     0.83912
236.05544;     0.83962
237.05544;     0.83780
238.05544;     0.83702
239.05544;     0.83596
240.05544;     0.83534
241.05544;     0.83363
242.05544;     0.83274
243.05544;     0.83077
244.05544;     0.83029
245.05544;     0.83083
246.05544;     0.83366
247.05544;     0.83995
248.05544;     0.85102
249.05544;     0.86122
250.05544;     0.87244
251.05544;     0.88532
252.05544;     0.89789
253.05544;     0.91061
254.05544;     0.92355
255.05544;     0.93567
256.05544;     0.94833
257.05544;     0.95912
258.05544;     0.96972
259.05544;     0.97906
260.05544;     0.98847
261.05544;     0.99715
262.05544;     1.00608
263.05544;     1.01320
264.05544;     1.02057
265.05544;     1.02714
266.05544;     1.03326
267.05544;     1.03871
268.05544;     1.04575
269.05544;     1.05235
270.05544;     1.05888
271.05544;     1.06676
272.05544;     1.07392
273.05544;     1.08152
274.05544;     1.08813
275.05544;     1.09436
276.05544;     1.09969
277.05544;     1.10533
278.05544;     1.11108
279.05544;     1.11580
280.05544;     1.12046
281.05544;     1.12538
282.05544;     1.12932
283.05544;     1.13295
284.05544;     1.13666
285.05544;     1.13930
286.05544;     1.14287
287.05544;     1.14579
288.05544;     1.14890
289.05544;     1.15089
290.05544;     1.15311
291.05544;     1.15525
292.05544;     1.15731
293.05544;     1.15873
294.05544;     1.16016
295.05544;     1.16034
296.05544;     1.16110
297.05544;     1.16081
298.05544;     1.15910
299.05544;     1.15768
300.05544;     1.15536
301.05544;     1.15143
302.05544;     1.14949
303.05544;     1.14746
304.05544;     1.14612
305.05544;     1.14628
306.05544;     1.14799
307.05544;     1.14991
308.05544;     1.15244
309.05544;     1.15568
310.05544;     1.15846
311.05544;     1.16208
312.05544;     1.16425
313.05544;     1.16793
314.05544;     1.17061
315.05544;     1.17305
316.05544;     1.17470
317.05544;     1.17706
318.05544;     1.17750
319.05544;     1.17948
320.05544;     1.17962
321.05544;     1.17880
322.05544;     1.17838
323.05544;     1.17603
324.05544;     1.17446
325.05544;     1.17323
326.05544;     1.17091
327.05544;     1.16846
328.05544;     1.16729
329.05544;     1.16455
330.05544;     1.16197
331.05544;     1.15981
332.05544;     1.15740
333.05544;     1.15539
334.05544;     1.15233
335.05544;     1.14895
336.05544;     1.14614
337.05544;     1.14264
338.05544;     1.13829
339.05544;     1.13396
340.05544;     1.12832
341.05544;     1.12393
342.05544;     1.11826
343.05544;     1.11310
344.05544;     1.10664
345.05544;     1.10035
346.05544;     1.09356
347.05544;     1.08652
348.05544;     1.07881
349.05544;     1.07151
350.05544;     1.06341
351.05544;     1.05354
352.05544;     1.04422
353.05544;     1.03441
354.05544;     1.02295
355.05544;     1.01016
356.05544;     0.99663
357.05544;     0.98181
358.05544;     0.96554
359.05544;     0.94843
360.05544;     0.92966
361.05544;     0.90904
362.05544;     0.88777
363.05544;     0.86398
364.05544;     0.83829
365.05544;     0.81080
366.05544;     0.78093
367.05544;     0.75034
368.05544;     0.71721
369.05544;     0.68341
370.05544;     0.64860
371.05544;     0.61147
372.05544;     0.57347
373.05544;     0.53651
374.05544;     0.49852
375.05544;     0.46022
376.05544;     0.42341
377.05544;     0.38767
378.05544;     0.35279
379.05544;     0.32099
380.05544;     0.29289
381.05544;     0.26690
382.05544;     0.24515
383.05544;     0.22855
384.05544;     0.21754
385.05544;     0.21140
386.05544;     0.21049
387.05544;     0.21741
388.05544;     0.22959
389.05544;     0.24847
390.05544;     0.27437
391.05544;     0.30693
392.05544;     0.34535
393.05544;     0.38961
394.05544;     0.44007
395.05544;     0.49277
396.05544;     0.54959
397.05544;     0.60668
398.05544;     0.66542
399.05544;     0.72288
400.05544;     0.77854
401.05544;     0.83086
402.05544;     0.88058
403.05544;     0.92500
404.05544;     0.96531
405.05544;     1.00182
406.05544;     1.03390
407.05544;     1.06327
408.05544;     1.08858
409.05544;     1.11280
410.05544;     1.13320
411.05544;     1.15242
412.05544;     1.16985
413.05544;     1.18517
414.05544;     1.20069
415.05544;     1.21430
416.05544;     1.22717
417.05544;     1.23906
418.05544;     1.24997
419.05544;     1.26145
420.05544;     1.27298
421.05544;     1.28168
422.05544;     1.29201
423.05544;     1.30126
424.05544;     1.31106
425.05544;     1.31966
426.05544;     1.32784
427.05544;     1.33640
428.05544;     1.34391
429.05544;     1.35117
430.05544;     1.35868
431.05544;     1.36600
432.05544;     1.37257
433.05544;     1.37995
434.05544;     1.38623
435.05544;     1.39145
436.05544;     1.39869
437.05544;     1.40409
438.05544;     1.40998
439.05544;     1.41514
440.05544;     1.42024
441.05544;     1.42477
442.05544;     1.42897
443.05544;     1.43400
444.05544;     1.43834
445.05544;     1.44168
446.05544;     1.44585
447.05544;     1.44864
448.05544;     1.45159
449.05544;     1.45498
450.05544;     1.45784
451.05544;     1.46041
452.05544;     1.46320
453.05544;     1.46497
454.05544;     1.46734
455.05544;     1.46987
456.05544;     1.47158
457.05544;     1.47263
458.05544;     1.47499
459.05544;     1.47618
460.05544;     1.47721
461.05544;     1.47908
462.05544;     1.48034
463.05544;     1.48092
464.05544;     1.48288
465.05544;     1.48292
466.05544;     1.48570
467.05544;     1.48663
468.05544;     1.48827
469.05544;     1.49028
470.05544;     1.49159
471.05544;     1.49317
472.05544;     1.49517
473.05544;     1.49584
474.05544;     1.49824
475.05544;     1.50040
476.05544;     1.50145
477.05544;     1.50359
478.05544;     1.50579
479.05544;     1.50760
480.05544;     1.50722
481.05544;     1.50943
482.05544;     1.51186
483.05544;     1.51320
484.05544;     1.51571
485.05544;     1.51729
486.05544;     1.51931
487.05544;     1.52155
488.05544;     1.52349
489.05544;     1.52522
490.05544;     1.52780
491.05544;     1.53061
492.05544;     1.53293
493.05544;     1.53472
494.05544;     1.53719
495.05544;     1.54039
496.05544;     1.54266
497.05544;     1.54405
498.05544;     1.54701
499.05544;     1.54965
500.05544;     1.55188
501.05544;     1.55415
502.05544;     1.55621
503.05544;     1.55889
504.05544;     1.56212
505.05544;     1.56455
506.05544;     1.56667
507.05544;     1.56970
508.05544;     1.57100
509.05544;     1.57344
510.05544;     1.57577
511.05544;     1.57891
512.05544;     1.58158
513.05544;     1.58325
514.05544;     1.58521
515.05544;     1.58886
516.05544;     1.59123
517.05544;     1.59431
518.05544;     1.59584
519.05544;     1.59786
520.05544;     1.60053
521.05544;     1.60343
522.05544;     1.60577
523.05544;     1.60774
524.05544;     1.61026
525.05544;     1.61195
526.05544;     1.61454
527.05544;     1.61653
528.05544;     1.61988
529.05544;     1.62116
530.05544;     1.62376
531.05544;     1.62495
532.05544;     1.62775
533.05544;     1.63042
534.05544;     1.63229
535.05544;     1.63378
536.05544;     1.63632
537.05544;     1.63720
538.05544;     1.63826
539.05544;     1.63942
540.05544;     1.64140
541.05544;     1.64366
542.05544;     1.64518
543.05544;     1.64593
544.05544;     1.64809
545.05544;     1.64920
546.05544;     1.65065
547.05544;     1.65217
548.05544;     1.65402
549.05544;     1.65317
550.05544;     1.65425
551.05544;     1.65556
552.05544;     1.65674
553.05544;     1.65745
554.05544;     1.65808
555.05544;     1.65935
556.05544;     1.65904
557.05544;     1.65980
558.05544;     1.65957
559.05544;     1.65925
560.05544;     1.65994
561.05544;     1.66017
562.05544;     1.66071
563.05544;     1.66097
564.05544;     1.66024
565.05544;     1.66036
566.05544;     1.66077
567.05544;     1.66118
568.05544;     1.65980
569.05544;     1.66040
570.05544;     1.65922
571.05544;     1.65905
572.05544;     1.65823
573.05544;     1.65740
574.05544;     1.65518
575.05544;     1.65464
576.05544;     1.65323
577.05544;     1.65182
578.05544;     1.65044
579.05544;     1.64926
580.05544;     1.64754
581.05544;     1.64521
582.05544;     1.64421
583.05544;     1.64210
584.05544;     1.64025
585.05544;     1.63877
586.05544;     1.63583
587.05544;     1.63293
588.05544;     1.63109
589.05544;     1.62797
590.05544;     1.62565
591.05544;     1.62312
592.05544;     1.61996
593.05544;     1.61637
594.05544;     1.61357
595.05544;     1.60887
596.05544;     1.60546
597.05544;     1.60210
598.05544;     1.59760
599.05544;     1.59497
600.05544;     1.59147
601.05544;     1.58689
602.05544;     1.58141
603.05544;     1.57736
604.05544;     1.57204
605.05544;     1.56757
606.05544;     1.56386
607.05544;     1.55739
608.05544;     1.55308
609.05544;     1.54786
610.05544;     1.54304
611.05544;     1.53583
612.05544;     1.52935
613.05544;     1.52372
614.05544;     1.51640
615.05544;     1.50936
616.05544;     1.50127
617.05544;     1.49329
618.05544;     1.48591
619.05544;     1.47659
620.05544;     1.46809
621.05544;     1.46042
622.05544;     1.45150
623.05544;     1.44271
624.05544;     1.43351
625.05544;     1.42296
626.05544;     1.41306
627.05544;     1.40353
628.05544;     1.39321
629.05544;     1.38383
630.05544;     1.37409
631.05544;     1.36316
632.05544;     1.35268
633.05544;     1.34034
634.05544;     1.32917
635.05544;     1.31745
636.05544;     1.30470
637.05544;     1.29232
638.05544;     1.28006
639.05544;     1.26691
640.05544;     1.25411
641.05544;     1.24191
642.05544;     1.22738
643.05544;     1.21464
644.05544;     1.20140
645.05544;     1.18762
646.05544;     1.17357
647.05544;     1.15902
648.05544;     1.14454
649.05544;     1.12923
650.05544;     1.11503
651.05544;     1.10029
652.05544;     1.08448
653.05544;     1.06989
654.05544;     1.05400
655.05544;     1.03842
656.05544;     1.02138
657.05544;     1.00588
658.05544;     0.98774
659.05544;     0.97130
660.05544;     0.95719
661.05544;     0.93989
662.05544;     0.92239
663.05544;     0.90528
664.05544;     0.88978
665.05544;     0.87215
666.05544;     0.85550
667.05544;     0.83716
668.05544;     0.82113
669.05544;     0.80480
670.05544;     0.78612
671.05544;     0.76736
672.05544;     0.74860
673.05544;     0.72902
674.05544;     0.71020
675.05544;     0.69294
676.05544;     0.67397
677.05544;     0.65497
678.05544;     0.63700
679.05544;     0.61886
680.05544;     0.59910
681.05544;     0.58043
682.05544;     0.56088
683.05544;     0.54266
684.05544;     0.52459
685.05544;     0.50637
686.05544;     0.48780
687.05544;     0.46797
688.05544;     0.45039
689.05544;     0.43193
690.05544;     0.41309
691.05544;     0.39620
692.05544;     0.37727
693.05544;     0.35874
694.05544;     0.33874
695.05544;     0.32060
696.05544;     0.30209
697.05544;     0.28419
698.05544;     0.26546
699.05544;     0.24770
700.05544;     0.23047
701.05544;     0.21329
702.05544;     0.19649
703.05544;     0.17925
704.05544;     0.16446
705.05544;     0.14729
706.05544;     0.13218
707.05544;     0.11595
708.05544;     0.10136
709.05544; 8.3293e-002
710.05544; 6.9103e-002
711.05544; 5.4253e-002
712.05544; 4.0404e-002
713.05544; 2.4589e-002
714.05544; 1.0368e-002
715.05544;-5.2790e-003
716.05544;-2.2747e-002
717.05544;-3.5729e-002
718.05544;-4.7985e-002
719.05544;-6.0887e-002
720.05544;-7.2668e-002
721.05544;-8.3474e-002
722.05544;-9.4059e-002
723.05544;    -0.10335
724.05544;    -0.11212
725.05544;    -0.11987
726.05544;    -0.12875
727.05544;    -0.13483
728.05544;    -0.14282
729.05544;    -0.15104
730.05544;    -0.15655
731.05544;    -0.16230
732.05544;    -0.16678
733.05544;    -0.17228
734.05544;    -0.17520
735.05544;    -0.17984
736.05544;    -0.18268
737.05544;    -0.18413
738.05544;    -0.18548
739.05544;    -0.18683
740.05544;    -0.18829
741.05544;    -0.18888
742.05544;    -0.18900
743.05544;    -0.18868
744.05544;    -0.18563
745.05544;    -0.18402
746.05544;    -0.18208
747.05544;    -0.18054
748.05544;    -0.17780
749.05544;    -0.17446
750.05544;    -0.17036
751.05544;    -0.16712
752.05544;    -0.16257
753.05544;    -0.15668
754.05544;    -0.15114
755.05544;    -0.14526
756.05544;    -0.14010
757.05544;    -0.13150
758.05544;    -0.12409
759.05544;    -0.11497
760.05544;    -0.10673
761.05544;-9.7985e-002
762.05544;-8.8333e-002
763.05544;-7.9187e-002
764.05544;-6.9799e-002
765.05544;-6.0185e-002
766.05544;-4.8340e-002
767.05544;-3.7285e-002
768.05544;-2.5481e-002
769.05544;-1.3779e-002
770.05544;-2.9160e-003
771.05544; 1.0107e-002
772.05544; 2.0653e-002
773.05544; 3.2647e-002
774.05544; 4.4437e-002
775.05544; 5.7380e-002
776.05544; 6.8305e-002
777.05544; 8.1508e-002
778.05544; 9.5229e-002
779.05544;     0.10897
780.05544;     0.12110
781.05544;     0.13324
782.05544;     0.14280
783.05544;     0.15638
784.05544;     0.16818
785.05544;     0.18117
786.05544;     0.19278
787.05544;     0.20551
788.05544;     0.21828
789.05544;     0.22844
790.05544;     0.24341
791.05544;     0.25582
792.05544;     0.27062
793.05544;     0.28366
794.05544;     0.29581
795.05544;     0.30847
796.05544;     0.32126