File: examples/Birch/TGA_DSC data T18/13WaT18 2 K min N2 15.2.2007.DSC.txt
#FILE:                        13WaT18 2 K min N2 15.2.2007.dsu
#FORMAT:                      NETZSCH4
#IDENTITY:                    13 WaT18 2 K min N2
#DECIMAL:                     POINT
#SEPARATOR:                   SEMICOLON
#MTYPE:                       DSC
#INSTRUMENT:                  NETZSCH STA 449C
#PROJECT:                     vtt
#DATE/TIME:                   15.2.2007 12:04:57
#CORR. FILE:                  correction 2K min N2 800 C.bsu
#LABORATORY:                  EO
#OPERATOR:                    TL
#REMARK:
#SAMPLE:                      13 WaT18
#SAMPLE MASS /mg:             12.065
#MATERIAL:                    Empty crucibles
#REFERENCE:                   al2o3
#REFERENCE MASS /mg:          40.312
#TYPE OF CRUCIBLE:            DSC/TG pan Al2O3
#SAMPLE CRUCIBLE MASS /mg:    0.000
#REFERENCE CRUCIBLE MASS /mg: 0.000
#PROTECTIVE GAS:              N2
#PURGE GAS 1:                 air
#FLOW RATE 1 /(ml/min):       40
#PURGE GAS 2:                 N2
#FLOW RATE 2:
#DSC RANGE /æm:               5000
#TG RANGE /æm:                5000
#CORR. CODE:                  020
#EXO:                         +1
#RANGE:                       20.0/2.00(K/min)/800.0
#SEGMENT:                     S1/2

##Temp./øC;DSC/(mW/mg)
 23.85012;-1.1263e-002
 24.85012;-1.9010e-002
 25.85012;-3.0111e-002
 26.85012;-3.9685e-002
 27.85012;-4.8032e-002
 28.85012;-5.5285e-002
 29.85012;-6.1162e-002
 30.85012;-6.5971e-002
 31.85012;-7.0976e-002
 32.85012;-7.4512e-002
 33.85012;-7.7360e-002
 34.85012;-8.0102e-002
 35.85012;-8.2401e-002
 36.85012;-8.5101e-002
 37.85012;-8.6676e-002
 38.85012;-8.7098e-002
 39.85012;-8.9161e-002
 40.85012;-8.9439e-002
 41.85012;-9.0436e-002
 42.85012;-9.0688e-002
 43.85012;-9.2325e-002
 44.85012;-9.2072e-002
 45.85012;-9.2857e-002
 46.85012;-9.3424e-002
 47.85012;-9.4446e-002
 48.85012;-9.4598e-002
 49.85012;-9.5177e-002
 50.85012;-9.5718e-002
 51.85012;-9.5297e-002
 52.85012;-9.4965e-002
 53.85012;-9.5467e-002
 54.85012;-9.5081e-002
 55.85012;-9.4547e-002
 56.85012;-9.4041e-002
 57.85012;-9.3257e-002
 58.85012;-9.2573e-002
 59.85012;-9.0681e-002
 60.85012;-8.8918e-002
 61.85012;-8.7951e-002
 62.85012;-8.5672e-002
 63.85012;-8.4722e-002
 64.85012;-8.2032e-002
 65.85012;-7.9471e-002
 66.85012;-7.7810e-002
 67.85012;-7.5446e-002
 68.85012;-7.3205e-002
 69.85012;-7.0872e-002
 70.85012;-6.7778e-002
 71.85012;-6.5029e-002
 72.85012;-6.3031e-002
 73.85012;-5.9690e-002
 74.85012;-5.7371e-002
 75.85012;-5.4508e-002
 76.85012;-5.2017e-002
 77.85012;-4.9280e-002
 78.85012;-4.6430e-002
 79.85012;-4.4887e-002
 80.85012;-4.1456e-002
 81.85012;-3.9470e-002
 82.85012;-3.7509e-002
 83.85012;-3.4289e-002
 84.85012;-3.2284e-002
 85.85012;-3.0402e-002
 86.85012;-2.8065e-002
 87.85012;-2.6244e-002
 88.85012;-2.3779e-002
 89.85012;-2.2093e-002
 90.85012;-1.9630e-002
 91.85012;-1.8420e-002
 92.85012;-1.5715e-002
 93.85012;-1.3810e-002
 94.85012;-1.2099e-002
 95.85012;-1.0225e-002
 96.85012;-8.7660e-003
 97.85012;-7.3267e-003
 98.85012;-5.6328e-003
 99.85012;-4.5767e-003
100.85012;-1.7956e-003
101.85012;-9.1701e-004
102.85012; 4.9183e-004
103.85012; 2.4647e-003
104.85012; 3.9554e-003
105.85012; 5.4886e-003
106.85012; 6.5251e-003
107.85012; 7.9429e-003
108.85012; 9.8372e-003
109.85012; 1.1377e-002
110.85012; 1.2978e-002
111.85012; 1.4777e-002
112.85012; 1.6565e-002
113.85012; 1.7646e-002
114.85012; 1.9134e-002
115.85012; 2.0289e-002
116.85012; 2.2217e-002
117.85012; 2.3580e-002
118.85012; 2.5499e-002
119.85012; 2.7149e-002
120.85012; 2.8757e-002
121.85012; 3.0022e-002
122.85012; 3.1865e-002
123.85012; 3.3443e-002
124.85012; 3.5058e-002
125.85012; 3.6348e-002
126.85012; 3.7969e-002
127.85012; 3.9587e-002
128.85012; 4.1416e-002
129.85012; 4.2749e-002
130.85012; 4.4859e-002
131.85012; 4.5615e-002
132.85012; 4.7942e-002
133.85012; 4.9660e-002
134.85012; 5.1621e-002
135.85012; 5.2993e-002
136.85012; 5.5153e-002
137.85012; 5.6475e-002
138.85012; 5.8180e-002
139.85012; 6.0101e-002
140.85012; 6.1887e-002
141.85012; 6.3416e-002
142.85012; 6.5692e-002
143.85012; 6.7525e-002
144.85012; 6.9039e-002
145.85012; 7.0843e-002
146.85012; 7.2658e-002
147.85012; 7.4807e-002
148.85012; 7.6171e-002
149.85012; 7.8245e-002
150.85012; 8.0759e-002
151.85012; 8.1922e-002
152.85012; 8.4469e-002
153.85012; 8.6017e-002
154.85012; 8.8299e-002
155.85012; 8.9872e-002
156.85012; 9.1889e-002
157.85012; 9.3372e-002
158.85012; 9.5983e-002
159.85012; 9.7870e-002
160.85012;     0.10003
161.85012;     0.10217
162.85012;     0.10396
163.85012;     0.10707
164.85012;     0.10842
165.85012;     0.11039
166.85012;     0.11186
167.85012;     0.11401
168.85012;     0.11654
169.85012;     0.11842
170.85012;     0.12036
171.85012;     0.12315
172.85012;     0.12456
173.85012;     0.12673
174.85012;     0.12921
175.85012;     0.13109
176.85012;     0.13276
177.85012;     0.13523
178.85012;     0.13778
179.85012;     0.14044
180.85012;     0.14189
181.85012;     0.14454
182.85012;     0.14630
183.85012;     0.14836
184.85012;     0.15031
185.85012;     0.15342
186.85012;     0.15483
187.85012;     0.15750
188.85012;     0.16023
189.85012;     0.16238
190.85012;     0.16513
191.85012;     0.16752
192.85012;     0.16964
193.85012;     0.17237
194.85012;     0.17539
195.85012;     0.17743
196.85012;     0.17988
197.85012;     0.18315
198.85012;     0.18529
199.85012;     0.18749
200.85012;     0.19028
201.85012;     0.19234
202.85012;     0.19524
203.85012;     0.19720
204.85012;     0.19986
205.85012;     0.20313
206.85012;     0.20437
207.85012;     0.20763
208.85012;     0.21005
209.85012;     0.21286
210.85012;     0.21492
211.85012;     0.21782
212.85012;     0.22004
213.85012;     0.22295
214.85012;     0.22566
215.85012;     0.22814
216.85012;     0.23041
217.85012;     0.23300
218.85012;     0.23550
219.85012;     0.23829
220.85012;     0.24115
221.85012;     0.24417
222.85012;     0.24656
223.85012;     0.24909
224.85012;     0.25127
225.85012;     0.25356
226.85012;     0.25636
227.85012;     0.25925
228.85012;     0.26174
229.85012;     0.26361
230.85012;     0.26693
231.85012;     0.26986
232.85012;     0.27196
233.85012;     0.27448
234.85012;     0.27800
235.85012;     0.27967
236.85012;     0.28106
237.85012;     0.28375
238.85012;     0.28648
239.85012;     0.28821
240.85012;     0.29041
241.85012;     0.29261
242.85012;     0.29410
243.85012;     0.29702
244.85012;     0.29764
245.85012;     0.29891
246.85012;     0.30227
247.85012;     0.30377
248.85012;     0.30628
249.85012;     0.30750
250.85012;     0.30946
251.85012;     0.31220
252.85012;     0.31286
253.85012;     0.31540
254.85012;     0.31716
255.85012;     0.31906
256.85012;     0.32071
257.85012;     0.32334
258.85012;     0.32503
259.85012;     0.32778
260.85012;     0.32873
261.85012;     0.33126
262.85012;     0.33278
263.85012;     0.33528
264.85012;     0.33735
265.85012;     0.33906
266.85012;     0.34142
267.85012;     0.34415
268.85012;     0.34645
269.85012;     0.34776
270.85012;     0.34998
271.85012;     0.35257
272.85012;     0.35495
273.85012;     0.35732
274.85012;     0.35890
275.85012;     0.36150
276.85012;     0.36379
277.85012;     0.36558
278.85012;     0.36921
279.85012;     0.37075
280.85012;     0.37324
281.85012;     0.37563
282.85012;     0.37779
283.85012;     0.37972
284.85012;     0.38257
285.85012;     0.38507
286.85012;     0.38657
287.85012;     0.38857
288.85012;     0.39066
289.85012;     0.39244
290.85012;     0.39503
291.85012;     0.39805
292.85012;     0.39924
293.85012;     0.40092
294.85012;     0.40261
295.85012;     0.40494
296.85012;     0.40626
297.85012;     0.40869
298.85012;     0.40945
299.85012;     0.41162
300.85012;     0.41230
301.85012;     0.41383
302.85012;     0.41559
303.85012;     0.41704
304.85012;     0.41886
305.85012;     0.42108
306.85012;     0.42161
307.85012;     0.42352
308.85012;     0.42566
309.85012;     0.42689
310.85012;     0.42790
311.85012;     0.42941
312.85012;     0.43034
313.85012;     0.43183
314.85012;     0.43407
315.85012;     0.43461
316.85012;     0.43549
317.85012;     0.43676
318.85012;     0.43667
319.85012;     0.43696
320.85012;     0.43772
321.85012;     0.43702
322.85012;     0.43716
323.85012;     0.43587
324.85012;     0.43537
325.85012;     0.43409
326.85012;     0.43127
327.85012;     0.42843
328.85012;     0.42546
329.85012;     0.42137
330.85012;     0.41772
331.85012;     0.41150
332.85012;     0.40517
333.85012;     0.39774
334.85012;     0.38869
335.85012;     0.37959
336.85012;     0.36929
337.85012;     0.36013
338.85012;     0.35013
339.85012;     0.34043
340.85012;     0.33099
341.85012;     0.32513
342.85012;     0.31867
343.85012;     0.31593
344.85012;     0.31607
345.85012;     0.31804
346.85012;     0.32426
347.85012;     0.33237
348.85012;     0.34365
349.85012;     0.35707
350.85012;     0.37323
351.85012;     0.38945
352.85012;     0.40558
353.85012;     0.42240
354.85012;     0.43701
355.85012;     0.44976
356.85012;     0.46115
357.85012;     0.47047
358.85012;     0.47859
359.85012;     0.48373
360.85012;     0.48994
361.85012;     0.49438
362.85012;     0.49835
363.85012;     0.50220
364.85012;     0.50536
365.85012;     0.50809
366.85012;     0.51116
367.85012;     0.51306
368.85012;     0.51558
369.85012;     0.51896
370.85012;     0.52190
371.85012;     0.52494
372.85012;     0.52777
373.85012;     0.52997
374.85012;     0.53284
375.85012;     0.53595
376.85012;     0.53914
377.85012;     0.54067
378.85012;     0.54423
379.85012;     0.54644
380.85012;     0.54922
381.85012;     0.55137
382.85012;     0.55357
383.85012;     0.55660
384.85012;     0.55887
385.85012;     0.56176
386.85012;     0.56328
387.85012;     0.56523
388.85012;     0.56785
389.85012;     0.56993
390.85012;     0.57185
391.85012;     0.57481
392.85012;     0.57687
393.85012;     0.57883
394.85012;     0.58006
395.85012;     0.58207
396.85012;     0.58505
397.85012;     0.58565
398.85012;     0.58826
399.85012;     0.59037
400.85012;     0.59181
401.85012;     0.59419
402.85012;     0.59634
403.85012;     0.59771
404.85012;     0.59873
405.85012;     0.60066
406.85012;     0.60279
407.85012;     0.60502
408.85012;     0.60560
409.85012;     0.60795
410.85012;     0.60880
411.85012;     0.61213
412.85012;     0.61323
413.85012;     0.61337
414.85012;     0.61648
415.85012;     0.61895
416.85012;     0.62050
417.85012;     0.62244
418.85012;     0.62336
419.85012;     0.62554
420.85012;     0.62641
421.85012;     0.62895
422.85012;     0.63079
423.85012;     0.63265
424.85012;     0.63429
425.85012;     0.63530
426.85012;     0.63657
427.85012;     0.63950
428.85012;     0.64103
429.85012;     0.64284
430.85012;     0.64536
431.85012;     0.64770
432.85012;     0.64943
433.85012;     0.65103
434.85012;     0.65316
435.85012;     0.65441
436.85012;     0.65608
437.85012;     0.65735
438.85012;     0.65927
439.85012;     0.66095
440.85012;     0.66327
441.85012;     0.66509
442.85012;     0.66655
443.85012;     0.66883
444.85012;     0.67102
445.85012;     0.67298
446.85012;     0.67521
447.85012;     0.67608
448.85012;     0.67888
449.85012;     0.68136
450.85012;     0.68259
451.85012;     0.68570
452.85012;     0.68769
453.85012;     0.69043
454.85012;     0.69203
455.85012;     0.69477
456.85012;     0.69741
457.85012;     0.69873
458.85012;     0.70154
459.85012;     0.70349
460.85012;     0.70679
461.85012;     0.70871
462.85012;     0.71105
463.85012;     0.71407
464.85012;     0.71633
465.85012;     0.71709
466.85012;     0.71990
467.85012;     0.72276
468.85012;     0.72406
469.85012;     0.72824
470.85012;     0.73163
471.85012;     0.73337
472.85012;     0.73615
473.85012;     0.73876
474.85012;     0.74167
475.85012;     0.74456
476.85012;     0.74614
477.85012;     0.74961
478.85012;     0.75148
479.85012;     0.75362
480.85012;     0.75596
481.85012;     0.75822
482.85012;     0.76031
483.85012;     0.76441
484.85012;     0.76626
485.85012;     0.76927
486.85012;     0.77233
487.85012;     0.77517
488.85012;     0.77787
489.85012;     0.77908
490.85012;     0.78160
491.85012;     0.78495
492.85012;     0.78657
493.85012;     0.79027
494.85012;     0.79181
495.85012;     0.79519
496.85012;     0.79781
497.85012;     0.80045
498.85012;     0.80297
499.85012;     0.80583
500.85012;     0.80859
501.85012;     0.81057
502.85012;     0.81257
503.85012;     0.81534
504.85012;     0.81876
505.85012;     0.82017
506.85012;     0.82405
507.85012;     0.82626
508.85012;     0.82802
509.85012;     0.83142
510.85012;     0.83409
511.85012;     0.83756
512.85012;     0.83986
513.85012;     0.84255
514.85012;     0.84527
515.85012;     0.84718
516.85012;     0.84991
517.85012;     0.85148
518.85012;     0.85196
519.85012;     0.85410
520.85012;     0.85802
521.85012;     0.85938
522.85012;     0.86255
523.85012;     0.86239
524.85012;     0.86525
525.85012;     0.86698
526.85012;     0.86765
527.85012;     0.87138
528.85012;     0.87329
529.85012;     0.87466
530.85012;     0.87538
531.85012;     0.87543
532.85012;     0.87798
533.85012;     0.87923
534.85012;     0.87933
535.85012;     0.88301
536.85012;     0.88270
537.85012;     0.88475
538.85012;     0.88577
539.85012;     0.88606
540.85012;     0.88754
541.85012;     0.88877
542.85012;     0.88824
543.85012;     0.89062
544.85012;     0.89132
545.85012;     0.89215
546.85012;     0.89725
547.85012;     0.89705
548.85012;     0.89823
549.85012;     0.89834
550.85012;     0.89746
551.85012;     0.89868
552.85012;     0.89869
553.85012;     0.89713
554.85012;     0.89665
555.85012;     0.89700
556.85012;     0.89595
557.85012;     0.89476
558.85012;     0.89482
559.85012;     0.89527
560.85012;     0.89303
561.85012;     0.89140
562.85012;     0.89075
563.85012;     0.88971
564.85012;     0.88761
565.85012;     0.88642
566.85012;     0.88329
567.85012;     0.88287
568.85012;     0.88003
569.85012;     0.87957
570.85012;     0.87760
571.85012;     0.87543
572.85012;     0.87457
573.85012;     0.87241
574.85012;     0.86938
575.85012;     0.86682
576.85012;     0.86308
577.85012;     0.86221
578.85012;     0.85876
579.85012;     0.85774
580.85012;     0.85533
581.85012;     0.85197
582.85012;     0.84834
583.85012;     0.84614
584.85012;     0.84240
585.85012;     0.83937
586.85012;     0.83532
587.85012;     0.83191
588.85012;     0.82899
589.85012;     0.82492
590.85012;     0.82204
591.85012;     0.81898
592.85012;     0.81286
593.85012;     0.81007
594.85012;     0.80469
595.85012;     0.80059
596.85012;     0.79818
597.85012;     0.79302
598.85012;     0.78878
599.85012;     0.78530
600.85012;     0.77970
601.85012;     0.77568
602.85012;     0.77053
603.85012;     0.76561
604.85012;     0.76159
605.85012;     0.75571
606.85012;     0.75112
607.85012;     0.74399
608.85012;     0.73996
609.85012;     0.73496
610.85012;     0.72839
611.85012;     0.72502
612.85012;     0.72019
613.85012;     0.71475
614.85012;     0.71107
615.85012;     0.70476
616.85012;     0.69958
617.85012;     0.69665
618.85012;     0.69101
619.85012;     0.68658
620.85012;     0.68095
621.85012;     0.67573
622.85012;     0.67142
623.85012;     0.66620
624.85012;     0.66095
625.85012;     0.65559
626.85012;     0.65168
627.85012;     0.64516
628.85012;     0.63997
629.85012;     0.63422
630.85012;     0.63502
631.85012;     0.63019
632.85012;     0.62528
633.85012;     0.62142
634.85012;     0.61732
635.85012;     0.61450
636.85012;     0.60909
637.85012;     0.60323
638.85012;     0.60050
639.85012;     0.59655
640.85012;     0.59276
641.85012;     0.58951
642.85012;     0.58479
643.85012;     0.58116
644.85012;     0.57633
645.85012;     0.57459
646.85012;     0.57129
647.85012;     0.56793
648.85012;     0.56618
649.85012;     0.56224
650.85012;     0.55966
651.85012;     0.55706
652.85012;     0.55459
653.85012;     0.55280
654.85012;     0.55095
655.85012;     0.55065
656.85012;     0.54915
657.85012;     0.54948
658.85012;     0.54746
659.85012;     0.54751
660.85012;     0.54612
661.85012;     0.54568
662.85012;     0.54606
663.85012;     0.54647
664.85012;     0.54728
665.85012;     0.54811
666.85012;     0.54915
667.85012;     0.55013
668.85012;     0.55185
669.85012;     0.55362
670.85012;     0.55377
671.85012;     0.55465
672.85012;     0.55751
673.85012;     0.55881
674.85012;     0.56002
675.85012;     0.56319
676.85012;     0.56435
677.85012;     0.56765
678.85012;     0.56922
679.85012;     0.57266
680.85012;     0.57705
681.85012;     0.57970
682.85012;     0.58310
683.85012;     0.58727
684.85012;     0.58930
685.85012;     0.59402
686.85012;     0.59734
687.85012;     0.60330
688.85012;     0.60844
689.85012;     0.61302
690.85012;     0.61840
691.85012;     0.62363
692.85012;     0.62811
693.85012;     0.63466
694.85012;     0.63931
695.85012;     0.64605
696.85012;     0.65231
697.85012;     0.65779
698.85012;     0.66424
699.85012;     0.67121
700.85012;     0.67738
701.85012;     0.68400
702.85012;     0.69115
703.85012;     0.69546
704.85012;     0.70383
705.85012;     0.71207
706.85012;     0.72005
707.85012;     0.72768
708.85012;     0.73569
709.85012;     0.74473
710.85012;     0.75129
711.85012;     0.75959
712.85012;     0.76824
713.85012;     0.77802
714.85012;     0.78748
715.85012;     0.79692
716.85012;     0.80802
717.85012;     0.81766
718.85012;     0.82741
719.85012;     0.83809
720.85012;     0.84632
721.85012;     0.85600
722.85012;     0.86703
723.85012;     0.87824
724.85012;     0.88838
725.85012;     0.90189
726.85012;     0.91338
727.85012;     0.92426
728.85012;     0.93648
729.85012;     0.94861
730.85012;     0.96148
731.85012;     0.97479
732.85012;     0.98801
733.85012;     1.00265
734.85012;     1.01444
735.85012;     1.02922
736.85012;     1.04131
737.85012;     1.05455
738.85012;     1.06821
739.85012;     1.08088
740.85012;     1.09518
741.85012;     1.10992
742.85012;     1.12330
743.85012;     1.13814
744.85012;     1.15499
745.85012;     1.17074
746.85012;     1.18565
747.85012;     1.19739
748.85012;     1.21199
749.85012;     1.22536
750.85012;     1.24158
751.85012;     1.25428
752.85012;     1.26901
753.85012;     1.28394
754.85012;     1.29796
755.85012;     1.31271
756.85012;     1.32806
757.85012;     1.34402
758.85012;     1.35706
759.85012;     1.37271
760.85012;     1.38728
761.85012;     1.40433
762.85012;     1.42134
763.85012;     1.43666
764.85012;     1.45320
765.85012;     1.46887
766.85012;     1.48234
767.85012;     1.49841
768.85012;     1.51439
769.85012;     1.52987
770.85012;     1.54468
771.85012;     1.56062
772.85012;     1.57672
773.85012;     1.59192
774.85012;     1.60798
775.85012;     1.62520
776.85012;     1.64051
777.85012;     1.65593
778.85012;     1.66993
779.85012;     1.68568
780.85012;     1.70099
781.85012;     1.71614
782.85012;     1.72942
783.85012;     1.74622
784.85012;     1.76234
785.85012;     1.77769
786.85012;     1.79395
787.85012;     1.80885
788.85012;     1.82409
789.85012;     1.84012
790.85012;     1.85505
791.85012;     1.87176
792.85012;     1.88783
793.85012;     1.90632
794.85012;     1.92250
795.85012;     1.93734
796.85012;     1.95218
797.85012;     1.96611