File: examples/Birch/TGA_DSC data T18/13WaT18 5 K min air 16.2.07.DSC.txt
#FILE:                        13WaT18 5 K min air 16.2.07.dsu
#FORMAT:                      NETZSCH4
#IDENTITY:                    13 WaT18 5 K min air
#DECIMAL:                     POINT
#SEPARATOR:                   SEMICOLON
#MTYPE:                       DSC
#INSTRUMENT:                  NETZSCH STA 449C
#PROJECT:                     vtt
#DATE/TIME:                   16.2.2007 14:13:33
#CORR. FILE:                  correction 5Kmin air 800 C.bsu
#LABORATORY:                  EO
#OPERATOR:                    TL
#REMARK:
#SAMPLE:                      13 WaT18
#SAMPLE MASS /mg:             12.341
#MATERIAL:                    Empty crucibles
#REFERENCE:                   al2o3
#REFERENCE MASS /mg:          40.312
#TYPE OF CRUCIBLE:            DSC/TG pan Al2O3
#SAMPLE CRUCIBLE MASS /mg:    0.000
#REFERENCE CRUCIBLE MASS /mg: 0.000
#PROTECTIVE GAS:              N2
#PURGE GAS 1:                 air
#FLOW RATE 1 /(ml/min):       40
#PURGE GAS 2:
#FLOW RATE 2:
#DSC RANGE /æm:               5000
#TG RANGE /æm:                5000
#CORR. CODE:                  020
#EXO:                         +1
#RANGE:                       20.0/5.00(K/min)/800.0
#SEGMENT:                     S1/1

##Temp./øC;DSC/(mW/mg)
 21.94700;-2.7377e-002
 22.94700;-3.8574e-002
 23.94700;-5.4689e-002
 24.94700;-6.8808e-002
 25.94700;-7.9770e-002
 26.94700;-9.0461e-002
 27.94700;    -0.10024
 28.94700;    -0.10860
 29.94700;    -0.11642
 30.94700;    -0.12381
 31.94700;    -0.13117
 32.94700;    -0.13845
 33.94700;    -0.14524
 34.94700;    -0.15180
 35.94700;    -0.15920
 36.94700;    -0.16579
 37.94700;    -0.17126
 38.94700;    -0.17741
 39.94700;    -0.18274
 40.94700;    -0.18866
 41.94700;    -0.19365
 42.94700;    -0.19877
 43.94700;    -0.20366
 44.94700;    -0.20843
 45.94700;    -0.21314
 46.94700;    -0.21827
 47.94700;    -0.22243
 48.94700;    -0.22549
 49.94700;    -0.22898
 50.94700;    -0.23294
 51.94700;    -0.23609
 52.94700;    -0.23916
 53.94700;    -0.24157
 54.94700;    -0.24430
 55.94700;    -0.24631
 56.94700;    -0.24814
 57.94700;    -0.25053
 58.94700;    -0.25140
 59.94700;    -0.25276
 60.94700;    -0.25296
 61.94700;    -0.25347
 62.94700;    -0.25336
 63.94700;    -0.25344
 64.94700;    -0.25233
 65.94700;    -0.25075
 66.94700;    -0.24912
 67.94700;    -0.24740
 68.94700;    -0.24491
 69.94700;    -0.24263
 70.94700;    -0.23881
 71.94700;    -0.23429
 72.94700;    -0.23044
 73.94700;    -0.22613
 74.94700;    -0.22174
 75.94700;    -0.21579
 76.94700;    -0.21049
 77.94700;    -0.20419
 78.94700;    -0.19760
 79.94700;    -0.19113
 80.94700;    -0.18487
 81.94700;    -0.17757
 82.94700;    -0.17065
 83.94700;    -0.16345
 84.94700;    -0.15561
 85.94700;    -0.14857
 86.94700;    -0.14099
 87.94700;    -0.13388
 88.94700;    -0.12653
 89.94700;    -0.11848
 90.94700;    -0.11100
 91.94700;    -0.10420
 92.94700;-9.7230e-002
 93.94700;-9.0713e-002
 94.94700;-8.3935e-002
 95.94700;-7.7353e-002
 96.94700;-7.1672e-002
 97.94700;-6.5151e-002
 98.94700;-5.9233e-002
 99.94700;-5.3163e-002
100.94700;-4.8064e-002
101.94700;-4.3025e-002
102.94700;-3.8032e-002
103.94700;-3.3022e-002
104.94700;-2.8252e-002
105.94700;-2.3378e-002
106.94700;-1.9290e-002
107.94700;-1.5221e-002
108.94700;-1.0794e-002
109.94700;-7.1274e-003
110.94700;-3.0185e-003
111.94700; 3.9030e-004
112.94700; 3.9618e-003
113.94700; 7.8427e-003
114.94700; 1.1242e-002
115.94700; 1.4466e-002
116.94700; 1.8305e-002
117.94700; 2.1564e-002
118.94700; 2.5068e-002
119.94700; 2.7606e-002
120.94700; 3.0928e-002
121.94700; 3.4283e-002
122.94700; 3.7583e-002
123.94700; 4.0237e-002
124.94700; 4.3386e-002
125.94700; 4.6379e-002
126.94700; 4.9241e-002
127.94700; 5.2624e-002
128.94700; 5.5185e-002
129.94700; 5.7935e-002
130.94700; 6.0613e-002
131.94700; 6.3561e-002
132.94700; 6.6702e-002
133.94700; 6.9277e-002
134.94700; 7.2185e-002
135.94700; 7.4942e-002
136.94700; 7.9082e-002
137.94700; 8.1527e-002
138.94700; 8.4227e-002
139.94700; 8.7687e-002
140.94700; 9.0307e-002
141.94700; 9.3981e-002
142.94700; 9.6678e-002
143.94700; 9.9665e-002
144.94700;     0.10299
145.94700;     0.10619
146.94700;     0.10952
147.94700;     0.11211
148.94700;     0.11520
149.94700;     0.11837
150.94700;     0.12142
151.94700;     0.12494
152.94700;     0.12875
153.94700;     0.13180
154.94700;     0.13491
155.94700;     0.13858
156.94700;     0.14155
157.94700;     0.14472
158.94700;     0.14872
159.94700;     0.15140
160.94700;     0.15536
161.94700;     0.15854
162.94700;     0.16207
163.94700;     0.16575
164.94700;     0.16923
165.94700;     0.17239
166.94700;     0.17642
167.94700;     0.18051
168.94700;     0.18370
169.94700;     0.18707
170.94700;     0.19115
171.94700;     0.19453
172.94700;     0.19854
173.94700;     0.20221
174.94700;     0.20591
175.94700;     0.20993
176.94700;     0.21352
177.94700;     0.21693
178.94700;     0.22102
179.94700;     0.22479
180.94700;     0.22801
181.94700;     0.23272
182.94700;     0.23750
183.94700;     0.24096
184.94700;     0.24455
185.94700;     0.24832
186.94700;     0.25195
187.94700;     0.25611
188.94700;     0.25959
189.94700;     0.26391
190.94700;     0.26782
191.94700;     0.27211
192.94700;     0.27595
193.94700;     0.27964
194.94700;     0.28443
195.94700;     0.28912
196.94700;     0.29278
197.94700;     0.29683
198.94700;     0.30157
199.94700;     0.30614
200.94700;     0.31098
201.94700;     0.31461
202.94700;     0.31937
203.94700;     0.32381
204.94700;     0.32789
205.94700;     0.33353
206.94700;     0.33795
207.94700;     0.34308
208.94700;     0.34802
209.94700;     0.35379
210.94700;     0.35865
211.94700;     0.36425
212.94700;     0.36982
213.94700;     0.37552
214.94700;     0.38109
215.94700;     0.38669
216.94700;     0.39323
217.94700;     0.39859
218.94700;     0.40576
219.94700;     0.41280
220.94700;     0.41879
221.94700;     0.42626
222.94700;     0.43393
223.94700;     0.44124
224.94700;     0.44887
225.94700;     0.45761
226.94700;     0.46574
227.94700;     0.47425
228.94700;     0.48394
229.94700;     0.49334
230.94700;     0.50303
231.94700;     0.51323
232.94700;     0.52384
233.94700;     0.53500
234.94700;     0.54611
235.94700;     0.55849
236.94700;     0.57019
237.94700;     0.58313
238.94700;     0.59626
239.94700;     0.60998
240.94700;     0.62308
241.94700;     0.63852
242.94700;     0.65378
243.94700;     0.66781
244.94700;     0.68445
245.94700;     0.70058
246.94700;     0.71637
247.94700;     0.73304
248.94700;     0.75037
249.94700;     0.76671
250.94700;     0.78271
251.94700;     0.80017
252.94700;     0.81638
253.94700;     0.83366
254.94700;     0.85096
255.94700;     0.86727
256.94700;     0.88385
257.94700;     0.89955
258.94700;     0.91541
259.94700;     0.93126
260.94700;     0.94619
261.94700;     0.96004
262.94700;     0.97404
263.94700;     0.98619
264.94700;     0.99842
265.94700;     1.00887
266.94700;     1.01754
267.94700;     1.02460
268.94700;     1.02878
269.94700;     1.03028
270.94700;     1.02686
271.94700;     1.01837
272.94700;     1.00471
273.94700;     0.98330
274.94700;     0.95419
275.94700;     0.91511
276.94700;     0.87506
277.94700;     0.83910
278.94700;     0.82539
279.94700;     0.85162
280.94700;     0.92293
281.94700;     1.03170
282.94700;     1.14952
283.94700;     1.25472
284.94700;     1.33642
285.94700;     1.39609
286.94700;     1.43806
287.94700;     1.46850
288.94700;     1.49337
289.94700;     1.51313
290.94700;     1.53099
291.94700;     1.54646
292.94700;     1.56239
293.94700;     1.57853
294.94700;     1.59611
295.94700;     1.61463
296.94700;     1.63471
297.94700;     1.65591
298.94700;     1.67954
299.94700;     1.70577
300.94700;     1.73464
301.94700;     1.76793
302.94700;     1.80408
303.94700;     1.84744
304.94700;     1.89659
305.94700;     1.95297
306.94700;     2.02096
307.94700;     2.10378
308.94700;     2.19422
309.94700;     2.29942
310.94700;     2.41783
311.94700;     2.54752
312.94700;     2.68768
313.94700;     2.82910
314.94700;     2.97889
315.94700;     3.13116
316.94700;     3.28227
317.94700;     3.44898
318.94700;     3.76492
319.94700;     3.78383
320.94700;     3.78443
321.94700;     3.78142
322.94700;     3.77539
323.94700;     3.76681
324.94700;     3.75848
325.94700;     3.74905
326.94700;     3.73808
327.94700;     3.72455
328.94700;     3.70770
329.94700;     3.68965
330.94700;     3.67086
331.94700;     3.64845
332.94700;     3.62298
333.94700;     3.59564
334.94700;     3.56491
335.94700;     3.53315
336.94700;     3.50111
337.94700;     3.46620
338.94700;     3.42953
339.94700;     3.39292
340.94700;     3.35482
341.94700;     3.31497
342.94700;     3.27478
343.94700;     3.23387
344.94700;     3.19353
345.94700;     3.15092
346.94700;     3.10951
347.94700;     3.06927
348.94700;     3.02950
349.94700;     2.99091
350.94700;     2.95250
351.94700;     2.91521
352.94700;     2.87983
353.94700;     2.84436
354.94700;     2.81091
355.94700;     2.77656
356.94700;     2.74353
357.94700;     2.71374
358.94700;     2.68453
359.94700;     2.65609
360.94700;     2.62989
361.94700;     2.60536
362.94700;     2.58087
363.94700;     2.55633
364.94700;     2.53450
365.94700;     2.51476
366.94700;     2.49518
367.94700;     2.47574
368.94700;     2.45734
369.94700;     2.44105
370.94700;     2.42703
371.94700;     2.41153
372.94700;     2.39664
373.94700;     2.38289
374.94700;     2.37098
375.94700;     2.36015
376.94700;     2.34990
377.94700;     2.34476
378.94700;     2.33384
379.94700;     2.32413
380.94700;     2.31692
381.94700;     2.31213
382.94700;     2.30852
383.94700;     2.30576
384.94700;     2.30246
385.94700;     2.30029
386.94700;     2.29850
387.94700;     2.29962
388.94700;     2.30000
389.94700;     2.30006
390.94700;     2.30195
391.94700;     2.30368
392.94700;     2.30654
393.94700;     2.31060
394.94700;     2.31594
395.94700;     2.32166
396.94700;     2.32913
397.94700;     2.33700
398.94700;     2.34705
399.94700;     2.35841
400.94700;     2.36839
401.94700;     2.37966
402.94700;     2.39280
403.94700;     2.41034
404.94700;     2.42846
405.94700;     2.44827
406.94700;     2.47189
407.94700;     2.49595
408.94700;     2.52066
409.94700;     2.54828
410.94700;     2.58066
411.94700;     2.61321
412.94700;     2.64916
413.94700;     2.68954
414.94700;     2.73260
415.94700;     2.77986
416.94700;     2.82646
417.94700;     2.87935
418.94700;     2.93791
419.94700;     3.00353
420.94700;     3.07643
421.94700;     3.16154
422.94700;     3.26800
423.94700;     3.34694
424.94700;     3.44724
425.94700;     3.57203
426.94700;     3.71968
427.94700;     3.89895
428.94700;     4.12565
429.94700;     4.41718
430.94700;     4.82422
431.94700;     5.44150
432.94700;     6.43836
433.94700;     9.54529
434.94700;    11.76419
435.94700;    12.93137
436.94700;    13.24965
437.94700;    12.67302
438.94700;    11.65817
439.94700;     5.06392
440.94700;     2.34740
441.94700;     1.93665
442.94700;     1.81941
443.94700;     1.79263
444.94700;     1.80294
445.94700;     1.83531
446.94700;     1.88592
447.94700;     1.84423
448.94700;     1.71004
449.94700;     1.56619
450.94700;     1.44395
451.94700;     1.32941
452.94700;     1.22841
453.94700;     1.11636
454.94700;     0.99375
455.94700;     0.88215
456.94700;     0.77579
457.94700;     0.67302
458.94700;     0.57579
459.94700;     0.48766
460.94700;     0.41008
461.94700;     0.34708
462.94700;     0.29604
463.94700;     0.25591
464.94700;     0.22446
465.94700;     0.20072
466.94700;     0.18191
467.94700;     0.16754
468.94700;     0.15612
469.94700;     0.14804
470.94700;     0.14232
471.94700;     0.13851
472.94700;     0.13494
473.94700;     0.13254
474.94700;     0.13126
475.94700;     0.13066
476.94700;     0.13040
477.94700;     0.13020
478.94700;     0.13016
479.94700;     0.12998
480.94700;     0.13028
481.94700;     0.13031
482.94700;     0.13034
483.94700;     0.13050
484.94700;     0.13067
485.94700;     0.13168
486.94700;     0.13094
487.94700;     0.13160
488.94700;     0.13237
489.94700;     0.13198
490.94700;     0.13296
491.94700;     0.13365
492.94700;     0.13349
493.94700;     0.13466
494.94700;     0.13512
495.94700;     0.13513
496.94700;     0.13549
497.94700;     0.13541
498.94700;     0.13642
499.94700;     0.13675
500.94700;     0.13694
501.94700;     0.13706
502.94700;     0.13699
503.94700;     0.13826
504.94700;     0.13922
505.94700;     0.13964
506.94700;     0.14041
507.94700;     0.14035
508.94700;     0.14165
509.94700;     0.14161
510.94700;     0.14289
511.94700;     0.14381
512.94700;     0.14443
513.94700;     0.14435
514.94700;     0.14506
515.94700;     0.14521
516.94700;     0.14555
517.94700;     0.14608
518.94700;     0.14658
519.94700;     0.14693
520.94700;     0.14666
521.94700;     0.14655
522.94700;     0.14746
523.94700;     0.14877
524.94700;     0.14902
525.94700;     0.14934
526.94700;     0.14957
527.94700;     0.15008
528.94700;     0.15050
529.94700;     0.15138
530.94700;     0.15181
531.94700;     0.15254
532.94700;     0.15308
533.94700;     0.15344
534.94700;     0.15372
535.94700;     0.15470
536.94700;     0.15501
537.94700;     0.15611
538.94700;     0.15662
539.94700;     0.15618
540.94700;     0.15750
541.94700;     0.15718
542.94700;     0.15822
543.94700;     0.15907
544.94700;     0.16024
545.94700;     0.16081
546.94700;     0.16059
547.94700;     0.16199
548.94700;     0.16274
549.94700;     0.16351
550.94700;     0.16431
551.94700;     0.16430
552.94700;     0.16517
553.94700;     0.16686
554.94700;     0.16712
555.94700;     0.16618
556.94700;     0.16633
557.94700;     0.16699
558.94700;     0.16779
559.94700;     0.16817
560.94700;     0.16944
561.94700;     0.16979
562.94700;     0.17136
563.94700;     0.17003
564.94700;     0.17001
565.94700;     0.17082
566.94700;     0.17107
567.94700;     0.17149
568.94700;     0.17121
569.94700;     0.17290
570.94700;     0.17329
571.94700;     0.17377
572.94700;     0.17422
573.94700;     0.17491
574.94700;     0.17547
575.94700;     0.17615
576.94700;     0.17656
577.94700;     0.17658
578.94700;     0.17695
579.94700;     0.17741
580.94700;     0.17698
581.94700;     0.17791
582.94700;     0.17940
583.94700;     0.17939
584.94700;     0.17921
585.94700;     0.17853
586.94700;     0.17915
587.94700;     0.18056
588.94700;     0.18014
589.94700;     0.18049
590.94700;     0.18101
591.94700;     0.18139
592.94700;     0.18224
593.94700;     0.18240
594.94700;     0.18306
595.94700;     0.18372
596.94700;     0.18452
597.94700;     0.18540
598.94700;     0.18507
599.94700;     0.18628
600.94700;     0.18638
601.94700;     0.18705
602.94700;     0.18723
603.94700;     0.18821
604.94700;     0.18727
605.94700;     0.18870
606.94700;     0.18960
607.94700;     0.19040
608.94700;     0.19069
609.94700;     0.19124
610.94700;     0.19123
611.94700;     0.19075
612.94700;     0.19093
613.94700;     0.19138
614.94700;     0.19091
615.94700;     0.19008
616.94700;     0.18997
617.94700;     0.19104
618.94700;     0.19108
619.94700;     0.19080
620.94700;     0.19135
621.94700;     0.19320
622.94700;     0.19457
623.94700;     0.19736
624.94700;     0.19893
625.94700;     0.20010
626.94700;     0.20131
627.94700;     0.20285
628.94700;     0.20192
629.94700;     0.20385
630.94700;     0.20316
631.94700;     0.20505
632.94700;     0.20572
633.94700;     0.20720
634.94700;     0.20911
635.94700;     0.20913
636.94700;     0.20990
637.94700;     0.21174
638.94700;     0.21262
639.94700;     0.21271
640.94700;     0.21362
641.94700;     0.21380
642.94700;     0.21392
643.94700;     0.21461
644.94700;     0.21608
645.94700;     0.21703
646.94700;     0.21821
647.94700;     0.21882
648.94700;     0.22052
649.94700;     0.22087
650.94700;     0.22184
651.94700;     0.22339
652.94700;     0.22444
653.94700;     0.22564
654.94700;     0.22679
655.94700;     0.22769
656.94700;     0.23015
657.94700;     0.23191
658.94700;     0.23270
659.94700;     0.23369
660.94700;     0.23550
661.94700;     0.23678
662.94700;     0.23861
663.94700;     0.23992
664.94700;     0.24205
665.94700;     0.24379
666.94700;     0.24388
667.94700;     0.24514
668.94700;     0.24630
669.94700;     0.24754
670.94700;     0.24892
671.94700;     0.24977
672.94700;     0.25137
673.94700;     0.25166
674.94700;     0.25384
675.94700;     0.25543
676.94700;     0.25653
677.94700;     0.25823
678.94700;     0.26073
679.94700;     0.26131
680.94700;     0.26321
681.94700;     0.26409
682.94700;     0.26504
683.94700;     0.26649
684.94700;     0.26733
685.94700;     0.26895
686.94700;     0.26928
687.94700;     0.27148
688.94700;     0.27356
689.94700;     0.27496
690.94700;     0.27608
691.94700;     0.27828
692.94700;     0.28042
693.94700;     0.28057
694.94700;     0.28223
695.94700;     0.28383
696.94700;     0.28647
697.94700;     0.28731
698.94700;     0.28890
699.94700;     0.28959
700.94700;     0.29147
701.94700;     0.29296
702.94700;     0.29467
703.94700;     0.29627
704.94700;     0.29790
705.94700;     0.29933
706.94700;     0.30036
707.94700;     0.30210
708.94700;     0.30402
709.94700;     0.30686
710.94700;     0.30806
711.94700;     0.30960
712.94700;     0.31067
713.94700;     0.31351
714.94700;     0.31569
715.94700;     0.31646
716.94700;     0.31747
717.94700;     0.31768
718.94700;     0.31988
719.94700;     0.32078
720.94700;     0.32340
721.94700;     0.32525
722.94700;     0.32562
723.94700;     0.32613
724.94700;     0.32789
725.94700;     0.32946
726.94700;     0.33111
727.94700;     0.33191
728.94700;     0.33316
729.94700;     0.33327
730.94700;     0.33474
731.94700;     0.33603
732.94700;     0.33648
733.94700;     0.33818
734.94700;     0.34038
735.94700;     0.34105
736.94700;     0.34211
737.94700;     0.34411
738.94700;     0.34604
739.94700;     0.34501
740.94700;     0.34764
741.94700;     0.34868
742.94700;     0.34955
743.94700;     0.35168
744.94700;     0.35341
745.94700;     0.35495
746.94700;     0.35529
747.94700;     0.35759
748.94700;     0.35830
749.94700;     0.36116
750.94700;     0.36122
751.94700;     0.36281
752.94700;     0.36283
753.94700;     0.36311
754.94700;     0.36514
755.94700;     0.36681
756.94700;     0.36681
757.94700;     0.36708
758.94700;     0.36682
759.94700;     0.36895
760.94700;     0.36943
761.94700;     0.37178
762.94700;     0.37460
763.94700;     0.37634
764.94700;     0.37774
765.94700;     0.37899
766.94700;     0.38002
767.94700;     0.38176
768.94700;     0.38186
769.94700;     0.38343
770.94700;     0.38422
771.94700;     0.38446
772.94700;     0.38536
773.94700;     0.38747
774.94700;     0.38717
775.94700;     0.38765
776.94700;     0.38894
777.94700;     0.39055
778.94700;     0.39290
779.94700;     0.39322
780.94700;     0.39379
781.94700;     0.39517
782.94700;     0.39528
783.94700;     0.39771
784.94700;     0.39606
785.94700;     0.39709
786.94700;     0.39768
787.94700;     0.39855
788.94700;     0.39942
789.94700;     0.40001
790.94700;     0.40004
791.94700;     0.40110
792.94700;     0.39768
793.94700;     0.38263
794.94700;     0.38275
795.94700;     0.37249
796.94700;     0.37595
797.94700;     0.37782