File: examples/Birch/TGA_DSC data T18/13WaT18 5 K min N2 16.2.2007.TG.txt
#FILE:                        13WaT18 5 K min N2 16.2.2007.dsu
#FORMAT:                      NETZSCH4
#IDENTITY:                    13 WaT18 5 K min N2
#DECIMAL:                     POINT
#SEPARATOR:                   SEMICOLON
#MTYPE:                       TG
#INSTRUMENT:                  NETZSCH STA 449C
#PROJECT:                     vtt
#DATE/TIME:                   16.2.2007 7:57:49
#CORR. FILE:                  correction 5K min N2 800 C.bsu
#LABORATORY:                  EO
#OPERATOR:                    TL
#REMARK:
#SAMPLE:                      13 WaT18
#SAMPLE MASS /mg:             11.322
#MATERIAL:                    Empty crucibles
#REFERENCE:                   al2o3
#REFERENCE MASS /mg:          40.312
#TYPE OF CRUCIBLE:            DSC/TG pan Al2O3
#SAMPLE CRUCIBLE MASS /mg:    0.000
#REFERENCE CRUCIBLE MASS /mg: 0.000
#PROTECTIVE GAS:              N2
#PURGE GAS 1:                 air
#FLOW RATE 1 /(ml/min):       40
#PURGE GAS 2:
#FLOW RATE 2:
#DSC RANGE /æm:               5000
#TG RANGE /æm:                5000
#CORR. CODE:                  020
#EXO:                         +1
#RANGE:                       20.0/5.00(K/min)/800.0
#SEGMENT:                     S1/2

##Temp./øC;Mass/%
 23.04100;100.00000
 24.04100; 99.89137
 25.04100; 99.87282
 26.04100; 99.85116
 27.04100; 99.82487
 28.04100; 99.80184
 29.04100; 99.77884
 30.04100; 99.74819
 31.04100; 99.72757
 32.04100; 99.70219
 33.04100; 99.67337
 34.04100; 99.64827
 35.04100; 99.62779
 36.04100; 99.59774
 37.04100; 99.56488
 38.04100; 99.54351
 39.04100; 99.51948
 40.04100; 99.48867
 41.04100; 99.45785
 42.04100; 99.42420
 43.04100; 99.37956
 44.04100; 99.34579
 45.04100; 99.30368
 46.04100; 99.26712
 47.04100; 99.22037
 48.04100; 99.17742
 49.04100; 99.13426
 50.04100; 99.08698
 51.04100; 99.03501
 52.04100; 98.98448
 53.04100; 98.93634
 54.04100; 98.88433
 55.04100; 98.82637
 56.04100; 98.77219
 57.04100; 98.71107
 58.04100; 98.65496
 59.04100; 98.59056
 60.04100; 98.52996
 61.04100; 98.46917
 62.04100; 98.40895
 63.04100; 98.34398
 64.04100; 98.28084
 65.04100; 98.22033
 66.04100; 98.14674
 67.04100; 98.08672
 68.04100; 98.02518
 69.04100; 97.96351
 70.04100; 97.89875
 71.04100; 97.83304
 72.04100; 97.76581
 73.04100; 97.69742
 74.04100; 97.64304
 75.04100; 97.58497
 76.04100; 97.53181
 77.04100; 97.47448
 78.04100; 97.41827
 79.04100; 97.36359
 80.04100; 97.31773
 81.04100; 97.27367
 82.04100; 97.22472
 83.04100; 97.18256
 84.04100; 97.13326
 85.04100; 97.09816
 86.04100; 97.06324
 87.04100; 97.02429
 88.04100; 96.98999
 89.04100; 96.95641
 90.04100; 96.92736
 91.04100; 96.89971
 92.04100; 96.87004
 93.04100; 96.84301
 94.04100; 96.82070
 95.04100; 96.79750
 96.04100; 96.78073
 97.04100; 96.76092
 98.04100; 96.73766
 99.04100; 96.71783
100.04100; 96.70107
101.04100; 96.68790
102.04100; 96.67370
103.04100; 96.65892
104.04100; 96.64176
105.04100; 96.63061
106.04100; 96.61856
107.04100; 96.61089
108.04100; 96.60052
109.04100; 96.58978
110.04100; 96.57731
111.04100; 96.56990
112.04100; 96.56049
113.04100; 96.55180
114.04100; 96.54220
115.04100; 96.53507
116.04100; 96.52987
117.04100; 96.52295
118.04100; 96.51865
119.04100; 96.51430
120.04100; 96.51036
121.04100; 96.50519
122.04100; 96.50120
123.04100; 96.49660
124.04100; 96.49249
125.04100; 96.48713
126.04100; 96.47934
127.04100; 96.47763
128.04100; 96.47411
129.04100; 96.46886
130.04100; 96.46457
131.04100; 96.46003
132.04100; 96.45595
133.04100; 96.44817
134.04100; 96.44583
135.04100; 96.43744
136.04100; 96.42630
137.04100; 96.42902
138.04100; 96.42973
139.04100; 96.42909
140.04100; 96.42645
141.04100; 96.42375
142.04100; 96.42198
143.04100; 96.42104
144.04100; 96.41671
145.04100; 96.41133
146.04100; 96.40516
147.04100; 96.40170
148.04100; 96.39812
149.04100; 96.39461
150.04100; 96.38844
151.04100; 96.38138
152.04100; 96.37792
153.04100; 96.37431
154.04100; 96.36994
155.04100; 96.36380
156.04100; 96.36045
157.04100; 96.35425
158.04100; 96.34974
159.04100; 96.34455
160.04100; 96.33913
161.04100; 96.33289
162.04100; 96.32687
163.04100; 96.32133
164.04100; 96.31733
165.04100; 96.30827
166.04100; 96.30816
167.04100; 96.30295
168.04100; 96.29841
169.04100; 96.29405
170.04100; 96.28690
171.04100; 96.27980
172.04100; 96.27449
173.04100; 96.26654
174.04100; 96.26212
175.04100; 96.25504
176.04100; 96.24707
177.04100; 96.23727
178.04100; 96.22579
179.04100; 96.21231
180.04100; 96.20273
181.04100; 96.19303
182.04100; 96.17894
183.04100; 96.16648
184.04100; 96.15582
185.04100; 96.14531
186.04100; 96.13120
187.04100; 96.11770
188.04100; 96.10555
189.04100; 96.08748
190.04100; 96.07269
191.04100; 96.05887
192.04100; 96.04539
193.04100; 96.02830
194.04100; 96.01080
195.04100; 95.99461
196.04100; 95.97956
197.04100; 95.96349
198.04100; 95.94906
199.04100; 95.92701
200.04100; 95.90586
201.04100; 95.88530
202.04100; 95.86781
203.04100; 95.84947
204.04100; 95.82819
205.04100; 95.81054
206.04100; 95.78737
207.04100; 95.76986
208.04100; 95.74397
209.04100; 95.72650
210.04100; 95.70709
211.04100; 95.68652
212.04100; 95.66592
213.04100; 95.63261
214.04100; 95.60910
215.04100; 95.58369
216.04100; 95.55451
217.04100; 95.53143
218.04100; 95.49566
219.04100; 95.46640
220.04100; 95.43537
221.04100; 95.40618
222.04100; 95.37957
223.04100; 95.33961
224.04100; 95.29638
225.04100; 95.25972
226.04100; 95.22289
227.04100; 95.18017
228.04100; 95.13327
229.04100; 95.08675
230.04100; 95.03566
231.04100; 94.99017
232.04100; 94.93448
233.04100; 94.87809
234.04100; 94.81892
235.04100; 94.75868
236.04100; 94.69077
237.04100; 94.63317
238.04100; 94.56037
239.04100; 94.49055
240.04100; 94.41435
241.04100; 94.33564
242.04100; 94.24766
243.04100; 94.16176
244.04100; 94.07055
245.04100; 93.97629
246.04100; 93.87837
247.04100; 93.77603
248.04100; 93.66159
249.04100; 93.54554
250.04100; 93.42411
251.04100; 93.29907
252.04100; 93.16097
253.04100; 93.02029
254.04100; 92.86155
255.04100; 92.69622
256.04100; 92.52111
257.04100; 92.33937
258.04100; 92.15032
259.04100; 91.94516
260.04100; 91.71415
261.04100; 91.48447
262.04100; 91.25798
263.04100; 90.99068
264.04100; 90.73879
265.04100; 90.45239
266.04100; 90.16744
267.04100; 89.85680
268.04100; 89.53650
269.04100; 89.21444
270.04100; 88.87068
271.04100; 88.51484
272.04100; 88.14722
273.04100; 87.76879
274.04100; 87.37954
275.04100; 86.98597
276.04100; 86.57551
277.04100; 86.15063
278.04100; 85.72534
279.04100; 85.30197
280.04100; 84.85588
281.04100; 84.40413
282.04100; 83.95503
283.04100; 83.50064
284.04100; 83.04033
285.04100; 82.57569
286.04100; 82.11398
287.04100; 81.64535
288.04100; 81.17415
289.04100; 80.70280
290.04100; 80.23643
291.04100; 79.76252
292.04100; 79.28529
293.04100; 78.81420
294.04100; 78.34219
295.04100; 77.86264
296.04100; 77.39496
297.04100; 76.93095
298.04100; 76.45422
299.04100; 75.97404
300.04100; 75.50585
301.04100; 75.03894
302.04100; 74.56838
303.04100; 74.08176
304.04100; 73.61579
305.04100; 73.14166
306.04100; 72.65627
307.04100; 72.17508
308.04100; 71.70741
309.04100; 71.22428
310.04100; 70.73458
311.04100; 70.25332
312.04100; 69.77652
313.04100; 69.28618
314.04100; 68.80248
315.04100; 68.31647
316.04100; 67.83448
317.04100; 67.33258
318.04100; 66.84568
319.04100; 66.34745
320.04100; 65.85203
321.04100; 65.35918
322.04100; 64.86378
323.04100; 64.36852
324.04100; 63.87069
325.04100; 63.37603
326.04100; 62.87302
327.04100; 62.37209
328.04100; 61.86355
329.04100; 61.34984
330.04100; 60.83467
331.04100; 60.32225
332.04100; 59.79148
333.04100; 59.25991
334.04100; 58.72414
335.04100; 58.16657
336.04100; 57.60448
337.04100; 57.03369
338.04100; 56.43452
339.04100; 55.82081
340.04100; 55.18949
341.04100; 54.52993
342.04100; 53.83002
343.04100; 52.99964
344.04100; 52.20205
345.04100; 51.40806
346.04100; 50.56964
347.04100; 49.62573
348.04100; 48.92951
349.04100; 47.88593
350.04100; 46.86342
351.04100; 45.72722
352.04100; 44.51621
353.04100; 43.34373
354.04100; 42.17188
355.04100; 40.97288
356.04100; 39.81281
357.04100; 38.47293
358.04100; 37.04364
359.04100; 35.76433
360.04100; 34.56555
361.04100; 33.23311
362.04100; 32.20057
363.04100; 31.15660
364.04100; 29.97286
365.04100; 29.00369
366.04100; 28.28527
367.04100; 27.60185
368.04100; 26.88622
369.04100; 26.37044
370.04100; 25.88584
371.04100; 25.47754
372.04100; 25.14879
373.04100; 24.87890
374.04100; 24.67237
375.04100; 24.48266
376.04100; 24.33192
377.04100; 24.21157
378.04100; 24.10158
379.04100; 23.99840
380.04100; 23.91479
381.04100; 23.82462
382.04100; 23.73813
383.04100; 23.66286
384.04100; 23.58458
385.04100; 23.50683
386.04100; 23.43098
387.04100; 23.36066
388.04100; 23.28357
389.04100; 23.21642
390.04100; 23.14108
391.04100; 23.06935
392.04100; 23.00084
393.04100; 22.92961
394.04100; 22.85663
395.04100; 22.79071
396.04100; 22.72572
397.04100; 22.65348
398.04100; 22.58187
399.04100; 22.51343
400.04100; 22.44710
401.04100; 22.37981
402.04100; 22.30534
403.04100; 22.23744
404.04100; 22.16513
405.04100; 22.10296
406.04100; 22.03203
407.04100; 21.96449
408.04100; 21.89214
409.04100; 21.82755
410.04100; 21.75411
411.04100; 21.68575
412.04100; 21.61699
413.04100; 21.55439
414.04100; 21.49029
415.04100; 21.42186
416.04100; 21.35638
417.04100; 21.29025
418.04100; 21.22752
419.04100; 21.16135
420.04100; 21.10231
421.04100; 21.04111
422.04100; 20.98073
423.04100; 20.91390
424.04100; 20.85730
425.04100; 20.79828
426.04100; 20.74243
427.04100; 20.68889
428.04100; 20.62870
429.04100; 20.57121
430.04100; 20.51801
431.04100; 20.46723
432.04100; 20.41396
433.04100; 20.35936
434.04100; 20.30642
435.04100; 20.25528
436.04100; 20.19977
437.04100; 20.14849
438.04100; 20.09752
439.04100; 20.05527
440.04100; 20.00372
441.04100; 19.96305
442.04100; 19.91520
443.04100; 19.86711
444.04100; 19.82197
445.04100; 19.77457
446.04100; 19.73488
447.04100; 19.69481
448.04100; 19.65189
449.04100; 19.60930
450.04100; 19.56438
451.04100; 19.52268
452.04100; 19.48392
453.04100; 19.44867
454.04100; 19.40640
455.04100; 19.36424
456.04100; 19.33068
457.04100; 19.29518
458.04100; 19.25491
459.04100; 19.22231
460.04100; 19.18750
461.04100; 19.14764
462.04100; 19.11367
463.04100; 19.07763
464.04100; 19.04357
465.04100; 19.01437
466.04100; 18.97710
467.04100; 18.94618
468.04100; 18.90837
469.04100; 18.87534
470.04100; 18.84230
471.04100; 18.81680
472.04100; 18.78795
473.04100; 18.75368
474.04100; 18.72539
475.04100; 18.69304
476.04100; 18.66371
477.04100; 18.62392
478.04100; 18.60015
479.04100; 18.57022
480.04100; 18.53944
481.04100; 18.51236
482.04100; 18.47792
483.04100; 18.45495
484.04100; 18.42556
485.04100; 18.40244
486.04100; 18.37476
487.04100; 18.34010
488.04100; 18.31829
489.04100; 18.29414
490.04100; 18.26672
491.04100; 18.23785
492.04100; 18.21229
493.04100; 18.17530
494.04100; 18.14768
495.04100; 18.12272
496.04100; 18.10482
497.04100; 18.07043
498.04100; 18.04657
499.04100; 18.02015
500.04100; 18.00060
501.04100; 17.96654
502.04100; 17.94930
503.04100; 17.92006
504.04100; 17.89749
505.04100; 17.86832
506.04100; 17.84868
507.04100; 17.82420
508.04100; 17.80096
509.04100; 17.77353
510.04100; 17.74705
511.04100; 17.72827
512.04100; 17.70747
513.04100; 17.68153
514.04100; 17.65501
515.04100; 17.63256
516.04100; 17.60498
517.04100; 17.58152
518.04100; 17.56230
519.04100; 17.54000
520.04100; 17.51355
521.04100; 17.49718
522.04100; 17.47659
523.04100; 17.45148
524.04100; 17.42857
525.04100; 17.40705
526.04100; 17.38072
527.04100; 17.35975
528.04100; 17.34864
529.04100; 17.32842
530.04100; 17.30433
531.04100; 17.27808
532.04100; 17.25317
533.04100; 17.22974
534.04100; 17.20844
535.04100; 17.19048
536.04100; 17.17712
537.04100; 17.14639
538.04100; 17.12372
539.04100; 17.10621
540.04100; 17.08616
541.04100; 17.06673
542.04100; 17.04455
543.04100; 17.02890
544.04100; 17.01048
545.04100; 16.99002
546.04100; 16.97675
547.04100; 16.95121
548.04100; 16.93685
549.04100; 16.91621
550.04100; 16.89364
551.04100; 16.87567
552.04100; 16.85875
553.04100; 16.83681
554.04100; 16.81454
555.04100; 16.80009
556.04100; 16.78434
557.04100; 16.76178
558.04100; 16.74359
559.04100; 16.71859
560.04100; 16.70436
561.04100; 16.68359
562.04100; 16.66984
563.04100; 16.64927
564.04100; 16.63102
565.04100; 16.61961
566.04100; 16.60225
567.04100; 16.59120
568.04100; 16.57080
569.04100; 16.55609
570.04100; 16.53301
571.04100; 16.51873
572.04100; 16.50086
573.04100; 16.48306
574.04100; 16.46868
575.04100; 16.44548
576.04100; 16.43227
577.04100; 16.41565
578.04100; 16.40337
579.04100; 16.39000
580.04100; 16.36970
581.04100; 16.35745
582.04100; 16.33887
583.04100; 16.31154
584.04100; 16.31072
585.04100; 16.29652
586.04100; 16.27802
587.04100; 16.26920
588.04100; 16.24889
589.04100; 16.23652
590.04100; 16.21271
591.04100; 16.19510
592.04100; 16.18097
593.04100; 16.16780
594.04100; 16.15885
595.04100; 16.14480
596.04100; 16.13074
597.04100; 16.11497
598.04100; 16.10098
599.04100; 16.08759
600.04100; 16.06901
601.04100; 16.05693
602.04100; 16.04170
603.04100; 16.02862
604.04100; 16.02119
605.04100; 16.00193
606.04100; 15.99639
607.04100; 15.98356
608.04100; 15.96862
609.04100; 15.95931
610.04100; 15.93885
611.04100; 15.93154
612.04100; 15.91915
613.04100; 15.90653
614.04100; 15.89653
615.04100; 15.88264
616.04100; 15.87217
617.04100; 15.85831
618.04100; 15.85153
619.04100; 15.83728
620.04100; 15.82820
621.04100; 15.81726
622.04100; 15.80703
623.04100; 15.80163
624.04100; 15.78577
625.04100; 15.77274
626.04100; 15.76112
627.04100; 15.75685
628.04100; 15.74773
629.04100; 15.73935
630.04100; 15.72557
631.04100; 15.71845
632.04100; 15.69529
633.04100; 15.68913
634.04100; 15.67736
635.04100; 15.66731
636.04100; 15.65532
637.04100; 15.64409
638.04100; 15.63311
639.04100; 15.62570
640.04100; 15.61495
641.04100; 15.60609
642.04100; 15.60182
643.04100; 15.58976
644.04100; 15.58211
645.04100; 15.57620
646.04100; 15.56498
647.04100; 15.55020
648.04100; 15.54423
649.04100; 15.53831
650.04100; 15.53057
651.04100; 15.52077
652.04100; 15.50799
653.04100; 15.50091
654.04100; 15.49309
655.04100; 15.48679
656.04100; 15.47625
657.04100; 15.47452
658.04100; 15.46395
659.04100; 15.45576
660.04100; 15.44794
661.04100; 15.44435
662.04100; 15.43023
663.04100; 15.42832
664.04100; 15.42128
665.04100; 15.41332
666.04100; 15.40367
667.04100; 15.39480
668.04100; 15.38850
669.04100; 15.37882
670.04100; 15.37257
671.04100; 15.36286
672.04100; 15.35146
673.04100; 15.34246
674.04100; 15.34107
675.04100; 15.33262
676.04100; 15.32401
677.04100; 15.31905
678.04100; 15.31396
679.04100; 15.30798
680.04100; 15.29634
681.04100; 15.29124
682.04100; 15.28312
683.04100; 15.27265
684.04100; 15.26678
685.04100; 15.26023
686.04100; 15.25343
687.04100; 15.24553
688.04100; 15.23715
689.04100; 15.23070
690.04100; 15.22657
691.04100; 15.22056
692.04100; 15.21487
693.04100; 15.20622
694.04100; 15.19685
695.04100; 15.18984
696.04100; 15.18081
697.04100; 15.17836
698.04100; 15.16904
699.04100; 15.16204
700.04100; 15.15638
701.04100; 15.14812
702.04100; 15.14022
703.04100; 15.12946
704.04100; 15.12308
705.04100; 15.11793
706.04100; 15.10866
707.04100; 15.10344
708.04100; 15.09653
709.04100; 15.09279
710.04100; 15.08657
711.04100; 15.08127
712.04100; 15.07240
713.04100; 15.06356
714.04100; 15.05830
715.04100; 15.05743
716.04100; 15.04850
717.04100; 15.04236
718.04100; 15.03873
719.04100; 15.02890
720.04100; 15.02199
721.04100; 15.01570
722.04100; 15.01225
723.04100; 15.00641
724.04100; 14.99914
725.04100; 14.99365
726.04100; 14.98852
727.04100; 14.98287
728.04100; 14.97445
729.04100; 14.96978
730.04100; 14.96703
731.04100; 14.95877
732.04100; 14.94985
733.04100; 14.94045
734.04100; 14.93513
735.04100; 14.92584
736.04100; 14.91920
737.04100; 14.91831
738.04100; 14.91525
739.04100; 14.90622
740.04100; 14.89902
741.04100; 14.89531
742.04100; 14.88632
743.04100; 14.88455
744.04100; 14.87929
745.04100; 14.87239
746.04100; 14.86089
747.04100; 14.85707
748.04100; 14.84646
749.04100; 14.84284
750.04100; 14.83939
751.04100; 14.82778
752.04100; 14.82600
753.04100; 14.81980
754.04100; 14.81708
755.04100; 14.81090
756.04100; 14.80381
757.04100; 14.79942
758.04100; 14.79416
759.04100; 14.78959
760.04100; 14.78174
761.04100; 14.77574
762.04100; 14.76999
763.04100; 14.76598
764.04100; 14.76235
765.04100; 14.75765
766.04100; 14.75051
767.04100; 14.74361
768.04100; 14.73661
769.04100; 14.73365
770.04100; 14.72353
771.04100; 14.71763
772.04100; 14.70706
773.04100; 14.70078
774.04100; 14.69840
775.04100; 14.69452
776.04100; 14.68953
777.04100; 14.68389
778.04100; 14.67664
779.04100; 14.67236
780.04100; 14.66603
781.04100; 14.66212
782.04100; 14.65419
783.04100; 14.64613
784.04100; 14.64542
785.04100; 14.64176
786.04100; 14.63554
787.04100; 14.62591
788.04100; 14.62233
789.04100; 14.62023
790.04100; 14.61488
791.04100; 14.60898
792.04100; 14.60441
793.04100; 14.59836
794.04100; 14.59382
795.04100; 14.58860
796.04100; 14.58059
797.04100; 14.57870