File: examples/Birch/TGA_DSC data T18/13WaT18 5 K min N2 16.2.2007.DSC.txt
#FILE:                        13WaT18 5 K min N2 16.2.2007.dsu
#FORMAT:                      NETZSCH4
#IDENTITY:                    13 WaT18 5 K min N2
#DECIMAL:                     POINT
#SEPARATOR:                   SEMICOLON
#MTYPE:                       DSC
#INSTRUMENT:                  NETZSCH STA 449C
#PROJECT:                     vtt
#DATE/TIME:                   16.2.2007 7:57:49
#CORR. FILE:                  correction 5K min N2 800 C.bsu
#LABORATORY:                  EO
#OPERATOR:                    TL
#REMARK:
#SAMPLE:                      13 WaT18
#SAMPLE MASS /mg:             11.322
#MATERIAL:                    Empty crucibles
#REFERENCE:                   al2o3
#REFERENCE MASS /mg:          40.312
#TYPE OF CRUCIBLE:            DSC/TG pan Al2O3
#SAMPLE CRUCIBLE MASS /mg:    0.000
#REFERENCE CRUCIBLE MASS /mg: 0.000
#PROTECTIVE GAS:              N2
#PURGE GAS 1:                 air
#FLOW RATE 1 /(ml/min):       40
#PURGE GAS 2:
#FLOW RATE 2:
#DSC RANGE /æm:               5000
#TG RANGE /æm:                5000
#CORR. CODE:                  020
#EXO:                         +1
#RANGE:                       20.0/5.00(K/min)/800.0
#SEGMENT:                     S1/2

##Temp./øC;DSC/(mW/mg)
 23.04100;-2.2219e-002
 24.04100;-2.5020e-002
 25.04100;-3.6683e-002
 26.04100;-4.8180e-002
 27.04100;-5.8692e-002
 28.04100;-6.7897e-002
 29.04100;-7.7086e-002
 30.04100;-8.5774e-002
 31.04100;-9.3221e-002
 32.04100;    -0.10065
 33.04100;    -0.10877
 34.04100;    -0.11630
 35.04100;    -0.12190
 36.04100;    -0.12927
 37.04100;    -0.13559
 38.04100;    -0.14140
 39.04100;    -0.14850
 40.04100;    -0.15456
 41.04100;    -0.15963
 42.04100;    -0.16539
 43.04100;    -0.17046
 44.04100;    -0.17593
 45.04100;    -0.18091
 46.04100;    -0.18563
 47.04100;    -0.19096
 48.04100;    -0.19499
 49.04100;    -0.19868
 50.04100;    -0.20242
 51.04100;    -0.20704
 52.04100;    -0.21043
 53.04100;    -0.21413
 54.04100;    -0.21663
 55.04100;    -0.21923
 56.04100;    -0.22184
 57.04100;    -0.22340
 58.04100;    -0.22597
 59.04100;    -0.22777
 60.04100;    -0.22847
 61.04100;    -0.22869
 62.04100;    -0.22941
 63.04100;    -0.22937
 64.04100;    -0.22922
 65.04100;    -0.22844
 66.04100;    -0.22726
 67.04100;    -0.22537
 68.04100;    -0.22263
 69.04100;    -0.22011
 70.04100;    -0.21632
 71.04100;    -0.21358
 72.04100;    -0.20918
 73.04100;    -0.20501
 74.04100;    -0.19959
 75.04100;    -0.19438
 76.04100;    -0.18862
 77.04100;    -0.18241
 78.04100;    -0.17619
 79.04100;    -0.17006
 80.04100;    -0.16311
 81.04100;    -0.15489
 82.04100;    -0.14815
 83.04100;    -0.14151
 84.04100;    -0.13325
 85.04100;    -0.12637
 86.04100;    -0.11831
 87.04100;    -0.11085
 88.04100;    -0.10309
 89.04100;-9.6174e-002
 90.04100;-8.8759e-002
 91.04100;-8.2228e-002
 92.04100;-7.4945e-002
 93.04100;-6.8651e-002
 94.04100;-6.1811e-002
 95.04100;-5.5927e-002
 96.04100;-4.9796e-002
 97.04100;-4.4303e-002
 98.04100;-3.8143e-002
 99.04100;-3.2797e-002
100.04100;-2.7078e-002
101.04100;-2.2307e-002
102.04100;-1.6525e-002
103.04100;-1.1531e-002
104.04100;-7.6172e-003
105.04100;-1.8722e-003
106.04100; 2.7256e-003
107.04100; 6.8954e-003
108.04100; 1.1164e-002
109.04100; 1.4978e-002
110.04100; 1.8975e-002
111.04100; 2.2601e-002
112.04100; 2.6015e-002
113.04100; 3.0652e-002
114.04100; 3.3811e-002
115.04100; 3.6941e-002
116.04100; 4.0483e-002
117.04100; 4.4652e-002
118.04100; 4.6916e-002
119.04100; 5.0567e-002
120.04100; 5.4715e-002
121.04100; 5.6198e-002
122.04100; 6.0194e-002
123.04100; 6.2656e-002
124.04100; 6.6287e-002
125.04100; 6.9484e-002
126.04100; 7.2159e-002
127.04100; 7.5632e-002
128.04100; 7.8552e-002
129.04100; 8.1431e-002
130.04100; 8.3704e-002
131.04100; 8.6954e-002
132.04100; 8.9699e-002
133.04100; 9.3033e-002
134.04100; 9.6200e-002
135.04100; 9.9260e-002
136.04100;     0.10186
137.04100;     0.10522
138.04100;     0.10800
139.04100;     0.11082
140.04100;     0.11321
141.04100;     0.11607
142.04100;     0.11916
143.04100;     0.12266
144.04100;     0.12515
145.04100;     0.12920
146.04100;     0.13124
147.04100;     0.13486
148.04100;     0.13782
149.04100;     0.14062
150.04100;     0.14353
151.04100;     0.14683
152.04100;     0.14959
153.04100;     0.15253
154.04100;     0.15619
155.04100;     0.15888
156.04100;     0.16221
157.04100;     0.16557
158.04100;     0.16849
159.04100;     0.17157
160.04100;     0.17418
161.04100;     0.17763
162.04100;     0.18057
163.04100;     0.18413
164.04100;     0.18631
165.04100;     0.18981
166.04100;     0.19337
167.04100;     0.19685
168.04100;     0.19931
169.04100;     0.20314
170.04100;     0.20697
171.04100;     0.20968
172.04100;     0.21365
173.04100;     0.21632
174.04100;     0.21990
175.04100;     0.22223
176.04100;     0.22579
177.04100;     0.22830
178.04100;     0.23185
179.04100;     0.23509
180.04100;     0.23723
181.04100;     0.24070
182.04100;     0.24394
183.04100;     0.24713
184.04100;     0.25055
185.04100;     0.25254
186.04100;     0.25506
187.04100;     0.25826
188.04100;     0.26140
189.04100;     0.26424
190.04100;     0.26807
191.04100;     0.27064
192.04100;     0.27484
193.04100;     0.27780
194.04100;     0.28075
195.04100;     0.28475
196.04100;     0.28747
197.04100;     0.29119
198.04100;     0.29445
199.04100;     0.29836
200.04100;     0.30209
201.04100;     0.30590
202.04100;     0.30901
203.04100;     0.31193
204.04100;     0.31563
205.04100;     0.31962
206.04100;     0.32278
207.04100;     0.32657
208.04100;     0.33062
209.04100;     0.33408
210.04100;     0.33764
211.04100;     0.34152
212.04100;     0.34564
213.04100;     0.34902
214.04100;     0.35256
215.04100;     0.35597
216.04100;     0.36032
217.04100;     0.36374
218.04100;     0.36708
219.04100;     0.37135
220.04100;     0.37450
221.04100;     0.37828
222.04100;     0.38118
223.04100;     0.38519
224.04100;     0.38817
225.04100;     0.39189
226.04100;     0.39624
227.04100;     0.39958
228.04100;     0.40337
229.04100;     0.40701
230.04100;     0.41045
231.04100;     0.41398
232.04100;     0.41760
233.04100;     0.42158
234.04100;     0.42588
235.04100;     0.43045
236.04100;     0.43418
237.04100;     0.43840
238.04100;     0.44267
239.04100;     0.44662
240.04100;     0.45086
241.04100;     0.45457
242.04100;     0.45883
243.04100;     0.46217
244.04100;     0.46559
245.04100;     0.46840
246.04100;     0.47283
247.04100;     0.47505
248.04100;     0.47876
249.04100;     0.48237
250.04100;     0.48440
251.04100;     0.48805
252.04100;     0.49052
253.04100;     0.49338
254.04100;     0.49573
255.04100;     0.49828
256.04100;     0.50048
257.04100;     0.50358
258.04100;     0.50573
259.04100;     0.50884
260.04100;     0.51085
261.04100;     0.51326
262.04100;     0.51540
263.04100;     0.51748
264.04100;     0.51967
265.04100;     0.52115
266.04100;     0.52376
267.04100;     0.52586
268.04100;     0.52779
269.04100;     0.52969
270.04100;     0.53187
271.04100;     0.53382
272.04100;     0.53592
273.04100;     0.53865
274.04100;     0.54049
275.04100;     0.54227
276.04100;     0.54626
277.04100;     0.54911
278.04100;     0.55179
279.04100;     0.55354
280.04100;     0.55663
281.04100;     0.55954
282.04100;     0.56295
283.04100;     0.56521
284.04100;     0.56771
285.04100;     0.57122
286.04100;     0.57331
287.04100;     0.57549
288.04100;     0.57881
289.04100;     0.58150
290.04100;     0.58395
291.04100;     0.58601
292.04100;     0.58868
293.04100;     0.59243
294.04100;     0.59517
295.04100;     0.59714
296.04100;     0.59900
297.04100;     0.60188
298.04100;     0.60472
299.04100;     0.60645
300.04100;     0.60894
301.04100;     0.61114
302.04100;     0.61286
303.04100;     0.61503
304.04100;     0.61821
305.04100;     0.62084
306.04100;     0.62252
307.04100;     0.62544
308.04100;     0.62615
309.04100;     0.62835
310.04100;     0.63013
311.04100;     0.63192
312.04100;     0.63243
313.04100;     0.63424
314.04100;     0.63560
315.04100;     0.63642
316.04100;     0.63778
317.04100;     0.63887
318.04100;     0.63939
319.04100;     0.64129
320.04100;     0.64182
321.04100;     0.64239
322.04100;     0.64388
323.04100;     0.64349
324.04100;     0.64432
325.04100;     0.64413
326.04100;     0.64500
327.04100;     0.64506
328.04100;     0.64499
329.04100;     0.64489
330.04100;     0.64411
331.04100;     0.64248
332.04100;     0.64116
333.04100;     0.64023
334.04100;     0.63889
335.04100;     0.63727
336.04100;     0.63472
337.04100;     0.63056
338.04100;     0.62631
339.04100;     0.62113
340.04100;     0.61577
341.04100;     0.60934
342.04100;     0.60210
343.04100;     0.59305
344.04100;     0.58308
345.04100;     0.57328
346.04100;     0.56114
347.04100;     0.54858
348.04100;     0.53471
349.04100;     0.52080
350.04100;     0.50507
351.04100;     0.48937
352.04100;     0.47286
353.04100;     0.45852
354.04100;     0.44578
355.04100;     0.43279
356.04100;     0.42074
357.04100;     0.41089
358.04100;     0.40487
359.04100;     0.40242
360.04100;     0.40333
361.04100;     0.40924
362.04100;     0.41895
363.04100;     0.43190
364.04100;     0.44943
365.04100;     0.46997
366.04100;     0.49370
367.04100;     0.52006
368.04100;     0.54823
369.04100;     0.57674
370.04100;     0.60469
371.04100;     0.63201
372.04100;     0.65673
373.04100;     0.67913
374.04100;     0.69944
375.04100;     0.71605
376.04100;     0.73041
377.04100;     0.74202
378.04100;     0.75142
379.04100;     0.76027
380.04100;     0.76835
381.04100;     0.77362
382.04100;     0.77914
383.04100;     0.78423
384.04100;     0.78889
385.04100;     0.79450
386.04100;     0.79875
387.04100;     0.80227
388.04100;     0.80632
389.04100;     0.81050
390.04100;     0.81549
391.04100;     0.81894
392.04100;     0.82352
393.04100;     0.82671
394.04100;     0.83001
395.04100;     0.83471
396.04100;     0.83821
397.04100;     0.84216
398.04100;     0.84638
399.04100;     0.85015
400.04100;     0.85335
401.04100;     0.85682
402.04100;     0.86047
403.04100;     0.86399
404.04100;     0.86757
405.04100;     0.87131
406.04100;     0.87283
407.04100;     0.87529
408.04100;     0.87848
409.04100;     0.88098
410.04100;     0.88355
411.04100;     0.88764
412.04100;     0.89087
413.04100;     0.89323
414.04100;     0.89589
415.04100;     0.89778
416.04100;     0.90071
417.04100;     0.90330
418.04100;     0.90526
419.04100;     0.90776
420.04100;     0.90985
421.04100;     0.91162
422.04100;     0.91386
423.04100;     0.91523
424.04100;     0.91769
425.04100;     0.91899
426.04100;     0.92150
427.04100;     0.92403
428.04100;     0.92662
429.04100;     0.92849
430.04100;     0.92971
431.04100;     0.93121
432.04100;     0.93341
433.04100;     0.93518
434.04100;     0.93656
435.04100;     0.93869
436.04100;     0.93912
437.04100;     0.94080
438.04100;     0.94316
439.04100;     0.94367
440.04100;     0.94681
441.04100;     0.94850
442.04100;     0.95009
443.04100;     0.95179
444.04100;     0.95381
445.04100;     0.95526
446.04100;     0.95701
447.04100;     0.95852
448.04100;     0.96105
449.04100;     0.96340
450.04100;     0.96515
451.04100;     0.96671
452.04100;     0.96822
453.04100;     0.96990
454.04100;     0.97273
455.04100;     0.97441
456.04100;     0.97647
457.04100;     0.97892
458.04100;     0.98092
459.04100;     0.98314
460.04100;     0.98515
461.04100;     0.98705
462.04100;     0.98899
463.04100;     0.99184
464.04100;     0.99469
465.04100;     0.99655
466.04100;     0.99827
467.04100;     1.00183
468.04100;     1.00462
469.04100;     1.00617
470.04100;     1.00849
471.04100;     1.01057
472.04100;     1.01391
473.04100;     1.01541
474.04100;     1.01785
475.04100;     1.01984
476.04100;     1.02302
477.04100;     1.02482
478.04100;     1.02599
479.04100;     1.02881
480.04100;     1.03061
481.04100;     1.03390
482.04100;     1.03607
483.04100;     1.03835
484.04100;     1.04042
485.04100;     1.04215
486.04100;     1.04432
487.04100;     1.04754
488.04100;     1.04909
489.04100;     1.05166
490.04100;     1.05386
491.04100;     1.05693
492.04100;     1.05851
493.04100;     1.06093
494.04100;     1.06443
495.04100;     1.06581
496.04100;     1.06789
497.04100;     1.06995
498.04100;     1.07248
499.04100;     1.07485
500.04100;     1.07731
501.04100;     1.07955
502.04100;     1.08142
503.04100;     1.08479
504.04100;     1.08699
505.04100;     1.08777
506.04100;     1.09096
507.04100;     1.09315
508.04100;     1.09524
509.04100;     1.09900
510.04100;     1.10115
511.04100;     1.10308
512.04100;     1.10522
513.04100;     1.10824
514.04100;     1.11085
515.04100;     1.11337
516.04100;     1.11562
517.04100;     1.11677
518.04100;     1.11992
519.04100;     1.12182
520.04100;     1.12433
521.04100;     1.12611
522.04100;     1.12747
523.04100;     1.13022
524.04100;     1.13206
525.04100;     1.13471
526.04100;     1.13575
527.04100;     1.13867
528.04100;     1.14113
529.04100;     1.14294
530.04100;     1.14465
531.04100;     1.14637
532.04100;     1.14699
533.04100;     1.14900
534.04100;     1.15207
535.04100;     1.15384
536.04100;     1.15602
537.04100;     1.15821
538.04100;     1.15878
539.04100;     1.16168
540.04100;     1.16450
541.04100;     1.16565
542.04100;     1.16812
543.04100;     1.16868
544.04100;     1.17079
545.04100;     1.17266
546.04100;     1.17313
547.04100;     1.17383
548.04100;     1.17509
549.04100;     1.17608
550.04100;     1.17798
551.04100;     1.17696
552.04100;     1.17832
553.04100;     1.17995
554.04100;     1.18163
555.04100;     1.18317
556.04100;     1.18443
557.04100;     1.18589
558.04100;     1.18642
559.04100;     1.18775
560.04100;     1.18833
561.04100;     1.18813
562.04100;     1.18828
563.04100;     1.18857
564.04100;     1.18886
565.04100;     1.18965
566.04100;     1.19038
567.04100;     1.18976
568.04100;     1.19096
569.04100;     1.19097
570.04100;     1.19225
571.04100;     1.19125
572.04100;     1.19147
573.04100;     1.19061
574.04100;     1.18973
575.04100;     1.18995
576.04100;     1.19117
577.04100;     1.19181
578.04100;     1.18946
579.04100;     1.18921
580.04100;     1.18850
581.04100;     1.18717
582.04100;     1.18572
583.04100;     1.18394
584.04100;     1.18212
585.04100;     1.18096
586.04100;     1.17763
587.04100;     1.17724
588.04100;     1.17744
589.04100;     1.17427
590.04100;     1.17248
591.04100;     1.17158
592.04100;     1.16964
593.04100;     1.16875
594.04100;     1.16651
595.04100;     1.16459
596.04100;     1.16314
597.04100;     1.15959
598.04100;     1.15762
599.04100;     1.15503
600.04100;     1.15114
601.04100;     1.14874
602.04100;     1.14512
603.04100;     1.14206
604.04100;     1.13960
605.04100;     1.13481
606.04100;     1.13169
607.04100;     1.12796
608.04100;     1.12307
609.04100;     1.11839
610.04100;     1.11459
611.04100;     1.11036
612.04100;     1.10702
613.04100;     1.10192
614.04100;     1.09781
615.04100;     1.09230
616.04100;     1.08745
617.04100;     1.08242
618.04100;     1.07720
619.04100;     1.07244
620.04100;     1.06645
621.04100;     1.06022
622.04100;     1.05620
623.04100;     1.05120
624.04100;     1.04525
625.04100;     1.04022
626.04100;     1.03323
627.04100;     1.02738
628.04100;     1.02050
629.04100;     1.01257
630.04100;     1.00533
631.04100;     1.00325
632.04100;     1.00122
633.04100;     0.99587
634.04100;     0.99046
635.04100;     0.98482
636.04100;     0.97898
637.04100;     0.97244
638.04100;     0.96557
639.04100;     0.95886
640.04100;     0.95130
641.04100;     0.94558
642.04100;     0.93803
643.04100;     0.93265
644.04100;     0.92554
645.04100;     0.91953
646.04100;     0.91463
647.04100;     0.90788
648.04100;     0.90178
649.04100;     0.89672
650.04100;     0.88986
651.04100;     0.88423
652.04100;     0.87807
653.04100;     0.87202
654.04100;     0.86649
655.04100;     0.86059
656.04100;     0.85531
657.04100;     0.85019
658.04100;     0.84507
659.04100;     0.84103
660.04100;     0.83461
661.04100;     0.83032
662.04100;     0.82663
663.04100;     0.82264
664.04100;     0.81813
665.04100;     0.81478
666.04100;     0.81110
667.04100;     0.80869
668.04100;     0.80471
669.04100;     0.80163
670.04100;     0.79781
671.04100;     0.79496
672.04100;     0.79328
673.04100;     0.79066
674.04100;     0.78725
675.04100;     0.78624
676.04100;     0.78402
677.04100;     0.78383
678.04100;     0.78286
679.04100;     0.78208
680.04100;     0.78441
681.04100;     0.78628
682.04100;     0.78837
683.04100;     0.78932
684.04100;     0.79059
685.04100;     0.79172
686.04100;     0.79429
687.04100;     0.79649
688.04100;     0.79686
689.04100;     0.79844
690.04100;     0.80039
691.04100;     0.80339
692.04100;     0.80562
693.04100;     0.80935
694.04100;     0.81410
695.04100;     0.81725
696.04100;     0.82021
697.04100;     0.82419
698.04100;     0.82846
699.04100;     0.83179
700.04100;     0.83636
701.04100;     0.84018
702.04100;     0.84628
703.04100;     0.85215
704.04100;     0.85736
705.04100;     0.86357
706.04100;     0.87037
707.04100;     0.87795
708.04100;     0.88336
709.04100;     0.89203
710.04100;     0.89911
711.04100;     0.90669
712.04100;     0.91412
713.04100;     0.92133
714.04100;     0.93016
715.04100;     0.93998
716.04100;     0.94842
717.04100;     0.96055
718.04100;     0.97065
719.04100;     0.97921
720.04100;     0.98905
721.04100;     0.99908
722.04100;     1.00795
723.04100;     1.01820
724.04100;     1.02973
725.04100;     1.03944
726.04100;     1.04982
727.04100;     1.06090
728.04100;     1.07193
729.04100;     1.08311
730.04100;     1.09555
731.04100;     1.10574
732.04100;     1.12053
733.04100;     1.13111
734.04100;     1.14396
735.04100;     1.15639
736.04100;     1.16816
737.04100;     1.18003
738.04100;     1.19085
739.04100;     1.20504
740.04100;     1.21760
741.04100;     1.23059
742.04100;     1.24324
743.04100;     1.25871
744.04100;     1.27001
745.04100;     1.28406
746.04100;     1.29927
747.04100;     1.31241
748.04100;     1.33032
749.04100;     1.34927
750.04100;     1.36404
751.04100;     1.37944
752.04100;     1.39442
753.04100;     1.41070
754.04100;     1.44395
755.04100;     1.45778
756.04100;     1.47121
757.04100;     1.48504
758.04100;     1.50120
759.04100;     1.51548
760.04100;     1.52904
761.04100;     1.54654
762.04100;     1.56221
763.04100;     1.57713
764.04100;     1.59164
765.04100;     1.60682
766.04100;     1.62077
767.04100;     1.63476
768.04100;     1.64975
769.04100;     1.66682
770.04100;     1.68167
771.04100;     1.69632
772.04100;     1.71201
773.04100;     1.72670
774.04100;     1.74240
775.04100;     1.75669
776.04100;     1.77139
777.04100;     1.78610
778.04100;     1.80234
779.04100;     1.81768
780.04100;     1.83369
781.04100;     1.85006
782.04100;     1.86869
783.04100;     1.88567
784.04100;     1.90257
785.04100;     1.91715
786.04100;     1.93147
787.04100;     1.94928
788.04100;     1.96512
789.04100;     1.98152
790.04100;     1.99777
791.04100;     2.01466
792.04100;     2.03107
793.04100;     2.05039
794.04100;     2.06339
795.04100;     2.07983
796.04100;     2.09443
797.04100;     2.11046