File: examples/Birch/TGA_DSC data T18/13WaT18 10 K min N2 15.2.2007.TG.txt
#FILE:                        13WaT18 10 K min N2 15.2.2007.dsu
#FORMAT:                      NETZSCH4
#IDENTITY:                    13 WaT18 10 K min N2
#DECIMAL:                     POINT
#SEPARATOR:                   SEMICOLON
#MTYPE:                       TG
#INSTRUMENT:                  NETZSCH STA 449C
#PROJECT:                     vtt
#DATE/TIME:                   15.2.2007 8:12:40
#CORR. FILE:                  correction 10K min N2 800 C.bsu
#LABORATORY:                  EO
#OPERATOR:                    TL
#REMARK:
#SAMPLE:                      13 WaT18
#SAMPLE MASS /mg:             12.798
#MATERIAL:                    Empty crucibles
#REFERENCE:                   al2o3
#REFERENCE MASS /mg:          40.312
#TYPE OF CRUCIBLE:            DSC/TG pan Al2O3
#SAMPLE CRUCIBLE MASS /mg:    0.000
#REFERENCE CRUCIBLE MASS /mg: 0.000
#PROTECTIVE GAS:              N2
#PURGE GAS 1:                 air
#FLOW RATE 1 /(ml/min):       40
#PURGE GAS 2:
#FLOW RATE 2:
#DSC RANGE /æm:               5000
#TG RANGE /æm:                5000
#CORR. CODE:                  020
#EXO:                         +1
#RANGE:                       20.0/10.00(K/min)/800.0
#SEGMENT:                     S1/2

##Temp./øC;Mass/%
 23.01411;100.00000
 24.01411; 99.94928
 25.01411; 99.94623
 26.01411; 99.93747
 27.01411; 99.93479
 28.01411; 99.92891
 29.01411; 99.93246
 30.01411; 99.93081
 31.01411; 99.91664
 32.01411; 99.90970
 33.01411; 99.90379
 34.01411; 99.89935
 35.01411; 99.89244
 36.01411; 99.88626
 37.01411; 99.87417
 38.01411; 99.86266
 39.01411; 99.84846
 40.01411; 99.83383
 41.01411; 99.82218
 42.01411; 99.80836
 43.01411; 99.79817
 44.01411; 99.78191
 45.01411; 99.76838
 46.01411; 99.74943
 47.01411; 99.73271
 48.01411; 99.71680
 49.01411; 99.70130
 50.01411; 99.68596
 51.01411; 99.66409
 52.01411; 99.63933
 53.01411; 99.61186
 54.01411; 99.59170
 55.01411; 99.57107
 56.01411; 99.54435
 57.01411; 99.50957
 58.01411; 99.47697
 59.01411; 99.45007
 60.01411; 99.42227
 61.01411; 99.38516
 62.01411; 99.35205
 63.01411; 99.31595
 64.01411; 99.28393
 65.01411; 99.25233
 66.01411; 99.21585
 67.01411; 99.17157
 68.01411; 99.12821
 69.01411; 99.08870
 70.01411; 99.04637
 71.01411; 99.00471
 72.01411; 98.96221
 73.01411; 98.91330
 74.01411; 98.86552
 75.01411; 98.81828
 76.01411; 98.77493
 77.01411; 98.72898
 78.01411; 98.67798
 79.01411; 98.63029
 80.01411; 98.58100
 81.01411; 98.53471
 82.01411; 98.48610
 83.01411; 98.43899
 84.01411; 98.39230
 85.01411; 98.34762
 86.01411; 98.30083
 87.01411; 98.25416
 88.01411; 98.20411
 89.01411; 98.16014
 90.01411; 98.11769
 91.01411; 98.07858
 92.01411; 98.03808
 93.01411; 97.99708
 94.01411; 97.95756
 95.01411; 97.92016
 96.01411; 97.88710
 97.01411; 97.85168
 98.01411; 97.82136
 99.01411; 97.78961
100.01411; 97.76098
101.01411; 97.73288
102.01411; 97.70789
103.01411; 97.68463
104.01411; 97.66062
105.01411; 97.64058
106.01411; 97.61719
107.01411; 97.60289
108.01411; 97.58542
109.01411; 97.57188
110.01411; 97.55269
111.01411; 97.53763
112.01411; 97.52525
113.01411; 97.51330
114.01411; 97.50103
115.01411; 97.49180
116.01411; 97.48542
117.01411; 97.47915
118.01411; 97.47113
119.01411; 97.46331
120.01411; 97.45678
121.01411; 97.44798
122.01411; 97.43949
123.01411; 97.43176
124.01411; 97.42683
125.01411; 97.42226
126.01411; 97.41723
127.01411; 97.41354
128.01411; 97.40959
129.01411; 97.40591
130.01411; 97.40173
131.01411; 97.39938
132.01411; 97.39475
133.01411; 97.39101
134.01411; 97.38750
135.01411; 97.38485
136.01411; 97.38164
137.01411; 97.38084
138.01411; 97.37954
139.01411; 97.37671
140.01411; 97.36841
141.01411; 97.36747
142.01411; 97.36677
143.01411; 97.36541
144.01411; 97.36330
145.01411; 97.35944
146.01411; 97.35899
147.01411; 97.35662
148.01411; 97.35574
149.01411; 97.35312
150.01411; 97.35047
151.01411; 97.34855
152.01411; 97.34641
153.01411; 97.34412
154.01411; 97.34178
155.01411; 97.34175
156.01411; 97.34107
157.01411; 97.33945
158.01411; 97.33877
159.01411; 97.33944
160.01411; 97.33712
161.01411; 97.33550
162.01411; 97.33409
163.01411; 97.33159
164.01411; 97.33133
165.01411; 97.32789
166.01411; 97.32294
167.01411; 97.32062
168.01411; 97.31911
169.01411; 97.31615
170.01411; 97.31295
171.01411; 97.30899
172.01411; 97.30744
173.01411; 97.30667
174.01411; 97.30556
175.01411; 97.30414
176.01411; 97.30189
177.01411; 97.30097
178.01411; 97.29723
179.01411; 97.29192
180.01411; 97.28647
181.01411; 97.28413
182.01411; 97.28174
183.01411; 97.27776
184.01411; 97.26920
185.01411; 97.26572
186.01411; 97.26154
187.01411; 97.25459
188.01411; 97.24946
189.01411; 97.24560
190.01411; 97.24024
191.01411; 97.23407
192.01411; 97.22827
193.01411; 97.21977
194.01411; 97.21324
195.01411; 97.20815
196.01411; 97.20404
197.01411; 97.19539
198.01411; 97.18538
199.01411; 97.17894
200.01411; 97.17115
201.01411; 97.16557
202.01411; 97.15401
203.01411; 97.14326
204.01411; 97.13474
205.01411; 97.12399
206.01411; 97.11318
207.01411; 97.10322
208.01411; 97.09119
209.01411; 97.08008
210.01411; 97.06855
211.01411; 97.05762
212.01411; 97.04191
213.01411; 97.03212
214.01411; 97.02177
215.01411; 97.00519
216.01411; 96.99333
217.01411; 96.97980
218.01411; 96.96282
219.01411; 96.94372
220.01411; 96.92931
221.01411; 96.91553
222.01411; 96.90008
223.01411; 96.87939
224.01411; 96.86307
225.01411; 96.84349
226.01411; 96.81802
227.01411; 96.79542
228.01411; 96.77130
229.01411; 96.75335
230.01411; 96.72683
231.01411; 96.69966
232.01411; 96.67624
233.01411; 96.64420
234.01411; 96.61118
235.01411; 96.58216
236.01411; 96.54919
237.01411; 96.51125
238.01411; 96.47369
239.01411; 96.43841
240.01411; 96.39320
241.01411; 96.34231
242.01411; 96.29486
243.01411; 96.24875
244.01411; 96.19676
245.01411; 96.14007
246.01411; 96.08023
247.01411; 96.02173
248.01411; 95.95734
249.01411; 95.89238
250.01411; 95.82526
251.01411; 95.75585
252.01411; 95.68059
253.01411; 95.60239
254.01411; 95.51687
255.01411; 95.43187
256.01411; 95.33769
257.01411; 95.22801
258.01411; 95.13321
259.01411; 95.02806
260.01411; 94.90536
261.01411; 94.79057
262.01411; 94.67341
263.01411; 94.52792
264.01411; 94.39764
265.01411; 94.23989
266.01411; 94.08241
267.01411; 93.91499
268.01411; 93.74224
269.01411; 93.55362
270.01411; 93.35215
271.01411; 93.14614
272.01411; 92.92371
273.01411; 92.70184
274.01411; 92.45736
275.01411; 92.20069
276.01411; 91.92898
277.01411; 91.64495
278.01411; 91.35416
279.01411; 91.04558
280.01411; 90.58374
281.01411; 90.31012
282.01411; 89.89282
283.01411; 89.60840
284.01411; 89.33415
285.01411; 88.81821
286.01411; 88.52434
287.01411; 87.96880
288.01411; 87.64735
289.01411; 87.14347
290.01411; 86.79023
291.01411; 86.22879
292.01411; 85.83525
293.01411; 85.47705
294.01411; 84.88185
295.01411; 84.38457
296.01411; 83.93925
297.01411; 83.56944
298.01411; 83.13649
299.01411; 82.64537
300.01411; 82.02382
301.01411; 81.59246
302.01411; 81.22023
303.01411; 80.57786
304.01411; 80.13552
305.01411; 79.65164
306.01411; 79.29168
307.01411; 78.65568
308.01411; 78.26332
309.01411; 77.87099
310.01411; 77.30017
311.01411; 76.93110
312.01411; 76.26643
313.01411; 75.76228
314.01411; 75.40106
315.01411; 75.03876
316.01411; 74.45243
317.01411; 73.87087
318.01411; 73.48888
319.01411; 72.85240
320.01411; 72.39775
321.01411; 71.87883
322.01411; 71.43025
323.01411; 70.96834
324.01411; 70.58031
325.01411; 69.93864
326.01411; 69.53209
327.01411; 69.11770
328.01411; 68.46584
329.01411; 67.94997
330.01411; 67.44323
331.01411; 66.97670
332.01411; 66.48177
333.01411; 65.96495
334.01411; 65.47161
335.01411; 65.04681
336.01411; 64.67198
337.01411; 64.02045
338.01411; 63.61283
339.01411; 63.02631
340.01411; 62.64018
341.01411; 61.94299
342.01411; 61.43712
343.01411; 60.92112
344.01411; 60.51407
345.01411; 59.82744
346.01411; 59.27204
347.01411; 58.70262
348.01411; 58.10772
349.01411; 57.53809
350.01411; 56.89060
351.01411; 56.28519
352.01411; 55.60906
353.01411; 54.94829
354.01411; 54.24849
355.01411; 53.49129
356.01411; 52.69426
357.01411; 51.84275
358.01411; 50.97859
359.01411; 50.14379
360.01411; 49.16600
361.01411; 48.18870
362.01411; 47.20218
363.01411; 46.11947
364.01411; 45.01457
365.01411; 43.91334
366.01411; 42.73603
367.01411; 41.53971
368.01411; 40.37104
369.01411; 39.13151
370.01411; 37.92182
371.01411; 36.70433
372.01411; 35.51441
373.01411; 34.35081
374.01411; 33.22823
375.01411; 32.17207
376.01411; 31.15957
377.01411; 30.19677
378.01411; 29.38708
379.01411; 28.57821
380.01411; 27.85642
381.01411; 27.32071
382.01411; 26.86832
383.01411; 26.33732
384.01411; 26.02390
385.01411; 25.60698
386.01411; 25.40229
387.01411; 25.22706
388.01411; 25.03344
389.01411; 24.86496
390.01411; 24.74006
391.01411; 24.62927
392.01411; 24.51868
393.01411; 24.41908
394.01411; 24.34357
395.01411; 24.26247
396.01411; 24.18481
397.01411; 24.10534
398.01411; 24.03010
399.01411; 23.96521
400.01411; 23.89327
401.01411; 23.82094
402.01411; 23.74306
403.01411; 23.68064
404.01411; 23.61512
405.01411; 23.54503
406.01411; 23.48145
407.01411; 23.41364
408.01411; 23.34530
409.01411; 23.27596
410.01411; 23.21765
411.01411; 23.14670
412.01411; 23.08266
413.01411; 23.01924
414.01411; 22.95019
415.01411; 22.88599
416.01411; 22.82068
417.01411; 22.75431
418.01411; 22.69202
419.01411; 22.62576
420.01411; 22.56364
421.01411; 22.49873
422.01411; 22.43484
423.01411; 22.37856
424.01411; 22.31158
425.01411; 22.24598
426.01411; 22.18383
427.01411; 22.12435
428.01411; 22.06454
429.01411; 22.00200
430.01411; 21.94446
431.01411; 21.88439
432.01411; 21.82367
433.01411; 21.77273
434.01411; 21.71690
435.01411; 21.65898
436.01411; 21.60205
437.01411; 21.54425
438.01411; 21.49115
439.01411; 21.43590
440.01411; 21.38261
441.01411; 21.33202
442.01411; 21.28120
443.01411; 21.23156
444.01411; 21.18155
445.01411; 21.13268
446.01411; 21.08284
447.01411; 21.03441
448.01411; 20.99137
449.01411; 20.94631
450.01411; 20.90000
451.01411; 20.85707
452.01411; 20.81182
453.01411; 20.77262
454.01411; 20.73593
455.01411; 20.69351
456.01411; 20.64781
457.01411; 20.60885
458.01411; 20.56960
459.01411; 20.53185
460.01411; 20.49681
461.01411; 20.46000
462.01411; 20.41854
463.01411; 20.38455
464.01411; 20.34843
465.01411; 20.31451
466.01411; 20.27604
467.01411; 20.24376
468.01411; 20.21167
469.01411; 20.17948
470.01411; 20.14820
471.01411; 20.11382
472.01411; 20.08703
473.01411; 20.05563
474.01411; 20.02582
475.01411; 19.99530
476.01411; 19.96398
477.01411; 19.93051
478.01411; 19.90071
479.01411; 19.87054
480.01411; 19.84522
481.01411; 19.82088
482.01411; 19.79082
483.01411; 19.76326
484.01411; 19.73456
485.01411; 19.70434
486.01411; 19.67749
487.01411; 19.65229
488.01411; 19.62516
489.01411; 19.60011
490.01411; 19.57266
491.01411; 19.54670
492.01411; 19.52390
493.01411; 19.49622
494.01411; 19.46882
495.01411; 19.44639
496.01411; 19.42115
497.01411; 19.39536
498.01411; 19.36530
499.01411; 19.34547
500.01411; 19.32037
501.01411; 19.29741
502.01411; 19.27361
503.01411; 19.25157
504.01411; 19.22826
505.01411; 19.20627
506.01411; 19.17889
507.01411; 19.15858
508.01411; 19.12874
509.01411; 19.11055
510.01411; 19.08747
511.01411; 19.06735
512.01411; 19.04735
513.01411; 19.01997
514.01411; 18.99435
515.01411; 18.97874
516.01411; 18.95573
517.01411; 18.93388
518.01411; 18.90927
519.01411; 18.88612
520.01411; 18.86425
521.01411; 18.83990
522.01411; 18.82190
523.01411; 18.79355
524.01411; 18.77581
525.01411; 18.76244
526.01411; 18.74365
527.01411; 18.72067
528.01411; 18.69637
529.01411; 18.67998
530.01411; 18.65776
531.01411; 18.63098
532.01411; 18.61893
533.01411; 18.60379
534.01411; 18.57538
535.01411; 18.55751
536.01411; 18.54108
537.01411; 18.51410
538.01411; 18.50730
539.01411; 18.48547
540.01411; 18.46435
541.01411; 18.44146
542.01411; 18.42172
543.01411; 18.40090
544.01411; 18.38261
545.01411; 18.37117
546.01411; 18.35085
547.01411; 18.32732
548.01411; 18.31010
549.01411; 18.29213
550.01411; 18.27733
551.01411; 18.26247
552.01411; 18.24306
553.01411; 18.21883
554.01411; 18.20766
555.01411; 18.18739
556.01411; 18.16698
557.01411; 18.15191
558.01411; 18.14106
559.01411; 18.12051
560.01411; 18.10717
561.01411; 18.08391
562.01411; 18.06255
563.01411; 18.04606
564.01411; 18.03967
565.01411; 18.01749
566.01411; 17.99687
567.01411; 17.98006
568.01411; 17.96193
569.01411; 17.94500
570.01411; 17.93174
571.01411; 17.91357
572.01411; 17.89614
573.01411; 17.88339
574.01411; 17.87122
575.01411; 17.85949
576.01411; 17.83674
577.01411; 17.81885
578.01411; 17.80787
579.01411; 17.79102
580.01411; 17.77166
581.01411; 17.75854
582.01411; 17.74633
583.01411; 17.73393
584.01411; 17.71682
585.01411; 17.70096
586.01411; 17.68751
587.01411; 17.67277
588.01411; 17.65636
589.01411; 17.63888
590.01411; 17.62355
591.01411; 17.60446
592.01411; 17.59416
593.01411; 17.58995
594.01411; 17.55953
595.01411; 17.55656
596.01411; 17.53994
597.01411; 17.52930
598.01411; 17.52046
599.01411; 17.50013
600.01411; 17.47918
601.01411; 17.47304
602.01411; 17.45961
603.01411; 17.45193
604.01411; 17.43454
605.01411; 17.41989
606.01411; 17.40656
607.01411; 17.39255
608.01411; 17.38240
609.01411; 17.37383
610.01411; 17.35428
611.01411; 17.34179
612.01411; 17.32697
613.01411; 17.32311
614.01411; 17.30510
615.01411; 17.30273
616.01411; 17.28795
617.01411; 17.27545
618.01411; 17.26133
619.01411; 17.25130
620.01411; 17.23558
621.01411; 17.22936
622.01411; 17.21447
623.01411; 17.21367
624.01411; 17.20525
625.01411; 17.18423
626.01411; 17.17143
627.01411; 17.17067
628.01411; 17.16540
629.01411; 17.14896
630.01411; 17.13584
631.01411; 17.12156
632.01411; 17.11988
633.01411; 17.11921
634.01411; 17.10229
635.01411; 17.08434
636.01411; 17.06476
637.01411; 17.05977
638.01411; 17.06134
639.01411; 17.04857
640.01411; 17.04173
641.01411; 17.03104
642.01411; 17.03219
643.01411; 17.02796
644.01411; 17.00768
645.01411; 16.99435
646.01411; 16.99249
647.01411; 16.98658
648.01411; 16.97541
649.01411; 16.96379
650.01411; 16.95840
651.01411; 16.94251
652.01411; 16.93956
653.01411; 16.92541
654.01411; 16.92615
655.01411; 16.91367
656.01411; 16.91207
657.01411; 16.90343
658.01411; 16.90033
659.01411; 16.88941
660.01411; 16.88154
661.01411; 16.86981
662.01411; 16.85732
663.01411; 16.85810
664.01411; 16.85186
665.01411; 16.84869
666.01411; 16.84089
667.01411; 16.82760
668.01411; 16.82524
669.01411; 16.81900
670.01411; 16.80808
671.01411; 16.80559
672.01411; 16.79786
673.01411; 16.78756
674.01411; 16.77818
675.01411; 16.76507
676.01411; 16.76435
677.01411; 16.76668
678.01411; 16.76347
679.01411; 16.75618
680.01411; 16.74168
681.01411; 16.73991
682.01411; 16.73449
683.01411; 16.72708
684.01411; 16.71784
685.01411; 16.71558
686.01411; 16.71639
687.01411; 16.70642
688.01411; 16.70081
689.01411; 16.70110
690.01411; 16.69389
691.01411; 16.67998
692.01411; 16.67273
693.01411; 16.66485
694.01411; 16.65546
695.01411; 16.65507
696.01411; 16.64823
697.01411; 16.63988
698.01411; 16.63434
699.01411; 16.63004
700.01411; 16.62580
701.01411; 16.62564
702.01411; 16.62027
703.01411; 16.61006
704.01411; 16.59714
705.01411; 16.59319
706.01411; 16.58874
707.01411; 16.58412
708.01411; 16.57892
709.01411; 16.57978
710.01411; 16.57580
711.01411; 16.57397
712.01411; 16.56760
713.01411; 16.56239
714.01411; 16.55607
715.01411; 16.55022
716.01411; 16.54513
717.01411; 16.53624
718.01411; 16.52761
719.01411; 16.51275
720.01411; 16.51665
721.01411; 16.51341
722.01411; 16.50461
723.01411; 16.49556
724.01411; 16.49472
725.01411; 16.48578
726.01411; 16.47951
727.01411; 16.46837
728.01411; 16.46681
729.01411; 16.46525
730.01411; 16.45463
731.01411; 16.45196
732.01411; 16.44428
733.01411; 16.44257
734.01411; 16.43881
735.01411; 16.44046
736.01411; 16.43774
737.01411; 16.43169
738.01411; 16.41999
739.01411; 16.41555
740.01411; 16.40227
741.01411; 16.38478
742.01411; 16.38597
743.01411; 16.38422
744.01411; 16.37157
745.01411; 16.36837
746.01411; 16.36442
747.01411; 16.35810
748.01411; 16.35334
749.01411; 16.34943
750.01411; 16.34078
751.01411; 16.33766
752.01411; 16.33454
753.01411; 16.32732
754.01411; 16.32115
755.01411; 16.31899
756.01411; 16.31305
757.01411; 16.30883
758.01411; 16.30082
759.01411; 16.29655
760.01411; 16.29222
761.01411; 16.28847
762.01411; 16.28622
763.01411; 16.27870
764.01411; 16.27069
765.01411; 16.26767
766.01411; 16.26433
767.01411; 16.25631
768.01411; 16.25360
769.01411; 16.25002
770.01411; 16.24474
771.01411; 16.24114
772.01411; 16.23399
773.01411; 16.22841
774.01411; 16.22523
775.01411; 16.21970
776.01411; 16.20949
777.01411; 16.20250
778.01411; 16.19612
779.01411; 16.19229
780.01411; 16.18936
781.01411; 16.18604
782.01411; 16.17779
783.01411; 16.17124
784.01411; 16.17167
785.01411; 16.17363
786.01411; 16.16767
787.01411; 16.15926
788.01411; 16.15354
789.01411; 16.14707
790.01411; 16.14704
791.01411; 16.14475
792.01411; 16.13757
793.01411; 16.13185
794.01411; 16.12835
795.01411; 16.12346
796.01411; 16.11853
797.01411; 16.11616